2018-12-03 19:41:37 WARNING (Recorder) [homeassistant.components.recorder] Ended unfinished session (id=6 from 2018-11-27 02:59:10.570289)
2018-12-03 19:42:04 ERROR (MainThread) [homeassistant.core] Error doing job: SSL handshake failed
Traceback (most recent call last):
  File "uvloop/handles/stream.pyx", line 609, in uvloop.loop.UVStream._on_eof
  File "uvloop/sslproto.pyx", line 171, in uvloop.loop._SSLPipe.feed_ssldata
  File "/usr/local/lib/python3.6/ssl.py", line 689, in do_handshake
    self._sslobj.do_handshake()
ssl.SSLError: [SSL: HTTP_REQUEST] http request (_ssl.c:841)
2018-12-03 19:42:04 ERROR (MainThread) [homeassistant.core] Error doing job: SSL error errno:1 reason: HTTP_REQUEST
Traceback (most recent call last):
  File "uvloop/sslproto.pyx", line 504, in uvloop.loop.SSLProtocol.data_received
  File "uvloop/sslproto.pyx", line 204, in uvloop.loop._SSLPipe.feed_ssldata
  File "uvloop/sslproto.pyx", line 171, in uvloop.loop._SSLPipe.feed_ssldata
  File "/usr/local/lib/python3.6/ssl.py", line 689, in do_handshake
    self._sslobj.do_handshake()
ssl.SSLError: [SSL: HTTP_REQUEST] http request (_ssl.c:841)
2018-12-03 19:42:04 ERROR (MainThread) [homeassistant.core] Error doing job: SSL handshake failed
Traceback (most recent call last):
  File "uvloop/handles/stream.pyx", line 609, in uvloop.loop.UVStream._on_eof
  File "uvloop/sslproto.pyx", line 171, in uvloop.loop._SSLPipe.feed_ssldata
  File "/usr/local/lib/python3.6/ssl.py", line 689, in do_handshake
    self._sslobj.do_handshake()
ssl.SSLError: [SSL: HTTP_REQUEST] http request (_ssl.c:841)
2018-12-03 19:42:04 ERROR (MainThread) [homeassistant.core] Error doing job: SSL error errno:1 reason: HTTP_REQUEST
Traceback (most recent call last):
  File "uvloop/sslproto.pyx", line 504, in uvloop.loop.SSLProtocol.data_received
  File "uvloop/sslproto.pyx", line 204, in uvloop.loop._SSLPipe.feed_ssldata
  File "uvloop/sslproto.pyx", line 171, in uvloop.loop._SSLPipe.feed_ssldata
  File "/usr/local/lib/python3.6/ssl.py", line 689, in do_handshake
    self._sslobj.do_handshake()
ssl.SSLError: [SSL: HTTP_REQUEST] http request (_ssl.c:841)
2018-12-03 19:42:04 ERROR (MainThread) [homeassistant.core] Error doing job: SSL handshake failed
Traceback (most recent call last):
  File "uvloop/handles/stream.pyx", line 609, in uvloop.loop.UVStream._on_eof
  File "uvloop/sslproto.pyx", line 171, in uvloop.loop._SSLPipe.feed_ssldata
  File "/usr/local/lib/python3.6/ssl.py", line 689, in do_handshake
    self._sslobj.do_handshake()
ssl.SSLError: [SSL: HTTP_REQUEST] http request (_ssl.c:841)
2018-12-03 19:42:04 ERROR (MainThread) [homeassistant.core] Error doing job: SSL error errno:1 reason: HTTP_REQUEST
Traceback (most recent call last):
  File "uvloop/sslproto.pyx", line 504, in uvloop.loop.SSLProtocol.data_received
  File "uvloop/sslproto.pyx", line 204, in uvloop.loop._SSLPipe.feed_ssldata
  File "uvloop/sslproto.pyx", line 171, in uvloop.loop._SSLPipe.feed_ssldata
  File "/usr/local/lib/python3.6/ssl.py", line 689, in do_handshake
    self._sslobj.do_handshake()
ssl.SSLError: [SSL: HTTP_REQUEST] http request (_ssl.c:841)
2018-12-03 19:42:05 ERROR (MainThread) [homeassistant.core] Error doing job: SSL handshake failed
Traceback (most recent call last):
  File "uvloop/handles/stream.pyx", line 609, in uvloop.loop.UVStream._on_eof
  File "uvloop/sslproto.pyx", line 171, in uvloop.loop._SSLPipe.feed_ssldata
  File "/usr/local/lib/python3.6/ssl.py", line 689, in do_handshake
    self._sslobj.do_handshake()
ssl.SSLError: [SSL: HTTP_REQUEST] http request (_ssl.c:841)
2018-12-03 19:42:05 ERROR (MainThread) [homeassistant.core] Error doing job: SSL error errno:1 reason: HTTP_REQUEST
Traceback (most recent call last):
  File "uvloop/sslproto.pyx", line 504, in uvloop.loop.SSLProtocol.data_received
  File "uvloop/sslproto.pyx", line 204, in uvloop.loop._SSLPipe.feed_ssldata
  File "uvloop/sslproto.pyx", line 171, in uvloop.loop._SSLPipe.feed_ssldata
  File "/usr/local/lib/python3.6/ssl.py", line 689, in do_handshake
    self._sslobj.do_handshake()
ssl.SSLError: [SSL: HTTP_REQUEST] http request (_ssl.c:841)
2018-12-03 19:42:10 ERROR (MainThread) [homeassistant.core] Error doing job: SSL handshake failed
Traceback (most recent call last):
  File "uvloop/handles/stream.pyx", line 609, in uvloop.loop.UVStream._on_eof
  File "uvloop/sslproto.pyx", line 171, in uvloop.loop._SSLPipe.feed_ssldata
  File "/usr/local/lib/python3.6/ssl.py", line 689, in do_handshake
    self._sslobj.do_handshake()
ssl.SSLError: [SSL: HTTP_REQUEST] http request (_ssl.c:841)
2018-12-03 19:42:10 ERROR (MainThread) [homeassistant.core] Error doing job: SSL error errno:1 reason: HTTP_REQUEST
Traceback (most recent call last):
  File "uvloop/sslproto.pyx", line 504, in uvloop.loop.SSLProtocol.data_received
  File "uvloop/sslproto.pyx", line 204, in uvloop.loop._SSLPipe.feed_ssldata
  File "uvloop/sslproto.pyx", line 171, in uvloop.loop._SSLPipe.feed_ssldata
  File "/usr/local/lib/python3.6/ssl.py", line 689, in do_handshake
    self._sslobj.do_handshake()
ssl.SSLError: [SSL: HTTP_REQUEST] http request (_ssl.c:841)
2018-12-03 19:42:10 ERROR (MainThread) [homeassistant.core] Error doing job: SSL handshake failed
Traceback (most recent call last):
  File "uvloop/handles/stream.pyx", line 609, in uvloop.loop.UVStream._on_eof
  File "uvloop/sslproto.pyx", line 171, in uvloop.loop._SSLPipe.feed_ssldata
  File "/usr/local/lib/python3.6/ssl.py", line 689, in do_handshake
    self._sslobj.do_handshake()
ssl.SSLError: [SSL: HTTP_REQUEST] http request (_ssl.c:841)
2018-12-03 19:42:10 ERROR (MainThread) [homeassistant.core] Error doing job: SSL error errno:1 reason: HTTP_REQUEST
Traceback (most recent call last):
  File "uvloop/sslproto.pyx", line 504, in uvloop.loop.SSLProtocol.data_received
  File "uvloop/sslproto.pyx", line 204, in uvloop.loop._SSLPipe.feed_ssldata
  File "uvloop/sslproto.pyx", line 171, in uvloop.loop._SSLPipe.feed_ssldata
  File "/usr/local/lib/python3.6/ssl.py", line 689, in do_handshake
    self._sslobj.do_handshake()
ssl.SSLError: [SSL: HTTP_REQUEST] http request (_ssl.c:841)
2018-12-03 19:42:10 ERROR (MainThread) [homeassistant.core] Error doing job: SSL handshake failed
Traceback (most recent call last):
  File "uvloop/handles/stream.pyx", line 609, in uvloop.loop.UVStream._on_eof
  File "uvloop/sslproto.pyx", line 171, in uvloop.loop._SSLPipe.feed_ssldata
  File "/usr/local/lib/python3.6/ssl.py", line 689, in do_handshake
    self._sslobj.do_handshake()
ssl.SSLError: [SSL: HTTP_REQUEST] http request (_ssl.c:841)
2018-12-03 19:42:10 ERROR (MainThread) [homeassistant.core] Error doing job: SSL error errno:1 reason: HTTP_REQUEST
Traceback (most recent call last):
  File "uvloop/sslproto.pyx", line 504, in uvloop.loop.SSLProtocol.data_received
  File "uvloop/sslproto.pyx", line 204, in uvloop.loop._SSLPipe.feed_ssldata
  File "uvloop/sslproto.pyx", line 171, in uvloop.loop._SSLPipe.feed_ssldata
  File "/usr/local/lib/python3.6/ssl.py", line 689, in do_handshake
    self._sslobj.do_handshake()
ssl.SSLError: [SSL: HTTP_REQUEST] http request (_ssl.c:841)
2018-12-03 19:42:52 ERROR (MainThread) [homeassistant.core] Error doing job: SSL handshake failed
Traceback (most recent call last):
  File "uvloop/handles/stream.pyx", line 609, in uvloop.loop.UVStream._on_eof
  File "uvloop/sslproto.pyx", line 171, in uvloop.loop._SSLPipe.feed_ssldata
  File "/usr/local/lib/python3.6/ssl.py", line 689, in do_handshake
    self._sslobj.do_handshake()
ssl.SSLError: [SSL: HTTP_REQUEST] http request (_ssl.c:841)
2018-12-03 19:42:52 ERROR (MainThread) [homeassistant.core] Error doing job: SSL error errno:1 reason: HTTP_REQUEST
Traceback (most recent call last):
  File "uvloop/sslproto.pyx", line 504, in uvloop.loop.SSLProtocol.data_received
  File "uvloop/sslproto.pyx", line 204, in uvloop.loop._SSLPipe.feed_ssldata
  File "uvloop/sslproto.pyx", line 171, in uvloop.loop._SSLPipe.feed_ssldata
  File "/usr/local/lib/python3.6/ssl.py", line 689, in do_handshake
    self._sslobj.do_handshake()
ssl.SSLError: [SSL: HTTP_REQUEST] http request (_ssl.c:841)
2018-12-03 19:44:46 WARNING (Thread-2) [pychromecast.socket_client] Heartbeat timeout, resetting connection
2018-12-03 19:55:38 ERROR (SyncWorker_0) [homeassistant.util.yaml] YAML file /config/configuration.yaml contains duplicate key "automation". Check lines 66 and 89.
2018-12-03 20:00:38 ERROR (SyncWorker_7) [homeassistant.util.yaml] YAML file /config/configuration.yaml contains duplicate key "automation". Check lines 66 and 89.
2018-12-03 20:00:40 ERROR (SyncWorker_4) [homeassistant.util.yaml] YAML file /config/configuration.yaml contains duplicate key "automation". Check lines 66 and 89.
2018-12-03 20:00:41 ERROR (SyncWorker_17) [homeassistant.util.yaml] YAML file /config/configuration.yaml contains duplicate key "automation". Check lines 66 and 89.
2018-12-03 20:01:33 ERROR (SyncWorker_9) [homeassistant.util.yaml] YAML file /config/configuration.yaml contains duplicate key "automation". Check lines 66 and 89.
2018-12-03 20:06:40 ERROR (SyncWorker_14) [homeassistant.util.yaml] YAML file /config/configuration.yaml contains duplicate key "automation". Check lines 66 and 89.
2018-12-03 20:06:42 ERROR (SyncWorker_3) [homeassistant.util.yaml] YAML file /config/configuration.yaml contains duplicate key "automation". Check lines 66 and 89.
2018-12-03 20:06:49 ERROR (SyncWorker_16) [homeassistant.util.yaml] YAML file /config/configuration.yaml contains duplicate key "automation". Check lines 66 and 89.
2018-12-03 20:06:49 WARNING (MainThread) [homeassistant.components.group] remove:Group 'all_automations' doesn't exist!
2018-12-03 20:06:51 ERROR (SyncWorker_7) [homeassistant.util.yaml] YAML file /config/configuration.yaml contains duplicate key "automation". Check lines 66 and 89.
2018-12-03 20:06:52 ERROR (SyncWorker_4) [homeassistant.util.yaml] YAML file /config/configuration.yaml contains duplicate key "automation". Check lines 66 and 89.
2018-12-03 20:06:52 WARNING (MainThread) [homeassistant.components.group] remove:Group 'all_scripts' doesn't exist!
2018-12-03 20:41:40 ERROR (MainThread) [homeassistant.components.updater] Got unexpected response: None
2018-12-03 20:41:50 ERROR (MainThread) [homeassistant.components.sensor.yr] Retrying in 17 minutes: Cannot connect to host aa015h6buqvih86i1.api.met.no:443 ssl:None [Try again]
2018-12-03 20:42:51 WARNING (MainThread) [homeassistant.components.group] remove:Group 'all_automations' doesn't exist!
