2018-12-10 19:50:27 WARNING (MainThread) [homeassistant.components.http] legacy_api_password support has been enabled. If you don't require it, remove the 'api_password' from your http config.
2018-12-10 19:50:41 ERROR (MainThread) [homeassistant.components.sensor.yr] Retrying in 15 minutes: Cannot connect to host aa015h6buqvih86i1.api.met.no:443 ssl:None [Try again]
2018-12-10 19:50:45 ERROR (SyncWorker_0) [homeassistant.components.sensor.waze_travel_time] Error on retrieving data: Internal Error
2018-12-10 19:55:38 ERROR (SyncWorker_3) [homeassistant.components.sensor.waze_travel_time] Error on retrieving data: Internal Error
2018-12-10 19:56:15 WARNING (MainThread) [homeassistant.helpers.entity] Update of sensor.google_travel_time__driving is taking over 10 seconds
2018-12-10 19:56:36 WARNING (MainThread) [homeassistant.components.sensor] Updating google_travel_time sensor took longer than the scheduled update interval 0:00:30
2018-12-10 19:57:06 WARNING (MainThread) [homeassistant.components.sensor] Updating google_travel_time sensor took longer than the scheduled update interval 0:00:30
2018-12-10 19:57:27 ERROR (MainThread) [homeassistant.helpers.entity] Update for sensor.google_travel_time__driving fails
Traceback (most recent call last):
  File "/usr/local/lib/python3.6/site-packages/googlemaps/client.py", line 253, in _request
    result = self._get_body(response)
  File "/usr/local/lib/python3.6/site-packages/googlemaps/client.py", line 276, in _get_body
    raise googlemaps.exceptions._RetriableRequest()
googlemaps.exceptions._RetriableRequest

During handling of the above exception, another exception occurred:

Traceback (most recent call last):
  File "/usr/local/lib/python3.6/site-packages/googlemaps/client.py", line 253, in _request
    result = self._get_body(response)
  File "/usr/local/lib/python3.6/site-packages/googlemaps/client.py", line 276, in _get_body
    raise googlemaps.exceptions._RetriableRequest()
googlemaps.exceptions._RetriableRequest

During handling of the above exception, another exception occurred:

Traceback (most recent call last):
  File "/usr/local/lib/python3.6/site-packages/googlemaps/client.py", line 253, in _request
    result = self._get_body(response)
  File "/usr/local/lib/python3.6/site-packages/googlemaps/client.py", line 276, in _get_body
    raise googlemaps.exceptions._RetriableRequest()
googlemaps.exceptions._RetriableRequest

During handling of the above exception, another exception occurred:

Traceback (most recent call last):
  File "/usr/local/lib/python3.6/site-packages/googlemaps/client.py", line 253, in _request
    result = self._get_body(response)
  File "/usr/local/lib/python3.6/site-packages/googlemaps/client.py", line 276, in _get_body
    raise googlemaps.exceptions._RetriableRequest()
googlemaps.exceptions._RetriableRequest

During handling of the above exception, another exception occurred:

Traceback (most recent call last):
  File "/usr/local/lib/python3.6/site-packages/googlemaps/client.py", line 253, in _request
    result = self._get_body(response)
  File "/usr/local/lib/python3.6/site-packages/googlemaps/client.py", line 276, in _get_body
    raise googlemaps.exceptions._RetriableRequest()
googlemaps.exceptions._RetriableRequest

During handling of the above exception, another exception occurred:

Traceback (most recent call last):
  File "/usr/local/lib/python3.6/site-packages/googlemaps/client.py", line 253, in _request
    result = self._get_body(response)
  File "/usr/local/lib/python3.6/site-packages/googlemaps/client.py", line 276, in _get_body
    raise googlemaps.exceptions._RetriableRequest()
googlemaps.exceptions._RetriableRequest

During handling of the above exception, another exception occurred:

Traceback (most recent call last):
  File "/usr/local/lib/python3.6/site-packages/googlemaps/client.py", line 253, in _request
    result = self._get_body(response)
  File "/usr/local/lib/python3.6/site-packages/googlemaps/client.py", line 276, in _get_body
    raise googlemaps.exceptions._RetriableRequest()
googlemaps.exceptions._RetriableRequest

During handling of the above exception, another exception occurred:

Traceback (most recent call last):
  File "/usr/local/lib/python3.6/site-packages/googlemaps/client.py", line 253, in _request
    result = self._get_body(response)
  File "/usr/local/lib/python3.6/site-packages/googlemaps/client.py", line 276, in _get_body
    raise googlemaps.exceptions._RetriableRequest()
googlemaps.exceptions._RetriableRequest

During handling of the above exception, another exception occurred:

Traceback (most recent call last):
  File "/usr/local/lib/python3.6/site-packages/googlemaps/client.py", line 253, in _request
    result = self._get_body(response)
  File "/usr/local/lib/python3.6/site-packages/googlemaps/client.py", line 276, in _get_body
    raise googlemaps.exceptions._RetriableRequest()
googlemaps.exceptions._RetriableRequest

During handling of the above exception, another exception occurred:

Traceback (most recent call last):
  File "/usr/local/lib/python3.6/site-packages/googlemaps/client.py", line 253, in _request
    result = self._get_body(response)
  File "/usr/local/lib/python3.6/site-packages/googlemaps/client.py", line 276, in _get_body
    raise googlemaps.exceptions._RetriableRequest()
googlemaps.exceptions._RetriableRequest

During handling of the above exception, another exception occurred:

Traceback (most recent call last):
  File "/usr/local/lib/python3.6/site-packages/googlemaps/client.py", line 253, in _request
    result = self._get_body(response)
  File "/usr/local/lib/python3.6/site-packages/googlemaps/client.py", line 276, in _get_body
    raise googlemaps.exceptions._RetriableRequest()
googlemaps.exceptions._RetriableRequest

During handling of the above exception, another exception occurred:

Traceback (most recent call last):
  File "/usr/local/lib/python3.6/site-packages/googlemaps/client.py", line 253, in _request
    result = self._get_body(response)
  File "/usr/local/lib/python3.6/site-packages/googlemaps/client.py", line 276, in _get_body
    raise googlemaps.exceptions._RetriableRequest()
googlemaps.exceptions._RetriableRequest

During handling of the above exception, another exception occurred:

Traceback (most recent call last):
  File "/usr/local/lib/python3.6/site-packages/homeassistant/helpers/entity.py", line 221, in async_update_ha_state
    await self.async_device_update()
  File "/usr/local/lib/python3.6/site-packages/homeassistant/helpers/entity.py", line 349, in async_device_update
    await self.hass.async_add_executor_job(self.update)
  File "/usr/local/lib/python3.6/concurrent/futures/thread.py", line 56, in run
    result = self.fn(*self.args, **self.kwargs)
  File "/usr/local/lib/python3.6/site-packages/homeassistant/util/__init__.py", line 324, in wrapper
    result = method(*args, **kwargs)
  File "/usr/local/lib/python3.6/site-packages/homeassistant/components/sensor/google_travel_time.py", line 242, in update
    self._origin, self._destination, **options_copy)
  File "/usr/local/lib/python3.6/site-packages/googlemaps/client.py", line 356, in wrapper
    result = func(*args, **kwargs)
  File "/usr/local/lib/python3.6/site-packages/googlemaps/distance_matrix.py", line 130, in distance_matrix
    return client._request("/maps/api/distancematrix/json", params)
  File "/usr/local/lib/python3.6/site-packages/googlemaps/client.py", line 260, in _request
    extract_body, requests_kwargs, post_json)
  File "/usr/local/lib/python3.6/site-packages/googlemaps/client.py", line 260, in _request
    extract_body, requests_kwargs, post_json)
  File "/usr/local/lib/python3.6/site-packages/googlemaps/client.py", line 260, in _request
    extract_body, requests_kwargs, post_json)
  [Previous line repeated 8 more times]
  File "/usr/local/lib/python3.6/site-packages/googlemaps/client.py", line 203, in _request
    raise googlemaps.exceptions.Timeout()
googlemaps.exceptions.Timeout
2018-12-10 19:57:47 WARNING (MainThread) [homeassistant.helpers.entity] Update of sensor.google_travel_time__driving is taking over 10 seconds
2018-12-10 19:58:08 WARNING (MainThread) [homeassistant.components.sensor] Updating google_travel_time sensor took longer than the scheduled update interval 0:00:30
2018-12-10 19:58:37 ERROR (MainThread) [homeassistant.helpers.entity] Update for sensor.google_travel_time__driving fails
Traceback (most recent call last):
  File "/usr/local/lib/python3.6/site-packages/googlemaps/client.py", line 253, in _request
    result = self._get_body(response)
  File "/usr/local/lib/python3.6/site-packages/googlemaps/client.py", line 276, in _get_body
    raise googlemaps.exceptions._RetriableRequest()
googlemaps.exceptions._RetriableRequest

During handling of the above exception, another exception occurred:

Traceback (most recent call last):
  File "/usr/local/lib/python3.6/site-packages/googlemaps/client.py", line 253, in _request
    result = self._get_body(response)
  File "/usr/local/lib/python3.6/site-packages/googlemaps/client.py", line 276, in _get_body
    raise googlemaps.exceptions._RetriableRequest()
googlemaps.exceptions._RetriableRequest

During handling of the above exception, another exception occurred:

Traceback (most recent call last):
  File "/usr/local/lib/python3.6/site-packages/googlemaps/client.py", line 253, in _request
    result = self._get_body(response)
  File "/usr/local/lib/python3.6/site-packages/googlemaps/client.py", line 276, in _get_body
    raise googlemaps.exceptions._RetriableRequest()
googlemaps.exceptions._RetriableRequest

During handling of the above exception, another exception occurred:

Traceback (most recent call last):
  File "/usr/local/lib/python3.6/site-packages/googlemaps/client.py", line 253, in _request
    result = self._get_body(response)
  File "/usr/local/lib/python3.6/site-packages/googlemaps/client.py", line 276, in _get_body
    raise googlemaps.exceptions._RetriableRequest()
googlemaps.exceptions._RetriableRequest

During handling of the above exception, another exception occurred:

Traceback (most recent call last):
  File "/usr/local/lib/python3.6/site-packages/googlemaps/client.py", line 253, in _request
    result = self._get_body(response)
  File "/usr/local/lib/python3.6/site-packages/googlemaps/client.py", line 276, in _get_body
    raise googlemaps.exceptions._RetriableRequest()
googlemaps.exceptions._RetriableRequest

During handling of the above exception, another exception occurred:

Traceback (most recent call last):
  File "/usr/local/lib/python3.6/site-packages/googlemaps/client.py", line 253, in _request
    result = self._get_body(response)
  File "/usr/local/lib/python3.6/site-packages/googlemaps/client.py", line 276, in _get_body
    raise googlemaps.exceptions._RetriableRequest()
googlemaps.exceptions._RetriableRequest

During handling of the above exception, another exception occurred:

Traceback (most recent call last):
  File "/usr/local/lib/python3.6/site-packages/googlemaps/client.py", line 253, in _request
    result = self._get_body(response)
  File "/usr/local/lib/python3.6/site-packages/googlemaps/client.py", line 276, in _get_body
    raise googlemaps.exceptions._RetriableRequest()
googlemaps.exceptions._RetriableRequest

During handling of the above exception, another exception occurred:

Traceback (most recent call last):
  File "/usr/local/lib/python3.6/site-packages/googlemaps/client.py", line 253, in _request
    result = self._get_body(response)
  File "/usr/local/lib/python3.6/site-packages/googlemaps/client.py", line 276, in _get_body
    raise googlemaps.exceptions._RetriableRequest()
googlemaps.exceptions._RetriableRequest

During handling of the above exception, another exception occurred:

Traceback (most recent call last):
  File "/usr/local/lib/python3.6/site-packages/googlemaps/client.py", line 253, in _request
    result = self._get_body(response)
  File "/usr/local/lib/python3.6/site-packages/googlemaps/client.py", line 276, in _get_body
    raise googlemaps.exceptions._RetriableRequest()
googlemaps.exceptions._RetriableRequest

During handling of the above exception, another exception occurred:

Traceback (most recent call last):
  File "/usr/local/lib/python3.6/site-packages/googlemaps/client.py", line 253, in _request
    result = self._get_body(response)
  File "/usr/local/lib/python3.6/site-packages/googlemaps/client.py", line 276, in _get_body
    raise googlemaps.exceptions._RetriableRequest()
googlemaps.exceptions._RetriableRequest

During handling of the above exception, another exception occurred:

Traceback (most recent call last):
  File "/usr/local/lib/python3.6/site-packages/googlemaps/client.py", line 253, in _request
    result = self._get_body(response)
  File "/usr/local/lib/python3.6/site-packages/googlemaps/client.py", line 276, in _get_body
    raise googlemaps.exceptions._RetriableRequest()
googlemaps.exceptions._RetriableRequest

During handling of the above exception, another exception occurred:

Traceback (most recent call last):
  File "/usr/local/lib/python3.6/site-packages/homeassistant/helpers/entity.py", line 221, in async_update_ha_state
    await self.async_device_update()
  File "/usr/local/lib/python3.6/site-packages/homeassistant/helpers/entity.py", line 349, in async_device_update
    await self.hass.async_add_executor_job(self.update)
  File "/usr/local/lib/python3.6/concurrent/futures/thread.py", line 56, in run
    result = self.fn(*self.args, **self.kwargs)
  File "/usr/local/lib/python3.6/site-packages/homeassistant/util/__init__.py", line 324, in wrapper
    result = method(*args, **kwargs)
  File "/usr/local/lib/python3.6/site-packages/homeassistant/components/sensor/google_travel_time.py", line 242, in update
    self._origin, self._destination, **options_copy)
  File "/usr/local/lib/python3.6/site-packages/googlemaps/client.py", line 356, in wrapper
    result = func(*args, **kwargs)
  File "/usr/local/lib/python3.6/site-packages/googlemaps/distance_matrix.py", line 130, in distance_matrix
    return client._request("/maps/api/distancematrix/json", params)
  File "/usr/local/lib/python3.6/site-packages/googlemaps/client.py", line 260, in _request
    extract_body, requests_kwargs, post_json)
  File "/usr/local/lib/python3.6/site-packages/googlemaps/client.py", line 260, in _request
    extract_body, requests_kwargs, post_json)
  File "/usr/local/lib/python3.6/site-packages/googlemaps/client.py", line 260, in _request
    extract_body, requests_kwargs, post_json)
  [Previous line repeated 7 more times]
  File "/usr/local/lib/python3.6/site-packages/googlemaps/client.py", line 203, in _request
    raise googlemaps.exceptions.Timeout()
googlemaps.exceptions.Timeout
2018-12-10 19:58:49 WARNING (MainThread) [homeassistant.helpers.entity] Update of sensor.google_travel_time__driving is taking over 10 seconds
2018-12-10 19:59:10 WARNING (MainThread) [homeassistant.components.sensor] Updating google_travel_time sensor took longer than the scheduled update interval 0:00:30
2018-12-10 19:59:40 WARNING (MainThread) [homeassistant.components.sensor] Updating google_travel_time sensor took longer than the scheduled update interval 0:00:30
2018-12-10 19:59:47 ERROR (MainThread) [homeassistant.helpers.entity] Update for sensor.google_travel_time__driving fails
Traceback (most recent call last):
  File "/usr/local/lib/python3.6/site-packages/googlemaps/client.py", line 253, in _request
    result = self._get_body(response)
  File "/usr/local/lib/python3.6/site-packages/googlemaps/client.py", line 276, in _get_body
    raise googlemaps.exceptions._RetriableRequest()
googlemaps.exceptions._RetriableRequest

During handling of the above exception, another exception occurred:

Traceback (most recent call last):
  File "/usr/local/lib/python3.6/site-packages/googlemaps/client.py", line 253, in _request
    result = self._get_body(response)
  File "/usr/local/lib/python3.6/site-packages/googlemaps/client.py", line 276, in _get_body
    raise googlemaps.exceptions._RetriableRequest()
googlemaps.exceptions._RetriableRequest

During handling of the above exception, another exception occurred:

Traceback (most recent call last):
  File "/usr/local/lib/python3.6/site-packages/googlemaps/client.py", line 253, in _request
    result = self._get_body(response)
  File "/usr/local/lib/python3.6/site-packages/googlemaps/client.py", line 276, in _get_body
    raise googlemaps.exceptions._RetriableRequest()
googlemaps.exceptions._RetriableRequest

During handling of the above exception, another exception occurred:

Traceback (most recent call last):
  File "/usr/local/lib/python3.6/site-packages/googlemaps/client.py", line 253, in _request
    result = self._get_body(response)
  File "/usr/local/lib/python3.6/site-packages/googlemaps/client.py", line 276, in _get_body
    raise googlemaps.exceptions._RetriableRequest()
googlemaps.exceptions._RetriableRequest

During handling of the above exception, another exception occurred:

Traceback (most recent call last):
  File "/usr/local/lib/python3.6/site-packages/googlemaps/client.py", line 253, in _request
    result = self._get_body(response)
  File "/usr/local/lib/python3.6/site-packages/googlemaps/client.py", line 276, in _get_body
    raise googlemaps.exceptions._RetriableRequest()
googlemaps.exceptions._RetriableRequest

During handling of the above exception, another exception occurred:

Traceback (most recent call last):
  File "/usr/local/lib/python3.6/site-packages/googlemaps/client.py", line 253, in _request
    result = self._get_body(response)
  File "/usr/local/lib/python3.6/site-packages/googlemaps/client.py", line 276, in _get_body
    raise googlemaps.exceptions._RetriableRequest()
googlemaps.exceptions._RetriableRequest

During handling of the above exception, another exception occurred:

Traceback (most recent call last):
  File "/usr/local/lib/python3.6/site-packages/googlemaps/client.py", line 253, in _request
    result = self._get_body(response)
  File "/usr/local/lib/python3.6/site-packages/googlemaps/client.py", line 276, in _get_body
    raise googlemaps.exceptions._RetriableRequest()
googlemaps.exceptions._RetriableRequest

During handling of the above exception, another exception occurred:

Traceback (most recent call last):
  File "/usr/local/lib/python3.6/site-packages/googlemaps/client.py", line 253, in _request
    result = self._get_body(response)
  File "/usr/local/lib/python3.6/site-packages/googlemaps/client.py", line 276, in _get_body
    raise googlemaps.exceptions._RetriableRequest()
googlemaps.exceptions._RetriableRequest

During handling of the above exception, another exception occurred:

Traceback (most recent call last):
  File "/usr/local/lib/python3.6/site-packages/googlemaps/client.py", line 253, in _request
    result = self._get_body(response)
  File "/usr/local/lib/python3.6/site-packages/googlemaps/client.py", line 276, in _get_body
    raise googlemaps.exceptions._RetriableRequest()
googlemaps.exceptions._RetriableRequest

During handling of the above exception, another exception occurred:

Traceback (most recent call last):
  File "/usr/local/lib/python3.6/site-packages/googlemaps/client.py", line 253, in _request
    result = self._get_body(response)
  File "/usr/local/lib/python3.6/site-packages/googlemaps/client.py", line 276, in _get_body
    raise googlemaps.exceptions._RetriableRequest()
googlemaps.exceptions._RetriableRequest

During handling of the above exception, another exception occurred:

Traceback (most recent call last):
  File "/usr/local/lib/python3.6/site-packages/googlemaps/client.py", line 253, in _request
    result = self._get_body(response)
  File "/usr/local/lib/python3.6/site-packages/googlemaps/client.py", line 276, in _get_body
    raise googlemaps.exceptions._RetriableRequest()
googlemaps.exceptions._RetriableRequest

During handling of the above exception, another exception occurred:

Traceback (most recent call last):
  File "/usr/local/lib/python3.6/site-packages/homeassistant/helpers/entity.py", line 221, in async_update_ha_state
    await self.async_device_update()
  File "/usr/local/lib/python3.6/site-packages/homeassistant/helpers/entity.py", line 349, in async_device_update
    await self.hass.async_add_executor_job(self.update)
  File "/usr/local/lib/python3.6/concurrent/futures/thread.py", line 56, in run
    result = self.fn(*self.args, **self.kwargs)
  File "/usr/local/lib/python3.6/site-packages/homeassistant/util/__init__.py", line 324, in wrapper
    result = method(*args, **kwargs)
  File "/usr/local/lib/python3.6/site-packages/homeassistant/components/sensor/google_travel_time.py", line 242, in update
    self._origin, self._destination, **options_copy)
  File "/usr/local/lib/python3.6/site-packages/googlemaps/client.py", line 356, in wrapper
    result = func(*args, **kwargs)
  File "/usr/local/lib/python3.6/site-packages/googlemaps/distance_matrix.py", line 130, in distance_matrix
    return client._request("/maps/api/distancematrix/json", params)
  File "/usr/local/lib/python3.6/site-packages/googlemaps/client.py", line 260, in _request
    extract_body, requests_kwargs, post_json)
  File "/usr/local/lib/python3.6/site-packages/googlemaps/client.py", line 260, in _request
    extract_body, requests_kwargs, post_json)
  File "/usr/local/lib/python3.6/site-packages/googlemaps/client.py", line 260, in _request
    extract_body, requests_kwargs, post_json)
  [Previous line repeated 7 more times]
  File "/usr/local/lib/python3.6/site-packages/googlemaps/client.py", line 203, in _request
    raise googlemaps.exceptions.Timeout()
googlemaps.exceptions.Timeout
2018-12-10 20:00:21 WARNING (MainThread) [homeassistant.helpers.entity] Update of sensor.google_travel_time__driving is taking over 10 seconds
2018-12-10 20:00:40 ERROR (SyncWorker_18) [homeassistant.components.sensor.waze_travel_time] Error on retrieving data: Internal Error
2018-12-10 20:00:42 WARNING (MainThread) [homeassistant.components.sensor] Updating google_travel_time sensor took longer than the scheduled update interval 0:00:30
2018-12-10 20:01:13 WARNING (MainThread) [homeassistant.components.sensor] Updating google_travel_time sensor took longer than the scheduled update interval 0:00:30
2018-12-10 20:01:17 ERROR (MainThread) [homeassistant.helpers.entity] Update for sensor.google_travel_time__driving fails
Traceback (most recent call last):
  File "/usr/local/lib/python3.6/site-packages/googlemaps/client.py", line 253, in _request
    result = self._get_body(response)
  File "/usr/local/lib/python3.6/site-packages/googlemaps/client.py", line 276, in _get_body
    raise googlemaps.exceptions._RetriableRequest()
googlemaps.exceptions._RetriableRequest

During handling of the above exception, another exception occurred:

Traceback (most recent call last):
  File "/usr/local/lib/python3.6/site-packages/googlemaps/client.py", line 253, in _request
    result = self._get_body(response)
  File "/usr/local/lib/python3.6/site-packages/googlemaps/client.py", line 276, in _get_body
    raise googlemaps.exceptions._RetriableRequest()
googlemaps.exceptions._RetriableRequest

During handling of the above exception, another exception occurred:

Traceback (most recent call last):
  File "/usr/local/lib/python3.6/site-packages/googlemaps/client.py", line 253, in _request
    result = self._get_body(response)
  File "/usr/local/lib/python3.6/site-packages/googlemaps/client.py", line 276, in _get_body
    raise googlemaps.exceptions._RetriableRequest()
googlemaps.exceptions._RetriableRequest

During handling of the above exception, another exception occurred:

Traceback (most recent call last):
  File "/usr/local/lib/python3.6/site-packages/googlemaps/client.py", line 253, in _request
    result = self._get_body(response)
  File "/usr/local/lib/python3.6/site-packages/googlemaps/client.py", line 276, in _get_body
    raise googlemaps.exceptions._RetriableRequest()
googlemaps.exceptions._RetriableRequest

During handling of the above exception, another exception occurred:

Traceback (most recent call last):
  File "/usr/local/lib/python3.6/site-packages/googlemaps/client.py", line 253, in _request
    result = self._get_body(response)
  File "/usr/local/lib/python3.6/site-packages/googlemaps/client.py", line 276, in _get_body
    raise googlemaps.exceptions._RetriableRequest()
googlemaps.exceptions._RetriableRequest

During handling of the above exception, another exception occurred:

Traceback (most recent call last):
  File "/usr/local/lib/python3.6/site-packages/googlemaps/client.py", line 253, in _request
    result = self._get_body(response)
  File "/usr/local/lib/python3.6/site-packages/googlemaps/client.py", line 276, in _get_body
    raise googlemaps.exceptions._RetriableRequest()
googlemaps.exceptions._RetriableRequest

During handling of the above exception, another exception occurred:

Traceback (most recent call last):
  File "/usr/local/lib/python3.6/site-packages/googlemaps/client.py", line 253, in _request
    result = self._get_body(response)
  File "/usr/local/lib/python3.6/site-packages/googlemaps/client.py", line 276, in _get_body
    raise googlemaps.exceptions._RetriableRequest()
googlemaps.exceptions._RetriableRequest

During handling of the above exception, another exception occurred:

Traceback (most recent call last):
  File "/usr/local/lib/python3.6/site-packages/googlemaps/client.py", line 253, in _request
    result = self._get_body(response)
  File "/usr/local/lib/python3.6/site-packages/googlemaps/client.py", line 276, in _get_body
    raise googlemaps.exceptions._RetriableRequest()
googlemaps.exceptions._RetriableRequest

During handling of the above exception, another exception occurred:

Traceback (most recent call last):
  File "/usr/local/lib/python3.6/site-packages/googlemaps/client.py", line 253, in _request
    result = self._get_body(response)
  File "/usr/local/lib/python3.6/site-packages/googlemaps/client.py", line 276, in _get_body
    raise googlemaps.exceptions._RetriableRequest()
googlemaps.exceptions._RetriableRequest

During handling of the above exception, another exception occurred:

Traceback (most recent call last):
  File "/usr/local/lib/python3.6/site-packages/googlemaps/client.py", line 253, in _request
    result = self._get_body(response)
  File "/usr/local/lib/python3.6/site-packages/googlemaps/client.py", line 276, in _get_body
    raise googlemaps.exceptions._RetriableRequest()
googlemaps.exceptions._RetriableRequest

During handling of the above exception, another exception occurred:

Traceback (most recent call last):
  File "/usr/local/lib/python3.6/site-packages/googlemaps/client.py", line 253, in _request
    result = self._get_body(response)
  File "/usr/local/lib/python3.6/site-packages/googlemaps/client.py", line 276, in _get_body
    raise googlemaps.exceptions._RetriableRequest()
googlemaps.exceptions._RetriableRequest

During handling of the above exception, another exception occurred:

Traceback (most recent call last):
  File "/usr/local/lib/python3.6/site-packages/homeassistant/helpers/entity.py", line 221, in async_update_ha_state
    await self.async_device_update()
  File "/usr/local/lib/python3.6/site-packages/homeassistant/helpers/entity.py", line 349, in async_device_update
    await self.hass.async_add_executor_job(self.update)
  File "/usr/local/lib/python3.6/concurrent/futures/thread.py", line 56, in run
    result = self.fn(*self.args, **self.kwargs)
  File "/usr/local/lib/python3.6/site-packages/homeassistant/util/__init__.py", line 324, in wrapper
    result = method(*args, **kwargs)
  File "/usr/local/lib/python3.6/site-packages/homeassistant/components/sensor/google_travel_time.py", line 242, in update
    self._origin, self._destination, **options_copy)
  File "/usr/local/lib/python3.6/site-packages/googlemaps/client.py", line 356, in wrapper
    result = func(*args, **kwargs)
  File "/usr/local/lib/python3.6/site-packages/googlemaps/distance_matrix.py", line 130, in distance_matrix
    return client._request("/maps/api/distancematrix/json", params)
  File "/usr/local/lib/python3.6/site-packages/googlemaps/client.py", line 260, in _request
    extract_body, requests_kwargs, post_json)
  File "/usr/local/lib/python3.6/site-packages/googlemaps/client.py", line 260, in _request
    extract_body, requests_kwargs, post_json)
  File "/usr/local/lib/python3.6/site-packages/googlemaps/client.py", line 260, in _request
    extract_body, requests_kwargs, post_json)
  [Previous line repeated 7 more times]
  File "/usr/local/lib/python3.6/site-packages/googlemaps/client.py", line 203, in _request
    raise googlemaps.exceptions.Timeout()
googlemaps.exceptions.Timeout
2018-12-10 20:01:54 WARNING (MainThread) [homeassistant.helpers.entity] Update of sensor.google_travel_time__driving is taking over 10 seconds
2018-12-10 20:02:15 WARNING (MainThread) [homeassistant.components.sensor] Updating google_travel_time sensor took longer than the scheduled update interval 0:00:30
2018-12-10 20:02:46 WARNING (MainThread) [homeassistant.components.sensor] Updating google_travel_time sensor took longer than the scheduled update interval 0:00:30
2018-12-10 20:03:05 ERROR (MainThread) [homeassistant.helpers.entity] Update for sensor.google_travel_time__driving fails
Traceback (most recent call last):
  File "/usr/local/lib/python3.6/site-packages/googlemaps/client.py", line 253, in _request
    result = self._get_body(response)
  File "/usr/local/lib/python3.6/site-packages/googlemaps/client.py", line 276, in _get_body
    raise googlemaps.exceptions._RetriableRequest()
googlemaps.exceptions._RetriableRequest

During handling of the above exception, another exception occurred:

Traceback (most recent call last):
  File "/usr/local/lib/python3.6/site-packages/googlemaps/client.py", line 253, in _request
    result = self._get_body(response)
  File "/usr/local/lib/python3.6/site-packages/googlemaps/client.py", line 276, in _get_body
    raise googlemaps.exceptions._RetriableRequest()
googlemaps.exceptions._RetriableRequest

During handling of the above exception, another exception occurred:

Traceback (most recent call last):
  File "/usr/local/lib/python3.6/site-packages/googlemaps/client.py", line 253, in _request
    result = self._get_body(response)
  File "/usr/local/lib/python3.6/site-packages/googlemaps/client.py", line 276, in _get_body
    raise googlemaps.exceptions._RetriableRequest()
googlemaps.exceptions._RetriableRequest

During handling of the above exception, another exception occurred:

Traceback (most recent call last):
  File "/usr/local/lib/python3.6/site-packages/googlemaps/client.py", line 253, in _request
    result = self._get_body(response)
  File "/usr/local/lib/python3.6/site-packages/googlemaps/client.py", line 276, in _get_body
    raise googlemaps.exceptions._RetriableRequest()
googlemaps.exceptions._RetriableRequest

During handling of the above exception, another exception occurred:

Traceback (most recent call last):
  File "/usr/local/lib/python3.6/site-packages/googlemaps/client.py", line 253, in _request
    result = self._get_body(response)
  File "/usr/local/lib/python3.6/site-packages/googlemaps/client.py", line 276, in _get_body
    raise googlemaps.exceptions._RetriableRequest()
googlemaps.exceptions._RetriableRequest

During handling of the above exception, another exception occurred:

Traceback (most recent call last):
  File "/usr/local/lib/python3.6/site-packages/googlemaps/client.py", line 253, in _request
    result = self._get_body(response)
  File "/usr/local/lib/python3.6/site-packages/googlemaps/client.py", line 276, in _get_body
    raise googlemaps.exceptions._RetriableRequest()
googlemaps.exceptions._RetriableRequest

During handling of the above exception, another exception occurred:

Traceback (most recent call last):
  File "/usr/local/lib/python3.6/site-packages/googlemaps/client.py", line 253, in _request
    result = self._get_body(response)
  File "/usr/local/lib/python3.6/site-packages/googlemaps/client.py", line 276, in _get_body
    raise googlemaps.exceptions._RetriableRequest()
googlemaps.exceptions._RetriableRequest

During handling of the above exception, another exception occurred:

Traceback (most recent call last):
  File "/usr/local/lib/python3.6/site-packages/googlemaps/client.py", line 253, in _request
    result = self._get_body(response)
  File "/usr/local/lib/python3.6/site-packages/googlemaps/client.py", line 276, in _get_body
    raise googlemaps.exceptions._RetriableRequest()
googlemaps.exceptions._RetriableRequest

During handling of the above exception, another exception occurred:

Traceback (most recent call last):
  File "/usr/local/lib/python3.6/site-packages/googlemaps/client.py", line 253, in _request
    result = self._get_body(response)
  File "/usr/local/lib/python3.6/site-packages/googlemaps/client.py", line 276, in _get_body
    raise googlemaps.exceptions._RetriableRequest()
googlemaps.exceptions._RetriableRequest

During handling of the above exception, another exception occurred:

Traceback (most recent call last):
  File "/usr/local/lib/python3.6/site-packages/googlemaps/client.py", line 253, in _request
    result = self._get_body(response)
  File "/usr/local/lib/python3.6/site-packages/googlemaps/client.py", line 276, in _get_body
    raise googlemaps.exceptions._RetriableRequest()
googlemaps.exceptions._RetriableRequest

During handling of the above exception, another exception occurred:

Traceback (most recent call last):
  File "/usr/local/lib/python3.6/site-packages/googlemaps/client.py", line 253, in _request
    result = self._get_body(response)
  File "/usr/local/lib/python3.6/site-packages/googlemaps/client.py", line 276, in _get_body
    raise googlemaps.exceptions._RetriableRequest()
googlemaps.exceptions._RetriableRequest

During handling of the above exception, another exception occurred:

Traceback (most recent call last):
  File "/usr/local/lib/python3.6/site-packages/googlemaps/client.py", line 253, in _request
    result = self._get_body(response)
  File "/usr/local/lib/python3.6/site-packages/googlemaps/client.py", line 276, in _get_body
    raise googlemaps.exceptions._RetriableRequest()
googlemaps.exceptions._RetriableRequest

During handling of the above exception, another exception occurred:

Traceback (most recent call last):
  File "/usr/local/lib/python3.6/site-packages/homeassistant/helpers/entity.py", line 221, in async_update_ha_state
    await self.async_device_update()
  File "/usr/local/lib/python3.6/site-packages/homeassistant/helpers/entity.py", line 349, in async_device_update
    await self.hass.async_add_executor_job(self.update)
  File "/usr/local/lib/python3.6/concurrent/futures/thread.py", line 56, in run
    result = self.fn(*self.args, **self.kwargs)
  File "/usr/local/lib/python3.6/site-packages/homeassistant/util/__init__.py", line 324, in wrapper
    result = method(*args, **kwargs)
  File "/usr/local/lib/python3.6/site-packages/homeassistant/components/sensor/google_travel_time.py", line 242, in update
    self._origin, self._destination, **options_copy)
  File "/usr/local/lib/python3.6/site-packages/googlemaps/client.py", line 356, in wrapper
    result = func(*args, **kwargs)
  File "/usr/local/lib/python3.6/site-packages/googlemaps/distance_matrix.py", line 130, in distance_matrix
    return client._request("/maps/api/distancematrix/json", params)
  File "/usr/local/lib/python3.6/site-packages/googlemaps/client.py", line 260, in _request
    extract_body, requests_kwargs, post_json)
  File "/usr/local/lib/python3.6/site-packages/googlemaps/client.py", line 260, in _request
    extract_body, requests_kwargs, post_json)
  File "/usr/local/lib/python3.6/site-packages/googlemaps/client.py", line 260, in _request
    extract_body, requests_kwargs, post_json)
  [Previous line repeated 8 more times]
  File "/usr/local/lib/python3.6/site-packages/googlemaps/client.py", line 203, in _request
    raise googlemaps.exceptions.Timeout()
googlemaps.exceptions.Timeout
2018-12-10 20:03:27 WARNING (MainThread) [homeassistant.helpers.entity] Update of sensor.google_travel_time__driving is taking over 10 seconds
2018-12-10 20:03:48 WARNING (MainThread) [homeassistant.components.sensor] Updating google_travel_time sensor took longer than the scheduled update interval 0:00:30
2018-12-10 20:04:19 WARNING (MainThread) [homeassistant.components.sensor] Updating google_travel_time sensor took longer than the scheduled update interval 0:00:30
2018-12-10 20:04:50 WARNING (MainThread) [homeassistant.components.sensor] Updating google_travel_time sensor took longer than the scheduled update interval 0:00:30
2018-12-10 20:04:58 ERROR (MainThread) [homeassistant.helpers.entity] Update for sensor.google_travel_time__driving fails
Traceback (most recent call last):
  File "/usr/local/lib/python3.6/site-packages/googlemaps/client.py", line 253, in _request
    result = self._get_body(response)
  File "/usr/local/lib/python3.6/site-packages/googlemaps/client.py", line 276, in _get_body
    raise googlemaps.exceptions._RetriableRequest()
googlemaps.exceptions._RetriableRequest

During handling of the above exception, another exception occurred:

Traceback (most recent call last):
  File "/usr/local/lib/python3.6/site-packages/googlemaps/client.py", line 253, in _request
    result = self._get_body(response)
  File "/usr/local/lib/python3.6/site-packages/googlemaps/client.py", line 276, in _get_body
    raise googlemaps.exceptions._RetriableRequest()
googlemaps.exceptions._RetriableRequest

During handling of the above exception, another exception occurred:

Traceback (most recent call last):
  File "/usr/local/lib/python3.6/site-packages/googlemaps/client.py", line 253, in _request
    result = self._get_body(response)
  File "/usr/local/lib/python3.6/site-packages/googlemaps/client.py", line 276, in _get_body
    raise googlemaps.exceptions._RetriableRequest()
googlemaps.exceptions._RetriableRequest

During handling of the above exception, another exception occurred:

Traceback (most recent call last):
  File "/usr/local/lib/python3.6/site-packages/googlemaps/client.py", line 253, in _request
    result = self._get_body(response)
  File "/usr/local/lib/python3.6/site-packages/googlemaps/client.py", line 276, in _get_body
    raise googlemaps.exceptions._RetriableRequest()
googlemaps.exceptions._RetriableRequest

During handling of the above exception, another exception occurred:

Traceback (most recent call last):
  File "/usr/local/lib/python3.6/site-packages/googlemaps/client.py", line 253, in _request
    result = self._get_body(response)
  File "/usr/local/lib/python3.6/site-packages/googlemaps/client.py", line 276, in _get_body
    raise googlemaps.exceptions._RetriableRequest()
googlemaps.exceptions._RetriableRequest

During handling of the above exception, another exception occurred:

Traceback (most recent call last):
  File "/usr/local/lib/python3.6/site-packages/googlemaps/client.py", line 253, in _request
    result = self._get_body(response)
  File "/usr/local/lib/python3.6/site-packages/googlemaps/client.py", line 276, in _get_body
    raise googlemaps.exceptions._RetriableRequest()
googlemaps.exceptions._RetriableRequest

During handling of the above exception, another exception occurred:

Traceback (most recent call last):
  File "/usr/local/lib/python3.6/site-packages/googlemaps/client.py", line 253, in _request
    result = self._get_body(response)
  File "/usr/local/lib/python3.6/site-packages/googlemaps/client.py", line 276, in _get_body
    raise googlemaps.exceptions._RetriableRequest()
googlemaps.exceptions._RetriableRequest

During handling of the above exception, another exception occurred:

Traceback (most recent call last):
  File "/usr/local/lib/python3.6/site-packages/googlemaps/client.py", line 253, in _request
    result = self._get_body(response)
  File "/usr/local/lib/python3.6/site-packages/googlemaps/client.py", line 276, in _get_body
    raise googlemaps.exceptions._RetriableRequest()
googlemaps.exceptions._RetriableRequest

During handling of the above exception, another exception occurred:

Traceback (most recent call last):
  File "/usr/local/lib/python3.6/site-packages/googlemaps/client.py", line 253, in _request
    result = self._get_body(response)
  File "/usr/local/lib/python3.6/site-packages/googlemaps/client.py", line 276, in _get_body
    raise googlemaps.exceptions._RetriableRequest()
googlemaps.exceptions._RetriableRequest

During handling of the above exception, another exception occurred:

Traceback (most recent call last):
  File "/usr/local/lib/python3.6/site-packages/googlemaps/client.py", line 253, in _request
    result = self._get_body(response)
  File "/usr/local/lib/python3.6/site-packages/googlemaps/client.py", line 276, in _get_body
    raise googlemaps.exceptions._RetriableRequest()
googlemaps.exceptions._RetriableRequest

During handling of the above exception, another exception occurred:

Traceback (most recent call last):
  File "/usr/local/lib/python3.6/site-packages/googlemaps/client.py", line 253, in _request
    result = self._get_body(response)
  File "/usr/local/lib/python3.6/site-packages/googlemaps/client.py", line 276, in _get_body
    raise googlemaps.exceptions._RetriableRequest()
googlemaps.exceptions._RetriableRequest

During handling of the above exception, another exception occurred:

Traceback (most recent call last):
  File "/usr/local/lib/python3.6/site-packages/googlemaps/client.py", line 253, in _request
    result = self._get_body(response)
  File "/usr/local/lib/python3.6/site-packages/googlemaps/client.py", line 276, in _get_body
    raise googlemaps.exceptions._RetriableRequest()
googlemaps.exceptions._RetriableRequest

During handling of the above exception, another exception occurred:

Traceback (most recent call last):
  File "/usr/local/lib/python3.6/site-packages/homeassistant/helpers/entity.py", line 221, in async_update_ha_state
    await self.async_device_update()
  File "/usr/local/lib/python3.6/site-packages/homeassistant/helpers/entity.py", line 349, in async_device_update
    await self.hass.async_add_executor_job(self.update)
  File "/usr/local/lib/python3.6/concurrent/futures/thread.py", line 56, in run
    result = self.fn(*self.args, **self.kwargs)
  File "/usr/local/lib/python3.6/site-packages/homeassistant/util/__init__.py", line 324, in wrapper
    result = method(*args, **kwargs)
  File "/usr/local/lib/python3.6/site-packages/homeassistant/components/sensor/google_travel_time.py", line 242, in update
    self._origin, self._destination, **options_copy)
  File "/usr/local/lib/python3.6/site-packages/googlemaps/client.py", line 356, in wrapper
    result = func(*args, **kwargs)
  File "/usr/local/lib/python3.6/site-packages/googlemaps/distance_matrix.py", line 130, in distance_matrix
    return client._request("/maps/api/distancematrix/json", params)
  File "/usr/local/lib/python3.6/site-packages/googlemaps/client.py", line 260, in _request
    extract_body, requests_kwargs, post_json)
  File "/usr/local/lib/python3.6/site-packages/googlemaps/client.py", line 260, in _request
    extract_body, requests_kwargs, post_json)
  File "/usr/local/lib/python3.6/site-packages/googlemaps/client.py", line 260, in _request
    extract_body, requests_kwargs, post_json)
  [Previous line repeated 8 more times]
  File "/usr/local/lib/python3.6/site-packages/googlemaps/client.py", line 203, in _request
    raise googlemaps.exceptions.Timeout()
googlemaps.exceptions.Timeout
2018-12-10 20:05:31 WARNING (MainThread) [homeassistant.helpers.entity] Update of sensor.google_travel_time__driving is taking over 10 seconds
2018-12-10 20:05:40 ERROR (SyncWorker_11) [homeassistant.components.sensor.waze_travel_time] Error on retrieving data: Internal Error
2018-12-10 20:05:41 ERROR (MainThread) [homeassistant.helpers.entity] Update for sensor.uberx_price fails
Traceback (most recent call last):
  File "/usr/local/lib/python3.6/site-packages/homeassistant/helpers/entity.py", line 221, in async_update_ha_state
    await self.async_device_update()
  File "/usr/local/lib/python3.6/site-packages/homeassistant/helpers/entity.py", line 349, in async_device_update
    await self.hass.async_add_executor_job(self.update)
  File "/usr/local/lib/python3.6/concurrent/futures/thread.py", line 56, in run
    result = self.fn(*self.args, **self.kwargs)
  File "/usr/local/lib/python3.6/site-packages/homeassistant/components/sensor/uber.py", line 164, in update
    self.data.update()
  File "/usr/local/lib/python3.6/site-packages/homeassistant/util/__init__.py", line 324, in wrapper
    result = method(*args, **kwargs)
  File "/usr/local/lib/python3.6/site-packages/homeassistant/components/sensor/uber.py", line 211, in update
    self.end_latitude, self.end_longitude)
  File "/usr/local/lib/python3.6/site-packages/uber_rides/client.py", line 179, in get_price_estimates
    return self._api_call('GET', 'v1.2/estimates/price', args=args)
  File "/usr/local/lib/python3.6/site-packages/uber_rides/client.py", line 107, in _api_call
    return request.execute()
  File "/usr/local/lib/python3.6/site-packages/uber_rides/request.py", line 152, in execute
    return self._send(prepared_request)
  File "/usr/local/lib/python3.6/site-packages/uber_rides/request.py", line 136, in _send
    response = session.send(prepared_request)
  File "/usr/local/lib/python3.6/site-packages/requests/sessions.py", line 644, in send
    r = dispatch_hook('response', hooks, r, **kwargs)
  File "/usr/local/lib/python3.6/site-packages/requests/hooks.py", line 31, in dispatch_hook
    _hook_data = hook(hook_data, **kwargs)
  File "/usr/local/lib/python3.6/site-packages/uber_rides/utils/handlers.py", line 60, in error_handler
    raise ClientError(response, error_message)
  File "/usr/local/lib/python3.6/site-packages/uber_rides/errors.py", line 112, in __init__
    errors, meta = super(ClientError, self)._adapt_response(response)
  File "/usr/local/lib/python3.6/site-packages/uber_rides/errors.py", line 51, in _adapt_response
    raise UnknownHttpError(response)
uber_rides.errors.UnknownHttpError
2018-12-10 20:05:52 WARNING (MainThread) [homeassistant.components.sensor] Updating google_travel_time sensor took longer than the scheduled update interval 0:00:30
2018-12-10 20:06:22 ERROR (MainThread) [homeassistant.helpers.entity] Update for sensor.google_travel_time__driving fails
Traceback (most recent call last):
  File "/usr/local/lib/python3.6/site-packages/googlemaps/client.py", line 253, in _request
    result = self._get_body(response)
  File "/usr/local/lib/python3.6/site-packages/googlemaps/client.py", line 276, in _get_body
    raise googlemaps.exceptions._RetriableRequest()
googlemaps.exceptions._RetriableRequest

During handling of the above exception, another exception occurred:

Traceback (most recent call last):
  File "/usr/local/lib/python3.6/site-packages/googlemaps/client.py", line 253, in _request
    result = self._get_body(response)
  File "/usr/local/lib/python3.6/site-packages/googlemaps/client.py", line 276, in _get_body
    raise googlemaps.exceptions._RetriableRequest()
googlemaps.exceptions._RetriableRequest

During handling of the above exception, another exception occurred:

Traceback (most recent call last):
  File "/usr/local/lib/python3.6/site-packages/googlemaps/client.py", line 253, in _request
    result = self._get_body(response)
  File "/usr/local/lib/python3.6/site-packages/googlemaps/client.py", line 276, in _get_body
    raise googlemaps.exceptions._RetriableRequest()
googlemaps.exceptions._RetriableRequest

During handling of the above exception, another exception occurred:

Traceback (most recent call last):
  File "/usr/local/lib/python3.6/site-packages/googlemaps/client.py", line 253, in _request
    result = self._get_body(response)
  File "/usr/local/lib/python3.6/site-packages/googlemaps/client.py", line 276, in _get_body
    raise googlemaps.exceptions._RetriableRequest()
googlemaps.exceptions._RetriableRequest

During handling of the above exception, another exception occurred:

Traceback (most recent call last):
  File "/usr/local/lib/python3.6/site-packages/googlemaps/client.py", line 253, in _request
    result = self._get_body(response)
  File "/usr/local/lib/python3.6/site-packages/googlemaps/client.py", line 276, in _get_body
    raise googlemaps.exceptions._RetriableRequest()
googlemaps.exceptions._RetriableRequest

During handling of the above exception, another exception occurred:

Traceback (most recent call last):
  File "/usr/local/lib/python3.6/site-packages/googlemaps/client.py", line 253, in _request
    result = self._get_body(response)
  File "/usr/local/lib/python3.6/site-packages/googlemaps/client.py", line 276, in _get_body
    raise googlemaps.exceptions._RetriableRequest()
googlemaps.exceptions._RetriableRequest

During handling of the above exception, another exception occurred:

Traceback (most recent call last):
  File "/usr/local/lib/python3.6/site-packages/googlemaps/client.py", line 253, in _request
    result = self._get_body(response)
  File "/usr/local/lib/python3.6/site-packages/googlemaps/client.py", line 276, in _get_body
    raise googlemaps.exceptions._RetriableRequest()
googlemaps.exceptions._RetriableRequest

During handling of the above exception, another exception occurred:

Traceback (most recent call last):
  File "/usr/local/lib/python3.6/site-packages/googlemaps/client.py", line 253, in _request
    result = self._get_body(response)
  File "/usr/local/lib/python3.6/site-packages/googlemaps/client.py", line 276, in _get_body
    raise googlemaps.exceptions._RetriableRequest()
googlemaps.exceptions._RetriableRequest

During handling of the above exception, another exception occurred:

Traceback (most recent call last):
  File "/usr/local/lib/python3.6/site-packages/googlemaps/client.py", line 253, in _request
    result = self._get_body(response)
  File "/usr/local/lib/python3.6/site-packages/googlemaps/client.py", line 276, in _get_body
    raise googlemaps.exceptions._RetriableRequest()
googlemaps.exceptions._RetriableRequest

During handling of the above exception, another exception occurred:

Traceback (most recent call last):
  File "/usr/local/lib/python3.6/site-packages/googlemaps/client.py", line 253, in _request
    result = self._get_body(response)
  File "/usr/local/lib/python3.6/site-packages/googlemaps/client.py", line 276, in _get_body
    raise googlemaps.exceptions._RetriableRequest()
googlemaps.exceptions._RetriableRequest

During handling of the above exception, another exception occurred:

Traceback (most recent call last):
  File "/usr/local/lib/python3.6/site-packages/googlemaps/client.py", line 253, in _request
    result = self._get_body(response)
  File "/usr/local/lib/python3.6/site-packages/googlemaps/client.py", line 276, in _get_body
    raise googlemaps.exceptions._RetriableRequest()
googlemaps.exceptions._RetriableRequest

During handling of the above exception, another exception occurred:

Traceback (most recent call last):
  File "/usr/local/lib/python3.6/site-packages/googlemaps/client.py", line 253, in _request
    result = self._get_body(response)
  File "/usr/local/lib/python3.6/site-packages/googlemaps/client.py", line 276, in _get_body
    raise googlemaps.exceptions._RetriableRequest()
googlemaps.exceptions._RetriableRequest

During handling of the above exception, another exception occurred:

Traceback (most recent call last):
  File "/usr/local/lib/python3.6/site-packages/homeassistant/helpers/entity.py", line 221, in async_update_ha_state
    await self.async_device_update()
  File "/usr/local/lib/python3.6/site-packages/homeassistant/helpers/entity.py", line 349, in async_device_update
    await self.hass.async_add_executor_job(self.update)
  File "/usr/local/lib/python3.6/concurrent/futures/thread.py", line 56, in run
    result = self.fn(*self.args, **self.kwargs)
  File "/usr/local/lib/python3.6/site-packages/homeassistant/util/__init__.py", line 324, in wrapper
    result = method(*args, **kwargs)
  File "/usr/local/lib/python3.6/site-packages/homeassistant/components/sensor/google_travel_time.py", line 242, in update
    self._origin, self._destination, **options_copy)
  File "/usr/local/lib/python3.6/site-packages/googlemaps/client.py", line 356, in wrapper
    result = func(*args, **kwargs)
  File "/usr/local/lib/python3.6/site-packages/googlemaps/distance_matrix.py", line 130, in distance_matrix
    return client._request("/maps/api/distancematrix/json", params)
  File "/usr/local/lib/python3.6/site-packages/googlemaps/client.py", line 260, in _request
    extract_body, requests_kwargs, post_json)
  File "/usr/local/lib/python3.6/site-packages/googlemaps/client.py", line 260, in _request
    extract_body, requests_kwargs, post_json)
  File "/usr/local/lib/python3.6/site-packages/googlemaps/client.py", line 260, in _request
    extract_body, requests_kwargs, post_json)
  [Previous line repeated 8 more times]
  File "/usr/local/lib/python3.6/site-packages/googlemaps/client.py", line 203, in _request
    raise googlemaps.exceptions.Timeout()
googlemaps.exceptions.Timeout
2018-12-10 20:06:33 WARNING (MainThread) [homeassistant.helpers.entity] Update of sensor.google_travel_time__driving is taking over 10 seconds
2018-12-10 20:06:54 WARNING (MainThread) [homeassistant.components.sensor] Updating google_travel_time sensor took longer than the scheduled update interval 0:00:30
2018-12-10 20:07:25 WARNING (MainThread) [homeassistant.components.sensor] Updating google_travel_time sensor took longer than the scheduled update interval 0:00:30
2018-12-10 20:07:56 WARNING (MainThread) [homeassistant.components.sensor] Updating google_travel_time sensor took longer than the scheduled update interval 0:00:30
2018-12-10 20:07:59 ERROR (MainThread) [homeassistant.helpers.entity] Update for sensor.google_travel_time__driving fails
Traceback (most recent call last):
  File "/usr/local/lib/python3.6/site-packages/googlemaps/client.py", line 253, in _request
    result = self._get_body(response)
  File "/usr/local/lib/python3.6/site-packages/googlemaps/client.py", line 276, in _get_body
    raise googlemaps.exceptions._RetriableRequest()
googlemaps.exceptions._RetriableRequest

During handling of the above exception, another exception occurred:

Traceback (most recent call last):
  File "/usr/local/lib/python3.6/site-packages/googlemaps/client.py", line 253, in _request
    result = self._get_body(response)
  File "/usr/local/lib/python3.6/site-packages/googlemaps/client.py", line 276, in _get_body
    raise googlemaps.exceptions._RetriableRequest()
googlemaps.exceptions._RetriableRequest

During handling of the above exception, another exception occurred:

Traceback (most recent call last):
  File "/usr/local/lib/python3.6/site-packages/googlemaps/client.py", line 253, in _request
    result = self._get_body(response)
  File "/usr/local/lib/python3.6/site-packages/googlemaps/client.py", line 276, in _get_body
    raise googlemaps.exceptions._RetriableRequest()
googlemaps.exceptions._RetriableRequest

During handling of the above exception, another exception occurred:

Traceback (most recent call last):
  File "/usr/local/lib/python3.6/site-packages/googlemaps/client.py", line 253, in _request
    result = self._get_body(response)
  File "/usr/local/lib/python3.6/site-packages/googlemaps/client.py", line 276, in _get_body
    raise googlemaps.exceptions._RetriableRequest()
googlemaps.exceptions._RetriableRequest

During handling of the above exception, another exception occurred:

Traceback (most recent call last):
  File "/usr/local/lib/python3.6/site-packages/googlemaps/client.py", line 253, in _request
    result = self._get_body(response)
  File "/usr/local/lib/python3.6/site-packages/googlemaps/client.py", line 276, in _get_body
    raise googlemaps.exceptions._RetriableRequest()
googlemaps.exceptions._RetriableRequest

During handling of the above exception, another exception occurred:

Traceback (most recent call last):
  File "/usr/local/lib/python3.6/site-packages/googlemaps/client.py", line 253, in _request
    result = self._get_body(response)
  File "/usr/local/lib/python3.6/site-packages/googlemaps/client.py", line 276, in _get_body
    raise googlemaps.exceptions._RetriableRequest()
googlemaps.exceptions._RetriableRequest

During handling of the above exception, another exception occurred:

Traceback (most recent call last):
  File "/usr/local/lib/python3.6/site-packages/googlemaps/client.py", line 253, in _request
    result = self._get_body(response)
  File "/usr/local/lib/python3.6/site-packages/googlemaps/client.py", line 276, in _get_body
    raise googlemaps.exceptions._RetriableRequest()
googlemaps.exceptions._RetriableRequest

During handling of the above exception, another exception occurred:

Traceback (most recent call last):
  File "/usr/local/lib/python3.6/site-packages/googlemaps/client.py", line 253, in _request
    result = self._get_body(response)
  File "/usr/local/lib/python3.6/site-packages/googlemaps/client.py", line 276, in _get_body
    raise googlemaps.exceptions._RetriableRequest()
googlemaps.exceptions._RetriableRequest

During handling of the above exception, another exception occurred:

Traceback (most recent call last):
  File "/usr/local/lib/python3.6/site-packages/googlemaps/client.py", line 253, in _request
    result = self._get_body(response)
  File "/usr/local/lib/python3.6/site-packages/googlemaps/client.py", line 276, in _get_body
    raise googlemaps.exceptions._RetriableRequest()
googlemaps.exceptions._RetriableRequest

During handling of the above exception, another exception occurred:

Traceback (most recent call last):
  File "/usr/local/lib/python3.6/site-packages/googlemaps/client.py", line 253, in _request
    result = self._get_body(response)
  File "/usr/local/lib/python3.6/site-packages/googlemaps/client.py", line 276, in _get_body
    raise googlemaps.exceptions._RetriableRequest()
googlemaps.exceptions._RetriableRequest

During handling of the above exception, another exception occurred:

Traceback (most recent call last):
  File "/usr/local/lib/python3.6/site-packages/googlemaps/client.py", line 253, in _request
    result = self._get_body(response)
  File "/usr/local/lib/python3.6/site-packages/googlemaps/client.py", line 276, in _get_body
    raise googlemaps.exceptions._RetriableRequest()
googlemaps.exceptions._RetriableRequest

During handling of the above exception, another exception occurred:

Traceback (most recent call last):
  File "/usr/local/lib/python3.6/site-packages/googlemaps/client.py", line 253, in _request
    result = self._get_body(response)
  File "/usr/local/lib/python3.6/site-packages/googlemaps/client.py", line 276, in _get_body
    raise googlemaps.exceptions._RetriableRequest()
googlemaps.exceptions._RetriableRequest

During handling of the above exception, another exception occurred:

Traceback (most recent call last):
  File "/usr/local/lib/python3.6/site-packages/homeassistant/helpers/entity.py", line 221, in async_update_ha_state
    await self.async_device_update()
  File "/usr/local/lib/python3.6/site-packages/homeassistant/helpers/entity.py", line 349, in async_device_update
    await self.hass.async_add_executor_job(self.update)
  File "/usr/local/lib/python3.6/concurrent/futures/thread.py", line 56, in run
    result = self.fn(*self.args, **self.kwargs)
  File "/usr/local/lib/python3.6/site-packages/homeassistant/util/__init__.py", line 324, in wrapper
    result = method(*args, **kwargs)
  File "/usr/local/lib/python3.6/site-packages/homeassistant/components/sensor/google_travel_time.py", line 242, in update
    self._origin, self._destination, **options_copy)
  File "/usr/local/lib/python3.6/site-packages/googlemaps/client.py", line 356, in wrapper
    result = func(*args, **kwargs)
  File "/usr/local/lib/python3.6/site-packages/googlemaps/distance_matrix.py", line 130, in distance_matrix
    return client._request("/maps/api/distancematrix/json", params)
  File "/usr/local/lib/python3.6/site-packages/googlemaps/client.py", line 260, in _request
    extract_body, requests_kwargs, post_json)
  File "/usr/local/lib/python3.6/site-packages/googlemaps/client.py", line 260, in _request
    extract_body, requests_kwargs, post_json)
  File "/usr/local/lib/python3.6/site-packages/googlemaps/client.py", line 260, in _request
    extract_body, requests_kwargs, post_json)
  [Previous line repeated 8 more times]
  File "/usr/local/lib/python3.6/site-packages/googlemaps/client.py", line 203, in _request
    raise googlemaps.exceptions.Timeout()
googlemaps.exceptions.Timeout
2018-12-10 20:08:37 WARNING (MainThread) [homeassistant.helpers.entity] Update of sensor.google_travel_time__driving is taking over 10 seconds
2018-12-10 20:08:58 WARNING (MainThread) [homeassistant.components.sensor] Updating google_travel_time sensor took longer than the scheduled update interval 0:00:30
2018-12-10 20:09:29 WARNING (MainThread) [homeassistant.components.sensor] Updating google_travel_time sensor took longer than the scheduled update interval 0:00:30
2018-12-10 20:09:54 ERROR (MainThread) [homeassistant.helpers.entity] Update for sensor.google_travel_time__driving fails
Traceback (most recent call last):
  File "/usr/local/lib/python3.6/site-packages/googlemaps/client.py", line 253, in _request
    result = self._get_body(response)
  File "/usr/local/lib/python3.6/site-packages/googlemaps/client.py", line 276, in _get_body
    raise googlemaps.exceptions._RetriableRequest()
googlemaps.exceptions._RetriableRequest

During handling of the above exception, another exception occurred:

Traceback (most recent call last):
  File "/usr/local/lib/python3.6/site-packages/googlemaps/client.py", line 253, in _request
    result = self._get_body(response)
  File "/usr/local/lib/python3.6/site-packages/googlemaps/client.py", line 276, in _get_body
    raise googlemaps.exceptions._RetriableRequest()
googlemaps.exceptions._RetriableRequest

During handling of the above exception, another exception occurred:

Traceback (most recent call last):
  File "/usr/local/lib/python3.6/site-packages/googlemaps/client.py", line 253, in _request
    result = self._get_body(response)
  File "/usr/local/lib/python3.6/site-packages/googlemaps/client.py", line 276, in _get_body
    raise googlemaps.exceptions._RetriableRequest()
googlemaps.exceptions._RetriableRequest

During handling of the above exception, another exception occurred:

Traceback (most recent call last):
  File "/usr/local/lib/python3.6/site-packages/googlemaps/client.py", line 253, in _request
    result = self._get_body(response)
  File "/usr/local/lib/python3.6/site-packages/googlemaps/client.py", line 276, in _get_body
    raise googlemaps.exceptions._RetriableRequest()
googlemaps.exceptions._RetriableRequest

During handling of the above exception, another exception occurred:

Traceback (most recent call last):
  File "/usr/local/lib/python3.6/site-packages/googlemaps/client.py", line 253, in _request
    result = self._get_body(response)
  File "/usr/local/lib/python3.6/site-packages/googlemaps/client.py", line 276, in _get_body
    raise googlemaps.exceptions._RetriableRequest()
googlemaps.exceptions._RetriableRequest

During handling of the above exception, another exception occurred:

Traceback (most recent call last):
  File "/usr/local/lib/python3.6/site-packages/googlemaps/client.py", line 253, in _request
    result = self._get_body(response)
  File "/usr/local/lib/python3.6/site-packages/googlemaps/client.py", line 276, in _get_body
    raise googlemaps.exceptions._RetriableRequest()
googlemaps.exceptions._RetriableRequest

During handling of the above exception, another exception occurred:

Traceback (most recent call last):
  File "/usr/local/lib/python3.6/site-packages/googlemaps/client.py", line 253, in _request
    result = self._get_body(response)
  File "/usr/local/lib/python3.6/site-packages/googlemaps/client.py", line 276, in _get_body
    raise googlemaps.exceptions._RetriableRequest()
googlemaps.exceptions._RetriableRequest

During handling of the above exception, another exception occurred:

Traceback (most recent call last):
  File "/usr/local/lib/python3.6/site-packages/googlemaps/client.py", line 253, in _request
    result = self._get_body(response)
  File "/usr/local/lib/python3.6/site-packages/googlemaps/client.py", line 276, in _get_body
    raise googlemaps.exceptions._RetriableRequest()
googlemaps.exceptions._RetriableRequest

During handling of the above exception, another exception occurred:

Traceback (most recent call last):
  File "/usr/local/lib/python3.6/site-packages/googlemaps/client.py", line 253, in _request
    result = self._get_body(response)
  File "/usr/local/lib/python3.6/site-packages/googlemaps/client.py", line 276, in _get_body
    raise googlemaps.exceptions._RetriableRequest()
googlemaps.exceptions._RetriableRequest

During handling of the above exception, another exception occurred:

Traceback (most recent call last):
  File "/usr/local/lib/python3.6/site-packages/googlemaps/client.py", line 253, in _request
    result = self._get_body(response)
  File "/usr/local/lib/python3.6/site-packages/googlemaps/client.py", line 276, in _get_body
    raise googlemaps.exceptions._RetriableRequest()
googlemaps.exceptions._RetriableRequest

During handling of the above exception, another exception occurred:

Traceback (most recent call last):
  File "/usr/local/lib/python3.6/site-packages/googlemaps/client.py", line 253, in _request
    result = self._get_body(response)
  File "/usr/local/lib/python3.6/site-packages/googlemaps/client.py", line 276, in _get_body
    raise googlemaps.exceptions._RetriableRequest()
googlemaps.exceptions._RetriableRequest

During handling of the above exception, another exception occurred:

Traceback (most recent call last):
  File "/usr/local/lib/python3.6/site-packages/googlemaps/client.py", line 253, in _request
    result = self._get_body(response)
  File "/usr/local/lib/python3.6/site-packages/googlemaps/client.py", line 276, in _get_body
    raise googlemaps.exceptions._RetriableRequest()
googlemaps.exceptions._RetriableRequest

During handling of the above exception, another exception occurred:

Traceback (most recent call last):
  File "/usr/local/lib/python3.6/site-packages/homeassistant/helpers/entity.py", line 221, in async_update_ha_state
    await self.async_device_update()
  File "/usr/local/lib/python3.6/site-packages/homeassistant/helpers/entity.py", line 349, in async_device_update
    await self.hass.async_add_executor_job(self.update)
  File "/usr/local/lib/python3.6/concurrent/futures/thread.py", line 56, in run
    result = self.fn(*self.args, **self.kwargs)
  File "/usr/local/lib/python3.6/site-packages/homeassistant/util/__init__.py", line 324, in wrapper
    result = method(*args, **kwargs)
  File "/usr/local/lib/python3.6/site-packages/homeassistant/components/sensor/google_travel_time.py", line 242, in update
    self._origin, self._destination, **options_copy)
  File "/usr/local/lib/python3.6/site-packages/googlemaps/client.py", line 356, in wrapper
    result = func(*args, **kwargs)
  File "/usr/local/lib/python3.6/site-packages/googlemaps/distance_matrix.py", line 130, in distance_matrix
    return client._request("/maps/api/distancematrix/json", params)
  File "/usr/local/lib/python3.6/site-packages/googlemaps/client.py", line 260, in _request
    extract_body, requests_kwargs, post_json)
  File "/usr/local/lib/python3.6/site-packages/googlemaps/client.py", line 260, in _request
    extract_body, requests_kwargs, post_json)
  File "/usr/local/lib/python3.6/site-packages/googlemaps/client.py", line 260, in _request
    extract_body, requests_kwargs, post_json)
  [Previous line repeated 8 more times]
  File "/usr/local/lib/python3.6/site-packages/googlemaps/client.py", line 203, in _request
    raise googlemaps.exceptions.Timeout()
googlemaps.exceptions.Timeout
2018-12-10 20:10:10 WARNING (MainThread) [homeassistant.helpers.entity] Update of sensor.google_travel_time__driving is taking over 10 seconds
2018-12-10 20:10:31 WARNING (MainThread) [homeassistant.components.sensor] Updating google_travel_time sensor took longer than the scheduled update interval 0:00:30
2018-12-10 20:10:41 ERROR (SyncWorker_11) [homeassistant.components.sensor.waze_travel_time] Error on retrieving data: Internal Error
2018-12-10 20:11:02 WARNING (MainThread) [homeassistant.components.sensor] Updating google_travel_time sensor took longer than the scheduled update interval 0:00:30
2018-12-10 20:11:13 ERROR (MainThread) [homeassistant.helpers.entity] Update for sensor.google_travel_time__driving fails
Traceback (most recent call last):
  File "/usr/local/lib/python3.6/site-packages/googlemaps/client.py", line 253, in _request
    result = self._get_body(response)
  File "/usr/local/lib/python3.6/site-packages/googlemaps/client.py", line 276, in _get_body
    raise googlemaps.exceptions._RetriableRequest()
googlemaps.exceptions._RetriableRequest

During handling of the above exception, another exception occurred:

Traceback (most recent call last):
  File "/usr/local/lib/python3.6/site-packages/googlemaps/client.py", line 253, in _request
    result = self._get_body(response)
  File "/usr/local/lib/python3.6/site-packages/googlemaps/client.py", line 276, in _get_body
    raise googlemaps.exceptions._RetriableRequest()
googlemaps.exceptions._RetriableRequest

During handling of the above exception, another exception occurred:

Traceback (most recent call last):
  File "/usr/local/lib/python3.6/site-packages/googlemaps/client.py", line 253, in _request
    result = self._get_body(response)
  File "/usr/local/lib/python3.6/site-packages/googlemaps/client.py", line 276, in _get_body
    raise googlemaps.exceptions._RetriableRequest()
googlemaps.exceptions._RetriableRequest

During handling of the above exception, another exception occurred:

Traceback (most recent call last):
  File "/usr/local/lib/python3.6/site-packages/googlemaps/client.py", line 253, in _request
    result = self._get_body(response)
  File "/usr/local/lib/python3.6/site-packages/googlemaps/client.py", line 276, in _get_body
    raise googlemaps.exceptions._RetriableRequest()
googlemaps.exceptions._RetriableRequest

During handling of the above exception, another exception occurred:

Traceback (most recent call last):
  File "/usr/local/lib/python3.6/site-packages/googlemaps/client.py", line 253, in _request
    result = self._get_body(response)
  File "/usr/local/lib/python3.6/site-packages/googlemaps/client.py", line 276, in _get_body
    raise googlemaps.exceptions._RetriableRequest()
googlemaps.exceptions._RetriableRequest

During handling of the above exception, another exception occurred:

Traceback (most recent call last):
  File "/usr/local/lib/python3.6/site-packages/googlemaps/client.py", line 253, in _request
    result = self._get_body(response)
  File "/usr/local/lib/python3.6/site-packages/googlemaps/client.py", line 276, in _get_body
    raise googlemaps.exceptions._RetriableRequest()
googlemaps.exceptions._RetriableRequest

During handling of the above exception, another exception occurred:

Traceback (most recent call last):
  File "/usr/local/lib/python3.6/site-packages/googlemaps/client.py", line 253, in _request
    result = self._get_body(response)
  File "/usr/local/lib/python3.6/site-packages/googlemaps/client.py", line 276, in _get_body
    raise googlemaps.exceptions._RetriableRequest()
googlemaps.exceptions._RetriableRequest

During handling of the above exception, another exception occurred:

Traceback (most recent call last):
  File "/usr/local/lib/python3.6/site-packages/googlemaps/client.py", line 253, in _request
    result = self._get_body(response)
  File "/usr/local/lib/python3.6/site-packages/googlemaps/client.py", line 276, in _get_body
    raise googlemaps.exceptions._RetriableRequest()
googlemaps.exceptions._RetriableRequest

During handling of the above exception, another exception occurred:

Traceback (most recent call last):
  File "/usr/local/lib/python3.6/site-packages/googlemaps/client.py", line 253, in _request
    result = self._get_body(response)
  File "/usr/local/lib/python3.6/site-packages/googlemaps/client.py", line 276, in _get_body
    raise googlemaps.exceptions._RetriableRequest()
googlemaps.exceptions._RetriableRequest

During handling of the above exception, another exception occurred:

Traceback (most recent call last):
  File "/usr/local/lib/python3.6/site-packages/googlemaps/client.py", line 253, in _request
    result = self._get_body(response)
  File "/usr/local/lib/python3.6/site-packages/googlemaps/client.py", line 276, in _get_body
    raise googlemaps.exceptions._RetriableRequest()
googlemaps.exceptions._RetriableRequest

During handling of the above exception, another exception occurred:

Traceback (most recent call last):
  File "/usr/local/lib/python3.6/site-packages/googlemaps/client.py", line 253, in _request
    result = self._get_body(response)
  File "/usr/local/lib/python3.6/site-packages/googlemaps/client.py", line 276, in _get_body
    raise googlemaps.exceptions._RetriableRequest()
googlemaps.exceptions._RetriableRequest

During handling of the above exception, another exception occurred:

Traceback (most recent call last):
  File "/usr/local/lib/python3.6/site-packages/googlemaps/client.py", line 253, in _request
    result = self._get_body(response)
  File "/usr/local/lib/python3.6/site-packages/googlemaps/client.py", line 276, in _get_body
    raise googlemaps.exceptions._RetriableRequest()
googlemaps.exceptions._RetriableRequest

During handling of the above exception, another exception occurred:

Traceback (most recent call last):
  File "/usr/local/lib/python3.6/site-packages/homeassistant/helpers/entity.py", line 221, in async_update_ha_state
    await self.async_device_update()
  File "/usr/local/lib/python3.6/site-packages/homeassistant/helpers/entity.py", line 349, in async_device_update
    await self.hass.async_add_executor_job(self.update)
  File "/usr/local/lib/python3.6/concurrent/futures/thread.py", line 56, in run
    result = self.fn(*self.args, **self.kwargs)
  File "/usr/local/lib/python3.6/site-packages/homeassistant/util/__init__.py", line 324, in wrapper
    result = method(*args, **kwargs)
  File "/usr/local/lib/python3.6/site-packages/homeassistant/components/sensor/google_travel_time.py", line 242, in update
    self._origin, self._destination, **options_copy)
  File "/usr/local/lib/python3.6/site-packages/googlemaps/client.py", line 356, in wrapper
    result = func(*args, **kwargs)
  File "/usr/local/lib/python3.6/site-packages/googlemaps/distance_matrix.py", line 130, in distance_matrix
    return client._request("/maps/api/distancematrix/json", params)
  File "/usr/local/lib/python3.6/site-packages/googlemaps/client.py", line 260, in _request
    extract_body, requests_kwargs, post_json)
  File "/usr/local/lib/python3.6/site-packages/googlemaps/client.py", line 260, in _request
    extract_body, requests_kwargs, post_json)
  File "/usr/local/lib/python3.6/site-packages/googlemaps/client.py", line 260, in _request
    extract_body, requests_kwargs, post_json)
  [Previous line repeated 8 more times]
  File "/usr/local/lib/python3.6/site-packages/googlemaps/client.py", line 203, in _request
    raise googlemaps.exceptions.Timeout()
googlemaps.exceptions.Timeout
2018-12-10 20:11:43 WARNING (MainThread) [homeassistant.helpers.entity] Update of sensor.google_travel_time__driving is taking over 10 seconds
2018-12-10 20:12:04 WARNING (MainThread) [homeassistant.components.sensor] Updating google_travel_time sensor took longer than the scheduled update interval 0:00:30
2018-12-10 20:12:35 WARNING (MainThread) [homeassistant.components.sensor] Updating google_travel_time sensor took longer than the scheduled update interval 0:00:30
2018-12-10 20:13:00 ERROR (MainThread) [homeassistant.helpers.entity] Update for sensor.google_travel_time__driving fails
Traceback (most recent call last):
  File "/usr/local/lib/python3.6/site-packages/googlemaps/client.py", line 253, in _request
    result = self._get_body(response)
  File "/usr/local/lib/python3.6/site-packages/googlemaps/client.py", line 276, in _get_body
    raise googlemaps.exceptions._RetriableRequest()
googlemaps.exceptions._RetriableRequest

During handling of the above exception, another exception occurred:

Traceback (most recent call last):
  File "/usr/local/lib/python3.6/site-packages/googlemaps/client.py", line 253, in _request
    result = self._get_body(response)
  File "/usr/local/lib/python3.6/site-packages/googlemaps/client.py", line 276, in _get_body
    raise googlemaps.exceptions._RetriableRequest()
googlemaps.exceptions._RetriableRequest

During handling of the above exception, another exception occurred:

Traceback (most recent call last):
  File "/usr/local/lib/python3.6/site-packages/googlemaps/client.py", line 253, in _request
    result = self._get_body(response)
  File "/usr/local/lib/python3.6/site-packages/googlemaps/client.py", line 276, in _get_body
    raise googlemaps.exceptions._RetriableRequest()
googlemaps.exceptions._RetriableRequest

During handling of the above exception, another exception occurred:

Traceback (most recent call last):
  File "/usr/local/lib/python3.6/site-packages/googlemaps/client.py", line 253, in _request
    result = self._get_body(response)
  File "/usr/local/lib/python3.6/site-packages/googlemaps/client.py", line 276, in _get_body
    raise googlemaps.exceptions._RetriableRequest()
googlemaps.exceptions._RetriableRequest

During handling of the above exception, another exception occurred:

Traceback (most recent call last):
  File "/usr/local/lib/python3.6/site-packages/googlemaps/client.py", line 253, in _request
    result = self._get_body(response)
  File "/usr/local/lib/python3.6/site-packages/googlemaps/client.py", line 276, in _get_body
    raise googlemaps.exceptions._RetriableRequest()
googlemaps.exceptions._RetriableRequest

During handling of the above exception, another exception occurred:

Traceback (most recent call last):
  File "/usr/local/lib/python3.6/site-packages/googlemaps/client.py", line 253, in _request
    result = self._get_body(response)
  File "/usr/local/lib/python3.6/site-packages/googlemaps/client.py", line 276, in _get_body
    raise googlemaps.exceptions._RetriableRequest()
googlemaps.exceptions._RetriableRequest

During handling of the above exception, another exception occurred:

Traceback (most recent call last):
  File "/usr/local/lib/python3.6/site-packages/googlemaps/client.py", line 253, in _request
    result = self._get_body(response)
  File "/usr/local/lib/python3.6/site-packages/googlemaps/client.py", line 276, in _get_body
    raise googlemaps.exceptions._RetriableRequest()
googlemaps.exceptions._RetriableRequest

During handling of the above exception, another exception occurred:

Traceback (most recent call last):
  File "/usr/local/lib/python3.6/site-packages/googlemaps/client.py", line 253, in _request
    result = self._get_body(response)
  File "/usr/local/lib/python3.6/site-packages/googlemaps/client.py", line 276, in _get_body
    raise googlemaps.exceptions._RetriableRequest()
googlemaps.exceptions._RetriableRequest

During handling of the above exception, another exception occurred:

Traceback (most recent call last):
  File "/usr/local/lib/python3.6/site-packages/googlemaps/client.py", line 253, in _request
    result = self._get_body(response)
  File "/usr/local/lib/python3.6/site-packages/googlemaps/client.py", line 276, in _get_body
    raise googlemaps.exceptions._RetriableRequest()
googlemaps.exceptions._RetriableRequest

During handling of the above exception, another exception occurred:

Traceback (most recent call last):
  File "/usr/local/lib/python3.6/site-packages/googlemaps/client.py", line 253, in _request
    result = self._get_body(response)
  File "/usr/local/lib/python3.6/site-packages/googlemaps/client.py", line 276, in _get_body
    raise googlemaps.exceptions._RetriableRequest()
googlemaps.exceptions._RetriableRequest

During handling of the above exception, another exception occurred:

Traceback (most recent call last):
  File "/usr/local/lib/python3.6/site-packages/googlemaps/client.py", line 253, in _request
    result = self._get_body(response)
  File "/usr/local/lib/python3.6/site-packages/googlemaps/client.py", line 276, in _get_body
    raise googlemaps.exceptions._RetriableRequest()
googlemaps.exceptions._RetriableRequest

During handling of the above exception, another exception occurred:

Traceback (most recent call last):
  File "/usr/local/lib/python3.6/site-packages/googlemaps/client.py", line 253, in _request
    result = self._get_body(response)
  File "/usr/local/lib/python3.6/site-packages/googlemaps/client.py", line 276, in _get_body
    raise googlemaps.exceptions._RetriableRequest()
googlemaps.exceptions._RetriableRequest

During handling of the above exception, another exception occurred:

Traceback (most recent call last):
  File "/usr/local/lib/python3.6/site-packages/homeassistant/helpers/entity.py", line 221, in async_update_ha_state
    await self.async_device_update()
  File "/usr/local/lib/python3.6/site-packages/homeassistant/helpers/entity.py", line 349, in async_device_update
    await self.hass.async_add_executor_job(self.update)
  File "/usr/local/lib/python3.6/concurrent/futures/thread.py", line 56, in run
    result = self.fn(*self.args, **self.kwargs)
  File "/usr/local/lib/python3.6/site-packages/homeassistant/util/__init__.py", line 324, in wrapper
    result = method(*args, **kwargs)
  File "/usr/local/lib/python3.6/site-packages/homeassistant/components/sensor/google_travel_time.py", line 242, in update
    self._origin, self._destination, **options_copy)
  File "/usr/local/lib/python3.6/site-packages/googlemaps/client.py", line 356, in wrapper
    result = func(*args, **kwargs)
  File "/usr/local/lib/python3.6/site-packages/googlemaps/distance_matrix.py", line 130, in distance_matrix
    return client._request("/maps/api/distancematrix/json", params)
  File "/usr/local/lib/python3.6/site-packages/googlemaps/client.py", line 260, in _request
    extract_body, requests_kwargs, post_json)
  File "/usr/local/lib/python3.6/site-packages/googlemaps/client.py", line 260, in _request
    extract_body, requests_kwargs, post_json)
  File "/usr/local/lib/python3.6/site-packages/googlemaps/client.py", line 260, in _request
    extract_body, requests_kwargs, post_json)
  [Previous line repeated 8 more times]
  File "/usr/local/lib/python3.6/site-packages/googlemaps/client.py", line 203, in _request
    raise googlemaps.exceptions.Timeout()
googlemaps.exceptions.Timeout
2018-12-10 20:13:16 WARNING (MainThread) [homeassistant.helpers.entity] Update of sensor.google_travel_time__driving is taking over 10 seconds
2018-12-10 20:13:37 WARNING (MainThread) [homeassistant.components.sensor] Updating google_travel_time sensor took longer than the scheduled update interval 0:00:30
2018-12-10 20:14:04 WARNING (Thread-5) [pychromecast.socket_client] Heartbeat timeout, resetting connection
2018-12-10 20:14:07 ERROR (MainThread) [homeassistant.helpers.entity] Update for sensor.google_travel_time__driving fails
Traceback (most recent call last):
  File "/usr/local/lib/python3.6/site-packages/googlemaps/client.py", line 253, in _request
    result = self._get_body(response)
  File "/usr/local/lib/python3.6/site-packages/googlemaps/client.py", line 276, in _get_body
    raise googlemaps.exceptions._RetriableRequest()
googlemaps.exceptions._RetriableRequest

During handling of the above exception, another exception occurred:

Traceback (most recent call last):
  File "/usr/local/lib/python3.6/site-packages/googlemaps/client.py", line 253, in _request
    result = self._get_body(response)
  File "/usr/local/lib/python3.6/site-packages/googlemaps/client.py", line 276, in _get_body
    raise googlemaps.exceptions._RetriableRequest()
googlemaps.exceptions._RetriableRequest

During handling of the above exception, another exception occurred:

Traceback (most recent call last):
  File "/usr/local/lib/python3.6/site-packages/googlemaps/client.py", line 253, in _request
    result = self._get_body(response)
  File "/usr/local/lib/python3.6/site-packages/googlemaps/client.py", line 276, in _get_body
    raise googlemaps.exceptions._RetriableRequest()
googlemaps.exceptions._RetriableRequest

During handling of the above exception, another exception occurred:

Traceback (most recent call last):
  File "/usr/local/lib/python3.6/site-packages/googlemaps/client.py", line 253, in _request
    result = self._get_body(response)
  File "/usr/local/lib/python3.6/site-packages/googlemaps/client.py", line 276, in _get_body
    raise googlemaps.exceptions._RetriableRequest()
googlemaps.exceptions._RetriableRequest

During handling of the above exception, another exception occurred:

Traceback (most recent call last):
  File "/usr/local/lib/python3.6/site-packages/googlemaps/client.py", line 253, in _request
    result = self._get_body(response)
  File "/usr/local/lib/python3.6/site-packages/googlemaps/client.py", line 276, in _get_body
    raise googlemaps.exceptions._RetriableRequest()
googlemaps.exceptions._RetriableRequest

During handling of the above exception, another exception occurred:

Traceback (most recent call last):
  File "/usr/local/lib/python3.6/site-packages/googlemaps/client.py", line 253, in _request
    result = self._get_body(response)
  File "/usr/local/lib/python3.6/site-packages/googlemaps/client.py", line 276, in _get_body
    raise googlemaps.exceptions._RetriableRequest()
googlemaps.exceptions._RetriableRequest

During handling of the above exception, another exception occurred:

Traceback (most recent call last):
  File "/usr/local/lib/python3.6/site-packages/googlemaps/client.py", line 253, in _request
    result = self._get_body(response)
  File "/usr/local/lib/python3.6/site-packages/googlemaps/client.py", line 276, in _get_body
    raise googlemaps.exceptions._RetriableRequest()
googlemaps.exceptions._RetriableRequest

During handling of the above exception, another exception occurred:

Traceback (most recent call last):
  File "/usr/local/lib/python3.6/site-packages/googlemaps/client.py", line 253, in _request
    result = self._get_body(response)
  File "/usr/local/lib/python3.6/site-packages/googlemaps/client.py", line 276, in _get_body
    raise googlemaps.exceptions._RetriableRequest()
googlemaps.exceptions._RetriableRequest

During handling of the above exception, another exception occurred:

Traceback (most recent call last):
  File "/usr/local/lib/python3.6/site-packages/googlemaps/client.py", line 253, in _request
    result = self._get_body(response)
  File "/usr/local/lib/python3.6/site-packages/googlemaps/client.py", line 276, in _get_body
    raise googlemaps.exceptions._RetriableRequest()
googlemaps.exceptions._RetriableRequest

During handling of the above exception, another exception occurred:

Traceback (most recent call last):
  File "/usr/local/lib/python3.6/site-packages/googlemaps/client.py", line 253, in _request
    result = self._get_body(response)
  File "/usr/local/lib/python3.6/site-packages/googlemaps/client.py", line 276, in _get_body
    raise googlemaps.exceptions._RetriableRequest()
googlemaps.exceptions._RetriableRequest

During handling of the above exception, another exception occurred:

Traceback (most recent call last):
  File "/usr/local/lib/python3.6/site-packages/googlemaps/client.py", line 253, in _request
    result = self._get_body(response)
  File "/usr/local/lib/python3.6/site-packages/googlemaps/client.py", line 276, in _get_body
    raise googlemaps.exceptions._RetriableRequest()
googlemaps.exceptions._RetriableRequest

During handling of the above exception, another exception occurred:

Traceback (most recent call last):
  File "/usr/local/lib/python3.6/site-packages/homeassistant/helpers/entity.py", line 221, in async_update_ha_state
    await self.async_device_update()
  File "/usr/local/lib/python3.6/site-packages/homeassistant/helpers/entity.py", line 349, in async_device_update
    await self.hass.async_add_executor_job(self.update)
  File "/usr/local/lib/python3.6/concurrent/futures/thread.py", line 56, in run
    result = self.fn(*self.args, **self.kwargs)
  File "/usr/local/lib/python3.6/site-packages/homeassistant/util/__init__.py", line 324, in wrapper
    result = method(*args, **kwargs)
  File "/usr/local/lib/python3.6/site-packages/homeassistant/components/sensor/google_travel_time.py", line 242, in update
    self._origin, self._destination, **options_copy)
  File "/usr/local/lib/python3.6/site-packages/googlemaps/client.py", line 356, in wrapper
    result = func(*args, **kwargs)
  File "/usr/local/lib/python3.6/site-packages/googlemaps/distance_matrix.py", line 130, in distance_matrix
    return client._request("/maps/api/distancematrix/json", params)
  File "/usr/local/lib/python3.6/site-packages/googlemaps/client.py", line 260, in _request
    extract_body, requests_kwargs, post_json)
  File "/usr/local/lib/python3.6/site-packages/googlemaps/client.py", line 260, in _request
    extract_body, requests_kwargs, post_json)
  File "/usr/local/lib/python3.6/site-packages/googlemaps/client.py", line 260, in _request
    extract_body, requests_kwargs, post_json)
  [Previous line repeated 7 more times]
  File "/usr/local/lib/python3.6/site-packages/googlemaps/client.py", line 203, in _request
    raise googlemaps.exceptions.Timeout()
googlemaps.exceptions.Timeout
2018-12-10 20:14:18 WARNING (MainThread) [homeassistant.helpers.entity] Update of sensor.google_travel_time__driving is taking over 10 seconds
2018-12-10 20:14:25 WARNING (Thread-5) [pychromecast.socket_client] Heartbeat timeout, resetting connection
2018-12-10 20:14:39 WARNING (MainThread) [homeassistant.components.sensor] Updating google_travel_time sensor took longer than the scheduled update interval 0:00:30
2018-12-10 20:15:10 WARNING (MainThread) [homeassistant.components.sensor] Updating google_travel_time sensor took longer than the scheduled update interval 0:00:30
2018-12-10 20:15:27 ERROR (MainThread) [homeassistant.helpers.entity] Update for sensor.google_travel_time__driving fails
Traceback (most recent call last):
  File "/usr/local/lib/python3.6/site-packages/googlemaps/client.py", line 253, in _request
    result = self._get_body(response)
  File "/usr/local/lib/python3.6/site-packages/googlemaps/client.py", line 276, in _get_body
    raise googlemaps.exceptions._RetriableRequest()
googlemaps.exceptions._RetriableRequest

During handling of the above exception, another exception occurred:

Traceback (most recent call last):
  File "/usr/local/lib/python3.6/site-packages/googlemaps/client.py", line 253, in _request
    result = self._get_body(response)
  File "/usr/local/lib/python3.6/site-packages/googlemaps/client.py", line 276, in _get_body
    raise googlemaps.exceptions._RetriableRequest()
googlemaps.exceptions._RetriableRequest

During handling of the above exception, another exception occurred:

Traceback (most recent call last):
  File "/usr/local/lib/python3.6/site-packages/googlemaps/client.py", line 253, in _request
    result = self._get_body(response)
  File "/usr/local/lib/python3.6/site-packages/googlemaps/client.py", line 276, in _get_body
    raise googlemaps.exceptions._RetriableRequest()
googlemaps.exceptions._RetriableRequest

During handling of the above exception, another exception occurred:

Traceback (most recent call last):
  File "/usr/local/lib/python3.6/site-packages/googlemaps/client.py", line 253, in _request
    result = self._get_body(response)
  File "/usr/local/lib/python3.6/site-packages/googlemaps/client.py", line 276, in _get_body
    raise googlemaps.exceptions._RetriableRequest()
googlemaps.exceptions._RetriableRequest

During handling of the above exception, another exception occurred:

Traceback (most recent call last):
  File "/usr/local/lib/python3.6/site-packages/googlemaps/client.py", line 253, in _request
    result = self._get_body(response)
  File "/usr/local/lib/python3.6/site-packages/googlemaps/client.py", line 276, in _get_body
    raise googlemaps.exceptions._RetriableRequest()
googlemaps.exceptions._RetriableRequest

During handling of the above exception, another exception occurred:

Traceback (most recent call last):
  File "/usr/local/lib/python3.6/site-packages/googlemaps/client.py", line 253, in _request
    result = self._get_body(response)
  File "/usr/local/lib/python3.6/site-packages/googlemaps/client.py", line 276, in _get_body
    raise googlemaps.exceptions._RetriableRequest()
googlemaps.exceptions._RetriableRequest

During handling of the above exception, another exception occurred:

Traceback (most recent call last):
  File "/usr/local/lib/python3.6/site-packages/googlemaps/client.py", line 253, in _request
    result = self._get_body(response)
  File "/usr/local/lib/python3.6/site-packages/googlemaps/client.py", line 276, in _get_body
    raise googlemaps.exceptions._RetriableRequest()
googlemaps.exceptions._RetriableRequest

During handling of the above exception, another exception occurred:

Traceback (most recent call last):
  File "/usr/local/lib/python3.6/site-packages/googlemaps/client.py", line 253, in _request
    result = self._get_body(response)
  File "/usr/local/lib/python3.6/site-packages/googlemaps/client.py", line 276, in _get_body
    raise googlemaps.exceptions._RetriableRequest()
googlemaps.exceptions._RetriableRequest

During handling of the above exception, another exception occurred:

Traceback (most recent call last):
  File "/usr/local/lib/python3.6/site-packages/googlemaps/client.py", line 253, in _request
    result = self._get_body(response)
  File "/usr/local/lib/python3.6/site-packages/googlemaps/client.py", line 276, in _get_body
    raise googlemaps.exceptions._RetriableRequest()
googlemaps.exceptions._RetriableRequest

During handling of the above exception, another exception occurred:

Traceback (most recent call last):
  File "/usr/local/lib/python3.6/site-packages/googlemaps/client.py", line 253, in _request
    result = self._get_body(response)
  File "/usr/local/lib/python3.6/site-packages/googlemaps/client.py", line 276, in _get_body
    raise googlemaps.exceptions._RetriableRequest()
googlemaps.exceptions._RetriableRequest

During handling of the above exception, another exception occurred:

Traceback (most recent call last):
  File "/usr/local/lib/python3.6/site-packages/googlemaps/client.py", line 253, in _request
    result = self._get_body(response)
  File "/usr/local/lib/python3.6/site-packages/googlemaps/client.py", line 276, in _get_body
    raise googlemaps.exceptions._RetriableRequest()
googlemaps.exceptions._RetriableRequest

During handling of the above exception, another exception occurred:

Traceback (most recent call last):
  File "/usr/local/lib/python3.6/site-packages/googlemaps/client.py", line 253, in _request
    result = self._get_body(response)
  File "/usr/local/lib/python3.6/site-packages/googlemaps/client.py", line 276, in _get_body
    raise googlemaps.exceptions._RetriableRequest()
googlemaps.exceptions._RetriableRequest

During handling of the above exception, another exception occurred:

Traceback (most recent call last):
  File "/usr/local/lib/python3.6/site-packages/homeassistant/helpers/entity.py", line 221, in async_update_ha_state
    await self.async_device_update()
  File "/usr/local/lib/python3.6/site-packages/homeassistant/helpers/entity.py", line 349, in async_device_update
    await self.hass.async_add_executor_job(self.update)
  File "/usr/local/lib/python3.6/concurrent/futures/thread.py", line 56, in run
    result = self.fn(*self.args, **self.kwargs)
  File "/usr/local/lib/python3.6/site-packages/homeassistant/util/__init__.py", line 324, in wrapper
    result = method(*args, **kwargs)
  File "/usr/local/lib/python3.6/site-packages/homeassistant/components/sensor/google_travel_time.py", line 242, in update
    self._origin, self._destination, **options_copy)
  File "/usr/local/lib/python3.6/site-packages/googlemaps/client.py", line 356, in wrapper
    result = func(*args, **kwargs)
  File "/usr/local/lib/python3.6/site-packages/googlemaps/distance_matrix.py", line 130, in distance_matrix
    return client._request("/maps/api/distancematrix/json", params)
  File "/usr/local/lib/python3.6/site-packages/googlemaps/client.py", line 260, in _request
    extract_body, requests_kwargs, post_json)
  File "/usr/local/lib/python3.6/site-packages/googlemaps/client.py", line 260, in _request
    extract_body, requests_kwargs, post_json)
  File "/usr/local/lib/python3.6/site-packages/googlemaps/client.py", line 260, in _request
    extract_body, requests_kwargs, post_json)
  [Previous line repeated 8 more times]
  File "/usr/local/lib/python3.6/site-packages/googlemaps/client.py", line 203, in _request
    raise googlemaps.exceptions.Timeout()
googlemaps.exceptions.Timeout
2018-12-10 20:15:43 ERROR (SyncWorker_19) [homeassistant.components.sensor.waze_travel_time] Error on retrieving data: Internal Error
2018-12-10 20:15:50 WARNING (MainThread) [homeassistant.helpers.entity] Update of sensor.google_travel_time__driving is taking over 10 seconds
2018-12-10 20:16:11 WARNING (MainThread) [homeassistant.components.sensor] Updating google_travel_time sensor took longer than the scheduled update interval 0:00:30
2018-12-10 20:16:18 WARNING (Thread-5) [pychromecast.socket_client] Heartbeat timeout, resetting connection
2018-12-10 20:16:34 ERROR (MainThread) [homeassistant.helpers.entity] Update for sensor.uberx_price fails
Traceback (most recent call last):
  File "/usr/local/lib/python3.6/site-packages/homeassistant/helpers/entity.py", line 221, in async_update_ha_state
    await self.async_device_update()
  File "/usr/local/lib/python3.6/site-packages/homeassistant/helpers/entity.py", line 349, in async_device_update
    await self.hass.async_add_executor_job(self.update)
  File "/usr/local/lib/python3.6/concurrent/futures/thread.py", line 56, in run
    result = self.fn(*self.args, **self.kwargs)
  File "/usr/local/lib/python3.6/site-packages/homeassistant/components/sensor/uber.py", line 164, in update
    self.data.update()
  File "/usr/local/lib/python3.6/site-packages/homeassistant/util/__init__.py", line 324, in wrapper
    result = method(*args, **kwargs)
  File "/usr/local/lib/python3.6/site-packages/homeassistant/components/sensor/uber.py", line 211, in update
    self.end_latitude, self.end_longitude)
  File "/usr/local/lib/python3.6/site-packages/uber_rides/client.py", line 179, in get_price_estimates
    return self._api_call('GET', 'v1.2/estimates/price', args=args)
  File "/usr/local/lib/python3.6/site-packages/uber_rides/client.py", line 107, in _api_call
    return request.execute()
  File "/usr/local/lib/python3.6/site-packages/uber_rides/request.py", line 152, in execute
    return self._send(prepared_request)
  File "/usr/local/lib/python3.6/site-packages/uber_rides/request.py", line 136, in _send
    response = session.send(prepared_request)
  File "/usr/local/lib/python3.6/site-packages/requests/sessions.py", line 644, in send
    r = dispatch_hook('response', hooks, r, **kwargs)
  File "/usr/local/lib/python3.6/site-packages/requests/hooks.py", line 31, in dispatch_hook
    _hook_data = hook(hook_data, **kwargs)
  File "/usr/local/lib/python3.6/site-packages/uber_rides/utils/handlers.py", line 60, in error_handler
    raise ClientError(response, error_message)
  File "/usr/local/lib/python3.6/site-packages/uber_rides/errors.py", line 112, in __init__
    errors, meta = super(ClientError, self)._adapt_response(response)
  File "/usr/local/lib/python3.6/site-packages/uber_rides/errors.py", line 51, in _adapt_response
    raise UnknownHttpError(response)
uber_rides.errors.UnknownHttpError
2018-12-10 20:16:42 WARNING (MainThread) [homeassistant.components.sensor] Updating google_travel_time sensor took longer than the scheduled update interval 0:00:30
2018-12-10 20:16:46 ERROR (MainThread) [homeassistant.helpers.entity] Update for sensor.google_travel_time__driving fails
Traceback (most recent call last):
  File "/usr/local/lib/python3.6/site-packages/googlemaps/client.py", line 253, in _request
    result = self._get_body(response)
  File "/usr/local/lib/python3.6/site-packages/googlemaps/client.py", line 276, in _get_body
    raise googlemaps.exceptions._RetriableRequest()
googlemaps.exceptions._RetriableRequest

During handling of the above exception, another exception occurred:

Traceback (most recent call last):
  File "/usr/local/lib/python3.6/site-packages/googlemaps/client.py", line 253, in _request
    result = self._get_body(response)
  File "/usr/local/lib/python3.6/site-packages/googlemaps/client.py", line 276, in _get_body
    raise googlemaps.exceptions._RetriableRequest()
googlemaps.exceptions._RetriableRequest

During handling of the above exception, another exception occurred:

Traceback (most recent call last):
  File "/usr/local/lib/python3.6/site-packages/googlemaps/client.py", line 253, in _request
    result = self._get_body(response)
  File "/usr/local/lib/python3.6/site-packages/googlemaps/client.py", line 276, in _get_body
    raise googlemaps.exceptions._RetriableRequest()
googlemaps.exceptions._RetriableRequest

During handling of the above exception, another exception occurred:

Traceback (most recent call last):
  File "/usr/local/lib/python3.6/site-packages/googlemaps/client.py", line 253, in _request
    result = self._get_body(response)
  File "/usr/local/lib/python3.6/site-packages/googlemaps/client.py", line 276, in _get_body
    raise googlemaps.exceptions._RetriableRequest()
googlemaps.exceptions._RetriableRequest

During handling of the above exception, another exception occurred:

Traceback (most recent call last):
  File "/usr/local/lib/python3.6/site-packages/googlemaps/client.py", line 253, in _request
    result = self._get_body(response)
  File "/usr/local/lib/python3.6/site-packages/googlemaps/client.py", line 276, in _get_body
    raise googlemaps.exceptions._RetriableRequest()
googlemaps.exceptions._RetriableRequest

During handling of the above exception, another exception occurred:

Traceback (most recent call last):
  File "/usr/local/lib/python3.6/site-packages/googlemaps/client.py", line 253, in _request
    result = self._get_body(response)
  File "/usr/local/lib/python3.6/site-packages/googlemaps/client.py", line 276, in _get_body
    raise googlemaps.exceptions._RetriableRequest()
googlemaps.exceptions._RetriableRequest

During handling of the above exception, another exception occurred:

Traceback (most recent call last):
  File "/usr/local/lib/python3.6/site-packages/googlemaps/client.py", line 253, in _request
    result = self._get_body(response)
  File "/usr/local/lib/python3.6/site-packages/googlemaps/client.py", line 276, in _get_body
    raise googlemaps.exceptions._RetriableRequest()
googlemaps.exceptions._RetriableRequest

During handling of the above exception, another exception occurred:

Traceback (most recent call last):
  File "/usr/local/lib/python3.6/site-packages/googlemaps/client.py", line 253, in _request
    result = self._get_body(response)
  File "/usr/local/lib/python3.6/site-packages/googlemaps/client.py", line 276, in _get_body
    raise googlemaps.exceptions._RetriableRequest()
googlemaps.exceptions._RetriableRequest

During handling of the above exception, another exception occurred:

Traceback (most recent call last):
  File "/usr/local/lib/python3.6/site-packages/googlemaps/client.py", line 253, in _request
    result = self._get_body(response)
  File "/usr/local/lib/python3.6/site-packages/googlemaps/client.py", line 276, in _get_body
    raise googlemaps.exceptions._RetriableRequest()
googlemaps.exceptions._RetriableRequest

During handling of the above exception, another exception occurred:

Traceback (most recent call last):
  File "/usr/local/lib/python3.6/site-packages/googlemaps/client.py", line 253, in _request
    result = self._get_body(response)
  File "/usr/local/lib/python3.6/site-packages/googlemaps/client.py", line 276, in _get_body
    raise googlemaps.exceptions._RetriableRequest()
googlemaps.exceptions._RetriableRequest

During handling of the above exception, another exception occurred:

Traceback (most recent call last):
  File "/usr/local/lib/python3.6/site-packages/googlemaps/client.py", line 253, in _request
    result = self._get_body(response)
  File "/usr/local/lib/python3.6/site-packages/googlemaps/client.py", line 276, in _get_body
    raise googlemaps.exceptions._RetriableRequest()
googlemaps.exceptions._RetriableRequest

During handling of the above exception, another exception occurred:

Traceback (most recent call last):
  File "/usr/local/lib/python3.6/site-packages/homeassistant/helpers/entity.py", line 221, in async_update_ha_state
    await self.async_device_update()
  File "/usr/local/lib/python3.6/site-packages/homeassistant/helpers/entity.py", line 349, in async_device_update
    await self.hass.async_add_executor_job(self.update)
  File "/usr/local/lib/python3.6/concurrent/futures/thread.py", line 56, in run
    result = self.fn(*self.args, **self.kwargs)
  File "/usr/local/lib/python3.6/site-packages/homeassistant/util/__init__.py", line 324, in wrapper
    result = method(*args, **kwargs)
  File "/usr/local/lib/python3.6/site-packages/homeassistant/components/sensor/google_travel_time.py", line 242, in update
    self._origin, self._destination, **options_copy)
  File "/usr/local/lib/python3.6/site-packages/googlemaps/client.py", line 356, in wrapper
    result = func(*args, **kwargs)
  File "/usr/local/lib/python3.6/site-packages/googlemaps/distance_matrix.py", line 130, in distance_matrix
    return client._request("/maps/api/distancematrix/json", params)
  File "/usr/local/lib/python3.6/site-packages/googlemaps/client.py", line 260, in _request
    extract_body, requests_kwargs, post_json)
  File "/usr/local/lib/python3.6/site-packages/googlemaps/client.py", line 260, in _request
    extract_body, requests_kwargs, post_json)
  File "/usr/local/lib/python3.6/site-packages/googlemaps/client.py", line 260, in _request
    extract_body, requests_kwargs, post_json)
  [Previous line repeated 7 more times]
  File "/usr/local/lib/python3.6/site-packages/googlemaps/client.py", line 203, in _request
    raise googlemaps.exceptions.Timeout()
googlemaps.exceptions.Timeout
2018-12-10 20:16:55 ERROR (Thread-5) [pychromecast.socket_client] Failed to connect, retrying in 5.0s
2018-12-10 20:17:23 WARNING (MainThread) [homeassistant.helpers.entity] Update of sensor.google_travel_time__driving is taking over 10 seconds
2018-12-10 20:17:39 ERROR (Thread-5) [pychromecast.socket_client] Error reading from socket.
2018-12-10 20:17:39 WARNING (Thread-5) [pychromecast.socket_client] Error communicating with socket, resetting connection
2018-12-10 20:17:44 WARNING (MainThread) [homeassistant.components.sensor] Updating google_travel_time sensor took longer than the scheduled update interval 0:00:30
2018-12-10 20:18:15 WARNING (MainThread) [homeassistant.components.sensor] Updating google_travel_time sensor took longer than the scheduled update interval 0:00:30
2018-12-10 20:18:33 ERROR (MainThread) [homeassistant.helpers.entity] Update for sensor.google_travel_time__driving fails
Traceback (most recent call last):
  File "/usr/local/lib/python3.6/site-packages/googlemaps/client.py", line 253, in _request
    result = self._get_body(response)
  File "/usr/local/lib/python3.6/site-packages/googlemaps/client.py", line 276, in _get_body
    raise googlemaps.exceptions._RetriableRequest()
googlemaps.exceptions._RetriableRequest

During handling of the above exception, another exception occurred:

Traceback (most recent call last):
  File "/usr/local/lib/python3.6/site-packages/googlemaps/client.py", line 253, in _request
    result = self._get_body(response)
  File "/usr/local/lib/python3.6/site-packages/googlemaps/client.py", line 276, in _get_body
    raise googlemaps.exceptions._RetriableRequest()
googlemaps.exceptions._RetriableRequest

During handling of the above exception, another exception occurred:

Traceback (most recent call last):
  File "/usr/local/lib/python3.6/site-packages/googlemaps/client.py", line 253, in _request
    result = self._get_body(response)
  File "/usr/local/lib/python3.6/site-packages/googlemaps/client.py", line 276, in _get_body
    raise googlemaps.exceptions._RetriableRequest()
googlemaps.exceptions._RetriableRequest

During handling of the above exception, another exception occurred:

Traceback (most recent call last):
  File "/usr/local/lib/python3.6/site-packages/googlemaps/client.py", line 253, in _request
    result = self._get_body(response)
  File "/usr/local/lib/python3.6/site-packages/googlemaps/client.py", line 276, in _get_body
    raise googlemaps.exceptions._RetriableRequest()
googlemaps.exceptions._RetriableRequest

During handling of the above exception, another exception occurred:

Traceback (most recent call last):
  File "/usr/local/lib/python3.6/site-packages/googlemaps/client.py", line 253, in _request
    result = self._get_body(response)
  File "/usr/local/lib/python3.6/site-packages/googlemaps/client.py", line 276, in _get_body
    raise googlemaps.exceptions._RetriableRequest()
googlemaps.exceptions._RetriableRequest

During handling of the above exception, another exception occurred:

Traceback (most recent call last):
  File "/usr/local/lib/python3.6/site-packages/googlemaps/client.py", line 253, in _request
    result = self._get_body(response)
  File "/usr/local/lib/python3.6/site-packages/googlemaps/client.py", line 276, in _get_body
    raise googlemaps.exceptions._RetriableRequest()
googlemaps.exceptions._RetriableRequest

During handling of the above exception, another exception occurred:

Traceback (most recent call last):
  File "/usr/local/lib/python3.6/site-packages/googlemaps/client.py", line 253, in _request
    result = self._get_body(response)
  File "/usr/local/lib/python3.6/site-packages/googlemaps/client.py", line 276, in _get_body
    raise googlemaps.exceptions._RetriableRequest()
googlemaps.exceptions._RetriableRequest

During handling of the above exception, another exception occurred:

Traceback (most recent call last):
  File "/usr/local/lib/python3.6/site-packages/googlemaps/client.py", line 253, in _request
    result = self._get_body(response)
  File "/usr/local/lib/python3.6/site-packages/googlemaps/client.py", line 276, in _get_body
    raise googlemaps.exceptions._RetriableRequest()
googlemaps.exceptions._RetriableRequest

During handling of the above exception, another exception occurred:

Traceback (most recent call last):
  File "/usr/local/lib/python3.6/site-packages/googlemaps/client.py", line 253, in _request
    result = self._get_body(response)
  File "/usr/local/lib/python3.6/site-packages/googlemaps/client.py", line 276, in _get_body
    raise googlemaps.exceptions._RetriableRequest()
googlemaps.exceptions._RetriableRequest

During handling of the above exception, another exception occurred:

Traceback (most recent call last):
  File "/usr/local/lib/python3.6/site-packages/googlemaps/client.py", line 253, in _request
    result = self._get_body(response)
  File "/usr/local/lib/python3.6/site-packages/googlemaps/client.py", line 276, in _get_body
    raise googlemaps.exceptions._RetriableRequest()
googlemaps.exceptions._RetriableRequest

During handling of the above exception, another exception occurred:

Traceback (most recent call last):
  File "/usr/local/lib/python3.6/site-packages/googlemaps/client.py", line 253, in _request
    result = self._get_body(response)
  File "/usr/local/lib/python3.6/site-packages/googlemaps/client.py", line 276, in _get_body
    raise googlemaps.exceptions._RetriableRequest()
googlemaps.exceptions._RetriableRequest

During handling of the above exception, another exception occurred:

Traceback (most recent call last):
  File "/usr/local/lib/python3.6/site-packages/googlemaps/client.py", line 253, in _request
    result = self._get_body(response)
  File "/usr/local/lib/python3.6/site-packages/googlemaps/client.py", line 276, in _get_body
    raise googlemaps.exceptions._RetriableRequest()
googlemaps.exceptions._RetriableRequest

During handling of the above exception, another exception occurred:

Traceback (most recent call last):
  File "/usr/local/lib/python3.6/site-packages/homeassistant/helpers/entity.py", line 221, in async_update_ha_state
    await self.async_device_update()
  File "/usr/local/lib/python3.6/site-packages/homeassistant/helpers/entity.py", line 349, in async_device_update
    await self.hass.async_add_executor_job(self.update)
  File "/usr/local/lib/python3.6/concurrent/futures/thread.py", line 56, in run
    result = self.fn(*self.args, **self.kwargs)
  File "/usr/local/lib/python3.6/site-packages/homeassistant/util/__init__.py", line 324, in wrapper
    result = method(*args, **kwargs)
  File "/usr/local/lib/python3.6/site-packages/homeassistant/components/sensor/google_travel_time.py", line 242, in update
    self._origin, self._destination, **options_copy)
  File "/usr/local/lib/python3.6/site-packages/googlemaps/client.py", line 356, in wrapper
    result = func(*args, **kwargs)
  File "/usr/local/lib/python3.6/site-packages/googlemaps/distance_matrix.py", line 130, in distance_matrix
    return client._request("/maps/api/distancematrix/json", params)
  File "/usr/local/lib/python3.6/site-packages/googlemaps/client.py", line 260, in _request
    extract_body, requests_kwargs, post_json)
  File "/usr/local/lib/python3.6/site-packages/googlemaps/client.py", line 260, in _request
    extract_body, requests_kwargs, post_json)
  File "/usr/local/lib/python3.6/site-packages/googlemaps/client.py", line 260, in _request
    extract_body, requests_kwargs, post_json)
  [Previous line repeated 8 more times]
  File "/usr/local/lib/python3.6/site-packages/googlemaps/client.py", line 203, in _request
    raise googlemaps.exceptions.Timeout()
googlemaps.exceptions.Timeout
2018-12-10 20:18:47 ERROR (MainThread) [homeassistant.core] Error executing service <ServiceCall tts.google_say (c:9a6af4d3d22e4adeaa9317c12ef3e928): entity_id=['media_player.marcos_bedroom'], message=Olá Marco>
Traceback (most recent call last):
  File "/usr/local/lib/python3.6/site-packages/homeassistant/core.py", line 1177, in _event_to_service_call
    await service_handler.func(service_call)
  File "/usr/local/lib/python3.6/site-packages/homeassistant/components/tts/__init__.py", line 137, in async_say_handle
    options=options
  File "/usr/local/lib/python3.6/site-packages/homeassistant/components/tts/__init__.py", line 306, in async_get_url
    engine, key, message, use_cache, language, options)
  File "/usr/local/lib/python3.6/site-packages/homeassistant/components/tts/__init__.py", line 318, in async_get_tts_audio
    message, language, options)
  File "/usr/local/lib/python3.6/site-packages/homeassistant/components/tts/google.py", line 83, in async_get_tts_audio
    token.calculate_token, part)
  File "/usr/local/lib/python3.6/concurrent/futures/thread.py", line 56, in run
    result = self.fn(*self.args, **self.kwargs)
  File "/usr/local/lib/python3.6/site-packages/gtts_token/gtts_token.py", line 28, in calculate_token
    seed = self._get_token_key()
  File "/usr/local/lib/python3.6/site-packages/gtts_token/gtts_token.py", line 57, in _get_token_key
    tkk_expr = re.search(".*?(TKK=.*?;)W.*?", line).group(1)
AttributeError: 'NoneType' object has no attribute 'group'
2018-12-10 20:18:56 WARNING (MainThread) [homeassistant.helpers.entity] Update of sensor.google_travel_time__driving is taking over 10 seconds
2018-12-10 20:19:16 WARNING (MainThread) [homeassistant.components.sensor] Updating google_travel_time sensor took longer than the scheduled update interval 0:00:30
2018-12-10 20:19:37 ERROR (MainThread) [homeassistant.core] Error executing service <ServiceCall tts.google_say (c:7ee420e7fd8e4d199289bb68387cd908): entity_id=['media_player.marcos_bedroom'], message=Hello Marco>
Traceback (most recent call last):
  File "/usr/local/lib/python3.6/site-packages/homeassistant/core.py", line 1177, in _event_to_service_call
    await service_handler.func(service_call)
  File "/usr/local/lib/python3.6/site-packages/homeassistant/components/tts/__init__.py", line 137, in async_say_handle
    options=options
  File "/usr/local/lib/python3.6/site-packages/homeassistant/components/tts/__init__.py", line 306, in async_get_url
    engine, key, message, use_cache, language, options)
  File "/usr/local/lib/python3.6/site-packages/homeassistant/components/tts/__init__.py", line 318, in async_get_tts_audio
    message, language, options)
  File "/usr/local/lib/python3.6/site-packages/homeassistant/components/tts/google.py", line 83, in async_get_tts_audio
    token.calculate_token, part)
  File "/usr/local/lib/python3.6/concurrent/futures/thread.py", line 56, in run
    result = self.fn(*self.args, **self.kwargs)
  File "/usr/local/lib/python3.6/site-packages/gtts_token/gtts_token.py", line 28, in calculate_token
    seed = self._get_token_key()
  File "/usr/local/lib/python3.6/site-packages/gtts_token/gtts_token.py", line 57, in _get_token_key
    tkk_expr = re.search(".*?(TKK=.*?;)W.*?", line).group(1)
AttributeError: 'NoneType' object has no attribute 'group'
2018-12-10 20:19:47 WARNING (MainThread) [homeassistant.components.sensor] Updating google_travel_time sensor took longer than the scheduled update interval 0:00:30
2018-12-10 20:19:53 ERROR (MainThread) [homeassistant.helpers.entity] Update for sensor.google_travel_time__driving fails
Traceback (most recent call last):
  File "/usr/local/lib/python3.6/site-packages/googlemaps/client.py", line 253, in _request
    result = self._get_body(response)
  File "/usr/local/lib/python3.6/site-packages/googlemaps/client.py", line 276, in _get_body
    raise googlemaps.exceptions._RetriableRequest()
googlemaps.exceptions._RetriableRequest

During handling of the above exception, another exception occurred:

Traceback (most recent call last):
  File "/usr/local/lib/python3.6/site-packages/googlemaps/client.py", line 253, in _request
    result = self._get_body(response)
  File "/usr/local/lib/python3.6/site-packages/googlemaps/client.py", line 276, in _get_body
    raise googlemaps.exceptions._RetriableRequest()
googlemaps.exceptions._RetriableRequest

During handling of the above exception, another exception occurred:

Traceback (most recent call last):
  File "/usr/local/lib/python3.6/site-packages/googlemaps/client.py", line 253, in _request
    result = self._get_body(response)
  File "/usr/local/lib/python3.6/site-packages/googlemaps/client.py", line 276, in _get_body
    raise googlemaps.exceptions._RetriableRequest()
googlemaps.exceptions._RetriableRequest

During handling of the above exception, another exception occurred:

Traceback (most recent call last):
  File "/usr/local/lib/python3.6/site-packages/googlemaps/client.py", line 253, in _request
    result = self._get_body(response)
  File "/usr/local/lib/python3.6/site-packages/googlemaps/client.py", line 276, in _get_body
    raise googlemaps.exceptions._RetriableRequest()
googlemaps.exceptions._RetriableRequest

During handling of the above exception, another exception occurred:

Traceback (most recent call last):
  File "/usr/local/lib/python3.6/site-packages/googlemaps/client.py", line 253, in _request
    result = self._get_body(response)
  File "/usr/local/lib/python3.6/site-packages/googlemaps/client.py", line 276, in _get_body
    raise googlemaps.exceptions._RetriableRequest()
googlemaps.exceptions._RetriableRequest

During handling of the above exception, another exception occurred:

Traceback (most recent call last):
  File "/usr/local/lib/python3.6/site-packages/googlemaps/client.py", line 253, in _request
    result = self._get_body(response)
  File "/usr/local/lib/python3.6/site-packages/googlemaps/client.py", line 276, in _get_body
    raise googlemaps.exceptions._RetriableRequest()
googlemaps.exceptions._RetriableRequest

During handling of the above exception, another exception occurred:

Traceback (most recent call last):
  File "/usr/local/lib/python3.6/site-packages/googlemaps/client.py", line 253, in _request
    result = self._get_body(response)
  File "/usr/local/lib/python3.6/site-packages/googlemaps/client.py", line 276, in _get_body
    raise googlemaps.exceptions._RetriableRequest()
googlemaps.exceptions._RetriableRequest

During handling of the above exception, another exception occurred:

Traceback (most recent call last):
  File "/usr/local/lib/python3.6/site-packages/googlemaps/client.py", line 253, in _request
    result = self._get_body(response)
  File "/usr/local/lib/python3.6/site-packages/googlemaps/client.py", line 276, in _get_body
    raise googlemaps.exceptions._RetriableRequest()
googlemaps.exceptions._RetriableRequest

During handling of the above exception, another exception occurred:

Traceback (most recent call last):
  File "/usr/local/lib/python3.6/site-packages/googlemaps/client.py", line 253, in _request
    result = self._get_body(response)
  File "/usr/local/lib/python3.6/site-packages/googlemaps/client.py", line 276, in _get_body
    raise googlemaps.exceptions._RetriableRequest()
googlemaps.exceptions._RetriableRequest

During handling of the above exception, another exception occurred:

Traceback (most recent call last):
  File "/usr/local/lib/python3.6/site-packages/googlemaps/client.py", line 253, in _request
    result = self._get_body(response)
  File "/usr/local/lib/python3.6/site-packages/googlemaps/client.py", line 276, in _get_body
    raise googlemaps.exceptions._RetriableRequest()
googlemaps.exceptions._RetriableRequest

During handling of the above exception, another exception occurred:

Traceback (most recent call last):
  File "/usr/local/lib/python3.6/site-packages/googlemaps/client.py", line 253, in _request
    result = self._get_body(response)
  File "/usr/local/lib/python3.6/site-packages/googlemaps/client.py", line 276, in _get_body
    raise googlemaps.exceptions._RetriableRequest()
googlemaps.exceptions._RetriableRequest

During handling of the above exception, another exception occurred:

Traceback (most recent call last):
  File "/usr/local/lib/python3.6/site-packages/homeassistant/helpers/entity.py", line 221, in async_update_ha_state
    await self.async_device_update()
  File "/usr/local/lib/python3.6/site-packages/homeassistant/helpers/entity.py", line 349, in async_device_update
    await self.hass.async_add_executor_job(self.update)
  File "/usr/local/lib/python3.6/concurrent/futures/thread.py", line 56, in run
    result = self.fn(*self.args, **self.kwargs)
  File "/usr/local/lib/python3.6/site-packages/homeassistant/util/__init__.py", line 324, in wrapper
    result = method(*args, **kwargs)
  File "/usr/local/lib/python3.6/site-packages/homeassistant/components/sensor/google_travel_time.py", line 242, in update
    self._origin, self._destination, **options_copy)
  File "/usr/local/lib/python3.6/site-packages/googlemaps/client.py", line 356, in wrapper
    result = func(*args, **kwargs)
  File "/usr/local/lib/python3.6/site-packages/googlemaps/distance_matrix.py", line 130, in distance_matrix
    return client._request("/maps/api/distancematrix/json", params)
  File "/usr/local/lib/python3.6/site-packages/googlemaps/client.py", line 260, in _request
    extract_body, requests_kwargs, post_json)
  File "/usr/local/lib/python3.6/site-packages/googlemaps/client.py", line 260, in _request
    extract_body, requests_kwargs, post_json)
  File "/usr/local/lib/python3.6/site-packages/googlemaps/client.py", line 260, in _request
    extract_body, requests_kwargs, post_json)
  [Previous line repeated 7 more times]
  File "/usr/local/lib/python3.6/site-packages/googlemaps/client.py", line 203, in _request
    raise googlemaps.exceptions.Timeout()
googlemaps.exceptions.Timeout
2018-12-10 20:20:00 ERROR (MainThread) [homeassistant.core] Error executing service <ServiceCall tts.google_say (c:aedc743c963c433da8ced8718dca9038): entity_id=['media_player.marcos_bedroom'], message=Olá>
Traceback (most recent call last):
  File "/usr/local/lib/python3.6/site-packages/homeassistant/core.py", line 1177, in _event_to_service_call
    await service_handler.func(service_call)
  File "/usr/local/lib/python3.6/site-packages/homeassistant/components/tts/__init__.py", line 137, in async_say_handle
    options=options
  File "/usr/local/lib/python3.6/site-packages/homeassistant/components/tts/__init__.py", line 306, in async_get_url
    engine, key, message, use_cache, language, options)
  File "/usr/local/lib/python3.6/site-packages/homeassistant/components/tts/__init__.py", line 318, in async_get_tts_audio
    message, language, options)
  File "/usr/local/lib/python3.6/site-packages/homeassistant/components/tts/google.py", line 83, in async_get_tts_audio
    token.calculate_token, part)
  File "/usr/local/lib/python3.6/concurrent/futures/thread.py", line 56, in run
    result = self.fn(*self.args, **self.kwargs)
  File "/usr/local/lib/python3.6/site-packages/gtts_token/gtts_token.py", line 28, in calculate_token
    seed = self._get_token_key()
  File "/usr/local/lib/python3.6/site-packages/gtts_token/gtts_token.py", line 57, in _get_token_key
    tkk_expr = re.search(".*?(TKK=.*?;)W.*?", line).group(1)
AttributeError: 'NoneType' object has no attribute 'group'
2018-12-10 20:20:28 WARNING (MainThread) [homeassistant.helpers.entity] Update of sensor.google_travel_time__driving is taking over 10 seconds
2018-12-10 20:20:43 ERROR (SyncWorker_19) [homeassistant.components.sensor.waze_travel_time] Error on retrieving data: Internal Error
2018-12-10 20:20:49 WARNING (MainThread) [homeassistant.components.sensor] Updating google_travel_time sensor took longer than the scheduled update interval 0:00:30
2018-12-10 20:21:20 WARNING (MainThread) [homeassistant.components.sensor] Updating google_travel_time sensor took longer than the scheduled update interval 0:00:30
2018-12-10 20:21:24 ERROR (MainThread) [homeassistant.helpers.entity] Update for sensor.google_travel_time__driving fails
Traceback (most recent call last):
  File "/usr/local/lib/python3.6/site-packages/googlemaps/client.py", line 253, in _request
    result = self._get_body(response)
  File "/usr/local/lib/python3.6/site-packages/googlemaps/client.py", line 276, in _get_body
    raise googlemaps.exceptions._RetriableRequest()
googlemaps.exceptions._RetriableRequest

During handling of the above exception, another exception occurred:

Traceback (most recent call last):
  File "/usr/local/lib/python3.6/site-packages/googlemaps/client.py", line 253, in _request
    result = self._get_body(response)
  File "/usr/local/lib/python3.6/site-packages/googlemaps/client.py", line 276, in _get_body
    raise googlemaps.exceptions._RetriableRequest()
googlemaps.exceptions._RetriableRequest

During handling of the above exception, another exception occurred:

Traceback (most recent call last):
  File "/usr/local/lib/python3.6/site-packages/googlemaps/client.py", line 253, in _request
    result = self._get_body(response)
  File "/usr/local/lib/python3.6/site-packages/googlemaps/client.py", line 276, in _get_body
    raise googlemaps.exceptions._RetriableRequest()
googlemaps.exceptions._RetriableRequest

During handling of the above exception, another exception occurred:

Traceback (most recent call last):
  File "/usr/local/lib/python3.6/site-packages/googlemaps/client.py", line 253, in _request
    result = self._get_body(response)
  File "/usr/local/lib/python3.6/site-packages/googlemaps/client.py", line 276, in _get_body
    raise googlemaps.exceptions._RetriableRequest()
googlemaps.exceptions._RetriableRequest

During handling of the above exception, another exception occurred:

Traceback (most recent call last):
  File "/usr/local/lib/python3.6/site-packages/googlemaps/client.py", line 253, in _request
    result = self._get_body(response)
  File "/usr/local/lib/python3.6/site-packages/googlemaps/client.py", line 276, in _get_body
    raise googlemaps.exceptions._RetriableRequest()
googlemaps.exceptions._RetriableRequest

During handling of the above exception, another exception occurred:

Traceback (most recent call last):
  File "/usr/local/lib/python3.6/site-packages/googlemaps/client.py", line 253, in _request
    result = self._get_body(response)
  File "/usr/local/lib/python3.6/site-packages/googlemaps/client.py", line 276, in _get_body
    raise googlemaps.exceptions._RetriableRequest()
googlemaps.exceptions._RetriableRequest

During handling of the above exception, another exception occurred:

Traceback (most recent call last):
  File "/usr/local/lib/python3.6/site-packages/googlemaps/client.py", line 253, in _request
    result = self._get_body(response)
  File "/usr/local/lib/python3.6/site-packages/googlemaps/client.py", line 276, in _get_body
    raise googlemaps.exceptions._RetriableRequest()
googlemaps.exceptions._RetriableRequest

During handling of the above exception, another exception occurred:

Traceback (most recent call last):
  File "/usr/local/lib/python3.6/site-packages/googlemaps/client.py", line 253, in _request
    result = self._get_body(response)
  File "/usr/local/lib/python3.6/site-packages/googlemaps/client.py", line 276, in _get_body
    raise googlemaps.exceptions._RetriableRequest()
googlemaps.exceptions._RetriableRequest

During handling of the above exception, another exception occurred:

Traceback (most recent call last):
  File "/usr/local/lib/python3.6/site-packages/googlemaps/client.py", line 253, in _request
    result = self._get_body(response)
  File "/usr/local/lib/python3.6/site-packages/googlemaps/client.py", line 276, in _get_body
    raise googlemaps.exceptions._RetriableRequest()
googlemaps.exceptions._RetriableRequest

During handling of the above exception, another exception occurred:

Traceback (most recent call last):
  File "/usr/local/lib/python3.6/site-packages/googlemaps/client.py", line 253, in _request
    result = self._get_body(response)
  File "/usr/local/lib/python3.6/site-packages/googlemaps/client.py", line 276, in _get_body
    raise googlemaps.exceptions._RetriableRequest()
googlemaps.exceptions._RetriableRequest

During handling of the above exception, another exception occurred:

Traceback (most recent call last):
  File "/usr/local/lib/python3.6/site-packages/googlemaps/client.py", line 253, in _request
    result = self._get_body(response)
  File "/usr/local/lib/python3.6/site-packages/googlemaps/client.py", line 276, in _get_body
    raise googlemaps.exceptions._RetriableRequest()
googlemaps.exceptions._RetriableRequest

During handling of the above exception, another exception occurred:

Traceback (most recent call last):
  File "/usr/local/lib/python3.6/site-packages/homeassistant/helpers/entity.py", line 221, in async_update_ha_state
    await self.async_device_update()
  File "/usr/local/lib/python3.6/site-packages/homeassistant/helpers/entity.py", line 349, in async_device_update
    await self.hass.async_add_executor_job(self.update)
  File "/usr/local/lib/python3.6/concurrent/futures/thread.py", line 56, in run
    result = self.fn(*self.args, **self.kwargs)
  File "/usr/local/lib/python3.6/site-packages/homeassistant/util/__init__.py", line 324, in wrapper
    result = method(*args, **kwargs)
  File "/usr/local/lib/python3.6/site-packages/homeassistant/components/sensor/google_travel_time.py", line 242, in update
    self._origin, self._destination, **options_copy)
  File "/usr/local/lib/python3.6/site-packages/googlemaps/client.py", line 356, in wrapper
    result = func(*args, **kwargs)
  File "/usr/local/lib/python3.6/site-packages/googlemaps/distance_matrix.py", line 130, in distance_matrix
    return client._request("/maps/api/distancematrix/json", params)
  File "/usr/local/lib/python3.6/site-packages/googlemaps/client.py", line 260, in _request
    extract_body, requests_kwargs, post_json)
  File "/usr/local/lib/python3.6/site-packages/googlemaps/client.py", line 260, in _request
    extract_body, requests_kwargs, post_json)
  File "/usr/local/lib/python3.6/site-packages/googlemaps/client.py", line 260, in _request
    extract_body, requests_kwargs, post_json)
  [Previous line repeated 7 more times]
  File "/usr/local/lib/python3.6/site-packages/googlemaps/client.py", line 203, in _request
    raise googlemaps.exceptions.Timeout()
googlemaps.exceptions.Timeout
2018-12-10 20:22:01 WARNING (MainThread) [homeassistant.helpers.entity] Update of sensor.google_travel_time__driving is taking over 10 seconds
2018-12-10 20:22:22 WARNING (MainThread) [homeassistant.components.sensor] Updating google_travel_time sensor took longer than the scheduled update interval 0:00:30
2018-12-10 20:22:53 WARNING (MainThread) [homeassistant.components.sensor] Updating google_travel_time sensor took longer than the scheduled update interval 0:00:30
2018-12-10 20:23:24 WARNING (MainThread) [homeassistant.components.sensor] Updating google_travel_time sensor took longer than the scheduled update interval 0:00:30
2018-12-10 20:23:28 ERROR (MainThread) [homeassistant.helpers.entity] Update for sensor.google_travel_time__driving fails
Traceback (most recent call last):
  File "/usr/local/lib/python3.6/site-packages/googlemaps/client.py", line 253, in _request
    result = self._get_body(response)
  File "/usr/local/lib/python3.6/site-packages/googlemaps/client.py", line 276, in _get_body
    raise googlemaps.exceptions._RetriableRequest()
googlemaps.exceptions._RetriableRequest

During handling of the above exception, another exception occurred:

Traceback (most recent call last):
  File "/usr/local/lib/python3.6/site-packages/googlemaps/client.py", line 253, in _request
    result = self._get_body(response)
  File "/usr/local/lib/python3.6/site-packages/googlemaps/client.py", line 276, in _get_body
    raise googlemaps.exceptions._RetriableRequest()
googlemaps.exceptions._RetriableRequest

During handling of the above exception, another exception occurred:

Traceback (most recent call last):
  File "/usr/local/lib/python3.6/site-packages/googlemaps/client.py", line 253, in _request
    result = self._get_body(response)
  File "/usr/local/lib/python3.6/site-packages/googlemaps/client.py", line 276, in _get_body
    raise googlemaps.exceptions._RetriableRequest()
googlemaps.exceptions._RetriableRequest

During handling of the above exception, another exception occurred:

Traceback (most recent call last):
  File "/usr/local/lib/python3.6/site-packages/googlemaps/client.py", line 253, in _request
    result = self._get_body(response)
  File "/usr/local/lib/python3.6/site-packages/googlemaps/client.py", line 276, in _get_body
    raise googlemaps.exceptions._RetriableRequest()
googlemaps.exceptions._RetriableRequest

During handling of the above exception, another exception occurred:

Traceback (most recent call last):
  File "/usr/local/lib/python3.6/site-packages/googlemaps/client.py", line 253, in _request
    result = self._get_body(response)
  File "/usr/local/lib/python3.6/site-packages/googlemaps/client.py", line 276, in _get_body
    raise googlemaps.exceptions._RetriableRequest()
googlemaps.exceptions._RetriableRequest

During handling of the above exception, another exception occurred:

Traceback (most recent call last):
  File "/usr/local/lib/python3.6/site-packages/googlemaps/client.py", line 253, in _request
    result = self._get_body(response)
  File "/usr/local/lib/python3.6/site-packages/googlemaps/client.py", line 276, in _get_body
    raise googlemaps.exceptions._RetriableRequest()
googlemaps.exceptions._RetriableRequest

During handling of the above exception, another exception occurred:

Traceback (most recent call last):
  File "/usr/local/lib/python3.6/site-packages/googlemaps/client.py", line 253, in _request
    result = self._get_body(response)
  File "/usr/local/lib/python3.6/site-packages/googlemaps/client.py", line 276, in _get_body
    raise googlemaps.exceptions._RetriableRequest()
googlemaps.exceptions._RetriableRequest

During handling of the above exception, another exception occurred:

Traceback (most recent call last):
  File "/usr/local/lib/python3.6/site-packages/googlemaps/client.py", line 253, in _request
    result = self._get_body(response)
  File "/usr/local/lib/python3.6/site-packages/googlemaps/client.py", line 276, in _get_body
    raise googlemaps.exceptions._RetriableRequest()
googlemaps.exceptions._RetriableRequest

During handling of the above exception, another exception occurred:

Traceback (most recent call last):
  File "/usr/local/lib/python3.6/site-packages/googlemaps/client.py", line 253, in _request
    result = self._get_body(response)
  File "/usr/local/lib/python3.6/site-packages/googlemaps/client.py", line 276, in _get_body
    raise googlemaps.exceptions._RetriableRequest()
googlemaps.exceptions._RetriableRequest

During handling of the above exception, another exception occurred:

Traceback (most recent call last):
  File "/usr/local/lib/python3.6/site-packages/googlemaps/client.py", line 253, in _request
    result = self._get_body(response)
  File "/usr/local/lib/python3.6/site-packages/googlemaps/client.py", line 276, in _get_body
    raise googlemaps.exceptions._RetriableRequest()
googlemaps.exceptions._RetriableRequest

During handling of the above exception, another exception occurred:

Traceback (most recent call last):
  File "/usr/local/lib/python3.6/site-packages/googlemaps/client.py", line 253, in _request
    result = self._get_body(response)
  File "/usr/local/lib/python3.6/site-packages/googlemaps/client.py", line 276, in _get_body
    raise googlemaps.exceptions._RetriableRequest()
googlemaps.exceptions._RetriableRequest

During handling of the above exception, another exception occurred:

Traceback (most recent call last):
  File "/usr/local/lib/python3.6/site-packages/googlemaps/client.py", line 253, in _request
    result = self._get_body(response)
  File "/usr/local/lib/python3.6/site-packages/googlemaps/client.py", line 276, in _get_body
    raise googlemaps.exceptions._RetriableRequest()
googlemaps.exceptions._RetriableRequest

During handling of the above exception, another exception occurred:

Traceback (most recent call last):
  File "/usr/local/lib/python3.6/site-packages/homeassistant/helpers/entity.py", line 221, in async_update_ha_state
    await self.async_device_update()
  File "/usr/local/lib/python3.6/site-packages/homeassistant/helpers/entity.py", line 349, in async_device_update
    await self.hass.async_add_executor_job(self.update)
  File "/usr/local/lib/python3.6/concurrent/futures/thread.py", line 56, in run
    result = self.fn(*self.args, **self.kwargs)
  File "/usr/local/lib/python3.6/site-packages/homeassistant/util/__init__.py", line 324, in wrapper
    result = method(*args, **kwargs)
  File "/usr/local/lib/python3.6/site-packages/homeassistant/components/sensor/google_travel_time.py", line 242, in update
    self._origin, self._destination, **options_copy)
  File "/usr/local/lib/python3.6/site-packages/googlemaps/client.py", line 356, in wrapper
    result = func(*args, **kwargs)
  File "/usr/local/lib/python3.6/site-packages/googlemaps/distance_matrix.py", line 130, in distance_matrix
    return client._request("/maps/api/distancematrix/json", params)
  File "/usr/local/lib/python3.6/site-packages/googlemaps/client.py", line 260, in _request
    extract_body, requests_kwargs, post_json)
  File "/usr/local/lib/python3.6/site-packages/googlemaps/client.py", line 260, in _request
    extract_body, requests_kwargs, post_json)
  File "/usr/local/lib/python3.6/site-packages/googlemaps/client.py", line 260, in _request
    extract_body, requests_kwargs, post_json)
  [Previous line repeated 8 more times]
  File "/usr/local/lib/python3.6/site-packages/googlemaps/client.py", line 203, in _request
    raise googlemaps.exceptions.Timeout()
googlemaps.exceptions.Timeout
2018-12-10 20:24:05 WARNING (MainThread) [homeassistant.helpers.entity] Update of sensor.google_travel_time__driving is taking over 10 seconds
2018-12-10 20:24:26 WARNING (MainThread) [homeassistant.components.sensor] Updating google_travel_time sensor took longer than the scheduled update interval 0:00:30
2018-12-10 20:24:57 WARNING (MainThread) [homeassistant.components.sensor] Updating google_travel_time sensor took longer than the scheduled update interval 0:00:30
2018-12-10 20:25:26 ERROR (MainThread) [homeassistant.helpers.entity] Update for sensor.google_travel_time__driving fails
Traceback (most recent call last):
  File "/usr/local/lib/python3.6/site-packages/googlemaps/client.py", line 253, in _request
    result = self._get_body(response)
  File "/usr/local/lib/python3.6/site-packages/googlemaps/client.py", line 276, in _get_body
    raise googlemaps.exceptions._RetriableRequest()
googlemaps.exceptions._RetriableRequest

During handling of the above exception, another exception occurred:

Traceback (most recent call last):
  File "/usr/local/lib/python3.6/site-packages/googlemaps/client.py", line 253, in _request
    result = self._get_body(response)
  File "/usr/local/lib/python3.6/site-packages/googlemaps/client.py", line 276, in _get_body
    raise googlemaps.exceptions._RetriableRequest()
googlemaps.exceptions._RetriableRequest

During handling of the above exception, another exception occurred:

Traceback (most recent call last):
  File "/usr/local/lib/python3.6/site-packages/googlemaps/client.py", line 253, in _request
    result = self._get_body(response)
  File "/usr/local/lib/python3.6/site-packages/googlemaps/client.py", line 276, in _get_body
    raise googlemaps.exceptions._RetriableRequest()
googlemaps.exceptions._RetriableRequest

During handling of the above exception, another exception occurred:

Traceback (most recent call last):
  File "/usr/local/lib/python3.6/site-packages/googlemaps/client.py", line 253, in _request
    result = self._get_body(response)
  File "/usr/local/lib/python3.6/site-packages/googlemaps/client.py", line 276, in _get_body
    raise googlemaps.exceptions._RetriableRequest()
googlemaps.exceptions._RetriableRequest

During handling of the above exception, another exception occurred:

Traceback (most recent call last):
  File "/usr/local/lib/python3.6/site-packages/googlemaps/client.py", line 253, in _request
    result = self._get_body(response)
  File "/usr/local/lib/python3.6/site-packages/googlemaps/client.py", line 276, in _get_body
    raise googlemaps.exceptions._RetriableRequest()
googlemaps.exceptions._RetriableRequest

During handling of the above exception, another exception occurred:

Traceback (most recent call last):
  File "/usr/local/lib/python3.6/site-packages/googlemaps/client.py", line 253, in _request
    result = self._get_body(response)
  File "/usr/local/lib/python3.6/site-packages/googlemaps/client.py", line 276, in _get_body
    raise googlemaps.exceptions._RetriableRequest()
googlemaps.exceptions._RetriableRequest

During handling of the above exception, another exception occurred:

Traceback (most recent call last):
  File "/usr/local/lib/python3.6/site-packages/googlemaps/client.py", line 253, in _request
    result = self._get_body(response)
  File "/usr/local/lib/python3.6/site-packages/googlemaps/client.py", line 276, in _get_body
    raise googlemaps.exceptions._RetriableRequest()
googlemaps.exceptions._RetriableRequest

During handling of the above exception, another exception occurred:

Traceback (most recent call last):
  File "/usr/local/lib/python3.6/site-packages/googlemaps/client.py", line 253, in _request
    result = self._get_body(response)
  File "/usr/local/lib/python3.6/site-packages/googlemaps/client.py", line 276, in _get_body
    raise googlemaps.exceptions._RetriableRequest()
googlemaps.exceptions._RetriableRequest

During handling of the above exception, another exception occurred:

Traceback (most recent call last):
  File "/usr/local/lib/python3.6/site-packages/googlemaps/client.py", line 253, in _request
    result = self._get_body(response)
  File "/usr/local/lib/python3.6/site-packages/googlemaps/client.py", line 276, in _get_body
    raise googlemaps.exceptions._RetriableRequest()
googlemaps.exceptions._RetriableRequest

During handling of the above exception, another exception occurred:

Traceback (most recent call last):
  File "/usr/local/lib/python3.6/site-packages/googlemaps/client.py", line 253, in _request
    result = self._get_body(response)
  File "/usr/local/lib/python3.6/site-packages/googlemaps/client.py", line 276, in _get_body
    raise googlemaps.exceptions._RetriableRequest()
googlemaps.exceptions._RetriableRequest

During handling of the above exception, another exception occurred:

Traceback (most recent call last):
  File "/usr/local/lib/python3.6/site-packages/googlemaps/client.py", line 253, in _request
    result = self._get_body(response)
  File "/usr/local/lib/python3.6/site-packages/googlemaps/client.py", line 276, in _get_body
    raise googlemaps.exceptions._RetriableRequest()
googlemaps.exceptions._RetriableRequest

During handling of the above exception, another exception occurred:

Traceback (most recent call last):
  File "/usr/local/lib/python3.6/site-packages/googlemaps/client.py", line 253, in _request
    result = self._get_body(response)
  File "/usr/local/lib/python3.6/site-packages/googlemaps/client.py", line 276, in _get_body
    raise googlemaps.exceptions._RetriableRequest()
googlemaps.exceptions._RetriableRequest

During handling of the above exception, another exception occurred:

Traceback (most recent call last):
  File "/usr/local/lib/python3.6/site-packages/homeassistant/helpers/entity.py", line 221, in async_update_ha_state
    await self.async_device_update()
  File "/usr/local/lib/python3.6/site-packages/homeassistant/helpers/entity.py", line 349, in async_device_update
    await self.hass.async_add_executor_job(self.update)
  File "/usr/local/lib/python3.6/concurrent/futures/thread.py", line 56, in run
    result = self.fn(*self.args, **self.kwargs)
  File "/usr/local/lib/python3.6/site-packages/homeassistant/util/__init__.py", line 324, in wrapper
    result = method(*args, **kwargs)
  File "/usr/local/lib/python3.6/site-packages/homeassistant/components/sensor/google_travel_time.py", line 242, in update
    self._origin, self._destination, **options_copy)
  File "/usr/local/lib/python3.6/site-packages/googlemaps/client.py", line 356, in wrapper
    result = func(*args, **kwargs)
  File "/usr/local/lib/python3.6/site-packages/googlemaps/distance_matrix.py", line 130, in distance_matrix
    return client._request("/maps/api/distancematrix/json", params)
  File "/usr/local/lib/python3.6/site-packages/googlemaps/client.py", line 260, in _request
    extract_body, requests_kwargs, post_json)
  File "/usr/local/lib/python3.6/site-packages/googlemaps/client.py", line 260, in _request
    extract_body, requests_kwargs, post_json)
  File "/usr/local/lib/python3.6/site-packages/googlemaps/client.py", line 260, in _request
    extract_body, requests_kwargs, post_json)
  [Previous line repeated 8 more times]
  File "/usr/local/lib/python3.6/site-packages/googlemaps/client.py", line 203, in _request
    raise googlemaps.exceptions.Timeout()
googlemaps.exceptions.Timeout
2018-12-10 20:25:38 WARNING (MainThread) [homeassistant.helpers.entity] Update of sensor.google_travel_time__driving is taking over 10 seconds
2018-12-10 20:25:47 ERROR (SyncWorker_3) [homeassistant.components.sensor.waze_travel_time] Error on retrieving data: Internal Error
2018-12-10 20:25:59 WARNING (MainThread) [homeassistant.components.sensor] Updating google_travel_time sensor took longer than the scheduled update interval 0:00:30
2018-12-10 20:26:28 ERROR (MainThread) [homeassistant.helpers.entity] Update for sensor.google_travel_time__driving fails
Traceback (most recent call last):
  File "/usr/local/lib/python3.6/site-packages/googlemaps/client.py", line 253, in _request
    result = self._get_body(response)
  File "/usr/local/lib/python3.6/site-packages/googlemaps/client.py", line 276, in _get_body
    raise googlemaps.exceptions._RetriableRequest()
googlemaps.exceptions._RetriableRequest

During handling of the above exception, another exception occurred:

Traceback (most recent call last):
  File "/usr/local/lib/python3.6/site-packages/googlemaps/client.py", line 253, in _request
    result = self._get_body(response)
  File "/usr/local/lib/python3.6/site-packages/googlemaps/client.py", line 276, in _get_body
    raise googlemaps.exceptions._RetriableRequest()
googlemaps.exceptions._RetriableRequest

During handling of the above exception, another exception occurred:

Traceback (most recent call last):
  File "/usr/local/lib/python3.6/site-packages/googlemaps/client.py", line 253, in _request
    result = self._get_body(response)
  File "/usr/local/lib/python3.6/site-packages/googlemaps/client.py", line 276, in _get_body
    raise googlemaps.exceptions._RetriableRequest()
googlemaps.exceptions._RetriableRequest

During handling of the above exception, another exception occurred:

Traceback (most recent call last):
  File "/usr/local/lib/python3.6/site-packages/googlemaps/client.py", line 253, in _request
    result = self._get_body(response)
  File "/usr/local/lib/python3.6/site-packages/googlemaps/client.py", line 276, in _get_body
    raise googlemaps.exceptions._RetriableRequest()
googlemaps.exceptions._RetriableRequest

During handling of the above exception, another exception occurred:

Traceback (most recent call last):
  File "/usr/local/lib/python3.6/site-packages/googlemaps/client.py", line 253, in _request
    result = self._get_body(response)
  File "/usr/local/lib/python3.6/site-packages/googlemaps/client.py", line 276, in _get_body
    raise googlemaps.exceptions._RetriableRequest()
googlemaps.exceptions._RetriableRequest

During handling of the above exception, another exception occurred:

Traceback (most recent call last):
  File "/usr/local/lib/python3.6/site-packages/googlemaps/client.py", line 253, in _request
    result = self._get_body(response)
  File "/usr/local/lib/python3.6/site-packages/googlemaps/client.py", line 276, in _get_body
    raise googlemaps.exceptions._RetriableRequest()
googlemaps.exceptions._RetriableRequest

During handling of the above exception, another exception occurred:

Traceback (most recent call last):
  File "/usr/local/lib/python3.6/site-packages/googlemaps/client.py", line 253, in _request
    result = self._get_body(response)
  File "/usr/local/lib/python3.6/site-packages/googlemaps/client.py", line 276, in _get_body
    raise googlemaps.exceptions._RetriableRequest()
googlemaps.exceptions._RetriableRequest

During handling of the above exception, another exception occurred:

Traceback (most recent call last):
  File "/usr/local/lib/python3.6/site-packages/googlemaps/client.py", line 253, in _request
    result = self._get_body(response)
  File "/usr/local/lib/python3.6/site-packages/googlemaps/client.py", line 276, in _get_body
    raise googlemaps.exceptions._RetriableRequest()
googlemaps.exceptions._RetriableRequest

During handling of the above exception, another exception occurred:

Traceback (most recent call last):
  File "/usr/local/lib/python3.6/site-packages/googlemaps/client.py", line 253, in _request
    result = self._get_body(response)
  File "/usr/local/lib/python3.6/site-packages/googlemaps/client.py", line 276, in _get_body
    raise googlemaps.exceptions._RetriableRequest()
googlemaps.exceptions._RetriableRequest

During handling of the above exception, another exception occurred:

Traceback (most recent call last):
  File "/usr/local/lib/python3.6/site-packages/googlemaps/client.py", line 253, in _request
    result = self._get_body(response)
  File "/usr/local/lib/python3.6/site-packages/googlemaps/client.py", line 276, in _get_body
    raise googlemaps.exceptions._RetriableRequest()
googlemaps.exceptions._RetriableRequest

During handling of the above exception, another exception occurred:

Traceback (most recent call last):
  File "/usr/local/lib/python3.6/site-packages/googlemaps/client.py", line 253, in _request
    result = self._get_body(response)
  File "/usr/local/lib/python3.6/site-packages/googlemaps/client.py", line 276, in _get_body
    raise googlemaps.exceptions._RetriableRequest()
googlemaps.exceptions._RetriableRequest

During handling of the above exception, another exception occurred:

Traceback (most recent call last):
  File "/usr/local/lib/python3.6/site-packages/homeassistant/helpers/entity.py", line 221, in async_update_ha_state
    await self.async_device_update()
  File "/usr/local/lib/python3.6/site-packages/homeassistant/helpers/entity.py", line 349, in async_device_update
    await self.hass.async_add_executor_job(self.update)
  File "/usr/local/lib/python3.6/concurrent/futures/thread.py", line 56, in run
    result = self.fn(*self.args, **self.kwargs)
  File "/usr/local/lib/python3.6/site-packages/homeassistant/util/__init__.py", line 324, in wrapper
    result = method(*args, **kwargs)
  File "/usr/local/lib/python3.6/site-packages/homeassistant/components/sensor/google_travel_time.py", line 242, in update
    self._origin, self._destination, **options_copy)
  File "/usr/local/lib/python3.6/site-packages/googlemaps/client.py", line 356, in wrapper
    result = func(*args, **kwargs)
  File "/usr/local/lib/python3.6/site-packages/googlemaps/distance_matrix.py", line 130, in distance_matrix
    return client._request("/maps/api/distancematrix/json", params)
  File "/usr/local/lib/python3.6/site-packages/googlemaps/client.py", line 260, in _request
    extract_body, requests_kwargs, post_json)
  File "/usr/local/lib/python3.6/site-packages/googlemaps/client.py", line 260, in _request
    extract_body, requests_kwargs, post_json)
  File "/usr/local/lib/python3.6/site-packages/googlemaps/client.py", line 260, in _request
    extract_body, requests_kwargs, post_json)
  [Previous line repeated 7 more times]
  File "/usr/local/lib/python3.6/site-packages/googlemaps/client.py", line 203, in _request
    raise googlemaps.exceptions.Timeout()
googlemaps.exceptions.Timeout
2018-12-10 20:26:40 WARNING (MainThread) [homeassistant.helpers.entity] Update of sensor.google_travel_time__driving is taking over 10 seconds
2018-12-10 20:27:01 WARNING (MainThread) [homeassistant.components.sensor] Updating google_travel_time sensor took longer than the scheduled update interval 0:00:30
2018-12-10 20:27:31 WARNING (MainThread) [homeassistant.components.sensor] Updating google_travel_time sensor took longer than the scheduled update interval 0:00:30
2018-12-10 20:27:38 ERROR (MainThread) [homeassistant.helpers.entity] Update for sensor.google_travel_time__driving fails
Traceback (most recent call last):
  File "/usr/local/lib/python3.6/site-packages/googlemaps/client.py", line 253, in _request
    result = self._get_body(response)
  File "/usr/local/lib/python3.6/site-packages/googlemaps/client.py", line 276, in _get_body
    raise googlemaps.exceptions._RetriableRequest()
googlemaps.exceptions._RetriableRequest

During handling of the above exception, another exception occurred:

Traceback (most recent call last):
  File "/usr/local/lib/python3.6/site-packages/googlemaps/client.py", line 253, in _request
    result = self._get_body(response)
  File "/usr/local/lib/python3.6/site-packages/googlemaps/client.py", line 276, in _get_body
    raise googlemaps.exceptions._RetriableRequest()
googlemaps.exceptions._RetriableRequest

During handling of the above exception, another exception occurred:

Traceback (most recent call last):
  File "/usr/local/lib/python3.6/site-packages/googlemaps/client.py", line 253, in _request
    result = self._get_body(response)
  File "/usr/local/lib/python3.6/site-packages/googlemaps/client.py", line 276, in _get_body
    raise googlemaps.exceptions._RetriableRequest()
googlemaps.exceptions._RetriableRequest

During handling of the above exception, another exception occurred:

Traceback (most recent call last):
  File "/usr/local/lib/python3.6/site-packages/googlemaps/client.py", line 253, in _request
    result = self._get_body(response)
  File "/usr/local/lib/python3.6/site-packages/googlemaps/client.py", line 276, in _get_body
    raise googlemaps.exceptions._RetriableRequest()
googlemaps.exceptions._RetriableRequest

During handling of the above exception, another exception occurred:

Traceback (most recent call last):
  File "/usr/local/lib/python3.6/site-packages/googlemaps/client.py", line 253, in _request
    result = self._get_body(response)
  File "/usr/local/lib/python3.6/site-packages/googlemaps/client.py", line 276, in _get_body
    raise googlemaps.exceptions._RetriableRequest()
googlemaps.exceptions._RetriableRequest

During handling of the above exception, another exception occurred:

Traceback (most recent call last):
  File "/usr/local/lib/python3.6/site-packages/googlemaps/client.py", line 253, in _request
    result = self._get_body(response)
  File "/usr/local/lib/python3.6/site-packages/googlemaps/client.py", line 276, in _get_body
    raise googlemaps.exceptions._RetriableRequest()
googlemaps.exceptions._RetriableRequest

During handling of the above exception, another exception occurred:

Traceback (most recent call last):
  File "/usr/local/lib/python3.6/site-packages/googlemaps/client.py", line 253, in _request
    result = self._get_body(response)
  File "/usr/local/lib/python3.6/site-packages/googlemaps/client.py", line 276, in _get_body
    raise googlemaps.exceptions._RetriableRequest()
googlemaps.exceptions._RetriableRequest

During handling of the above exception, another exception occurred:

Traceback (most recent call last):
  File "/usr/local/lib/python3.6/site-packages/googlemaps/client.py", line 253, in _request
    result = self._get_body(response)
  File "/usr/local/lib/python3.6/site-packages/googlemaps/client.py", line 276, in _get_body
    raise googlemaps.exceptions._RetriableRequest()
googlemaps.exceptions._RetriableRequest

During handling of the above exception, another exception occurred:

Traceback (most recent call last):
  File "/usr/local/lib/python3.6/site-packages/googlemaps/client.py", line 253, in _request
    result = self._get_body(response)
  File "/usr/local/lib/python3.6/site-packages/googlemaps/client.py", line 276, in _get_body
    raise googlemaps.exceptions._RetriableRequest()
googlemaps.exceptions._RetriableRequest

During handling of the above exception, another exception occurred:

Traceback (most recent call last):
  File "/usr/local/lib/python3.6/site-packages/googlemaps/client.py", line 253, in _request
    result = self._get_body(response)
  File "/usr/local/lib/python3.6/site-packages/googlemaps/client.py", line 276, in _get_body
    raise googlemaps.exceptions._RetriableRequest()
googlemaps.exceptions._RetriableRequest

During handling of the above exception, another exception occurred:

Traceback (most recent call last):
  File "/usr/local/lib/python3.6/site-packages/googlemaps/client.py", line 253, in _request
    result = self._get_body(response)
  File "/usr/local/lib/python3.6/site-packages/googlemaps/client.py", line 276, in _get_body
    raise googlemaps.exceptions._RetriableRequest()
googlemaps.exceptions._RetriableRequest

During handling of the above exception, another exception occurred:

Traceback (most recent call last):
  File "/usr/local/lib/python3.6/site-packages/homeassistant/helpers/entity.py", line 221, in async_update_ha_state
    await self.async_device_update()
  File "/usr/local/lib/python3.6/site-packages/homeassistant/helpers/entity.py", line 349, in async_device_update
    await self.hass.async_add_executor_job(self.update)
  File "/usr/local/lib/python3.6/concurrent/futures/thread.py", line 56, in run
    result = self.fn(*self.args, **self.kwargs)
  File "/usr/local/lib/python3.6/site-packages/homeassistant/util/__init__.py", line 324, in wrapper
    result = method(*args, **kwargs)
  File "/usr/local/lib/python3.6/site-packages/homeassistant/components/sensor/google_travel_time.py", line 242, in update
    self._origin, self._destination, **options_copy)
  File "/usr/local/lib/python3.6/site-packages/googlemaps/client.py", line 356, in wrapper
    result = func(*args, **kwargs)
  File "/usr/local/lib/python3.6/site-packages/googlemaps/distance_matrix.py", line 130, in distance_matrix
    return client._request("/maps/api/distancematrix/json", params)
  File "/usr/local/lib/python3.6/site-packages/googlemaps/client.py", line 260, in _request
    extract_body, requests_kwargs, post_json)
  File "/usr/local/lib/python3.6/site-packages/googlemaps/client.py", line 260, in _request
    extract_body, requests_kwargs, post_json)
  File "/usr/local/lib/python3.6/site-packages/googlemaps/client.py", line 260, in _request
    extract_body, requests_kwargs, post_json)
  [Previous line repeated 7 more times]
  File "/usr/local/lib/python3.6/site-packages/googlemaps/client.py", line 203, in _request
    raise googlemaps.exceptions.Timeout()
googlemaps.exceptions.Timeout
2018-12-10 20:28:12 WARNING (MainThread) [homeassistant.helpers.entity] Update of sensor.google_travel_time__driving is taking over 10 seconds
2018-12-10 20:28:33 WARNING (MainThread) [homeassistant.components.sensor] Updating google_travel_time sensor took longer than the scheduled update interval 0:00:30
2018-12-10 20:29:03 ERROR (MainThread) [homeassistant.helpers.entity] Update for sensor.google_travel_time__driving fails
Traceback (most recent call last):
  File "/usr/local/lib/python3.6/site-packages/googlemaps/client.py", line 253, in _request
    result = self._get_body(response)
  File "/usr/local/lib/python3.6/site-packages/googlemaps/client.py", line 276, in _get_body
    raise googlemaps.exceptions._RetriableRequest()
googlemaps.exceptions._RetriableRequest

During handling of the above exception, another exception occurred:

Traceback (most recent call last):
  File "/usr/local/lib/python3.6/site-packages/googlemaps/client.py", line 253, in _request
    result = self._get_body(response)
  File "/usr/local/lib/python3.6/site-packages/googlemaps/client.py", line 276, in _get_body
    raise googlemaps.exceptions._RetriableRequest()
googlemaps.exceptions._RetriableRequest

During handling of the above exception, another exception occurred:

Traceback (most recent call last):
  File "/usr/local/lib/python3.6/site-packages/googlemaps/client.py", line 253, in _request
    result = self._get_body(response)
  File "/usr/local/lib/python3.6/site-packages/googlemaps/client.py", line 276, in _get_body
    raise googlemaps.exceptions._RetriableRequest()
googlemaps.exceptions._RetriableRequest

During handling of the above exception, another exception occurred:

Traceback (most recent call last):
  File "/usr/local/lib/python3.6/site-packages/googlemaps/client.py", line 253, in _request
    result = self._get_body(response)
  File "/usr/local/lib/python3.6/site-packages/googlemaps/client.py", line 276, in _get_body
    raise googlemaps.exceptions._RetriableRequest()
googlemaps.exceptions._RetriableRequest

During handling of the above exception, another exception occurred:

Traceback (most recent call last):
  File "/usr/local/lib/python3.6/site-packages/googlemaps/client.py", line 253, in _request
    result = self._get_body(response)
  File "/usr/local/lib/python3.6/site-packages/googlemaps/client.py", line 276, in _get_body
    raise googlemaps.exceptions._RetriableRequest()
googlemaps.exceptions._RetriableRequest

During handling of the above exception, another exception occurred:

Traceback (most recent call last):
  File "/usr/local/lib/python3.6/site-packages/googlemaps/client.py", line 253, in _request
    result = self._get_body(response)
  File "/usr/local/lib/python3.6/site-packages/googlemaps/client.py", line 276, in _get_body
    raise googlemaps.exceptions._RetriableRequest()
googlemaps.exceptions._RetriableRequest

During handling of the above exception, another exception occurred:

Traceback (most recent call last):
  File "/usr/local/lib/python3.6/site-packages/googlemaps/client.py", line 253, in _request
    result = self._get_body(response)
  File "/usr/local/lib/python3.6/site-packages/googlemaps/client.py", line 276, in _get_body
    raise googlemaps.exceptions._RetriableRequest()
googlemaps.exceptions._RetriableRequest

During handling of the above exception, another exception occurred:

Traceback (most recent call last):
  File "/usr/local/lib/python3.6/site-packages/googlemaps/client.py", line 253, in _request
    result = self._get_body(response)
  File "/usr/local/lib/python3.6/site-packages/googlemaps/client.py", line 276, in _get_body
    raise googlemaps.exceptions._RetriableRequest()
googlemaps.exceptions._RetriableRequest

During handling of the above exception, another exception occurred:

Traceback (most recent call last):
  File "/usr/local/lib/python3.6/site-packages/googlemaps/client.py", line 253, in _request
    result = self._get_body(response)
  File "/usr/local/lib/python3.6/site-packages/googlemaps/client.py", line 276, in _get_body
    raise googlemaps.exceptions._RetriableRequest()
googlemaps.exceptions._RetriableRequest

During handling of the above exception, another exception occurred:

Traceback (most recent call last):
  File "/usr/local/lib/python3.6/site-packages/googlemaps/client.py", line 253, in _request
    result = self._get_body(response)
  File "/usr/local/lib/python3.6/site-packages/googlemaps/client.py", line 276, in _get_body
    raise googlemaps.exceptions._RetriableRequest()
googlemaps.exceptions._RetriableRequest

During handling of the above exception, another exception occurred:

Traceback (most recent call last):
  File "/usr/local/lib/python3.6/site-packages/googlemaps/client.py", line 253, in _request
    result = self._get_body(response)
  File "/usr/local/lib/python3.6/site-packages/googlemaps/client.py", line 276, in _get_body
    raise googlemaps.exceptions._RetriableRequest()
googlemaps.exceptions._RetriableRequest

During handling of the above exception, another exception occurred:

Traceback (most recent call last):
  File "/usr/local/lib/python3.6/site-packages/homeassistant/helpers/entity.py", line 221, in async_update_ha_state
    await self.async_device_update()
  File "/usr/local/lib/python3.6/site-packages/homeassistant/helpers/entity.py", line 349, in async_device_update
    await self.hass.async_add_executor_job(self.update)
  File "/usr/local/lib/python3.6/concurrent/futures/thread.py", line 56, in run
    result = self.fn(*self.args, **self.kwargs)
  File "/usr/local/lib/python3.6/site-packages/homeassistant/util/__init__.py", line 324, in wrapper
    result = method(*args, **kwargs)
  File "/usr/local/lib/python3.6/site-packages/homeassistant/components/sensor/google_travel_time.py", line 242, in update
    self._origin, self._destination, **options_copy)
  File "/usr/local/lib/python3.6/site-packages/googlemaps/client.py", line 356, in wrapper
    result = func(*args, **kwargs)
  File "/usr/local/lib/python3.6/site-packages/googlemaps/distance_matrix.py", line 130, in distance_matrix
    return client._request("/maps/api/distancematrix/json", params)
  File "/usr/local/lib/python3.6/site-packages/googlemaps/client.py", line 260, in _request
    extract_body, requests_kwargs, post_json)
  File "/usr/local/lib/python3.6/site-packages/googlemaps/client.py", line 260, in _request
    extract_body, requests_kwargs, post_json)
  File "/usr/local/lib/python3.6/site-packages/googlemaps/client.py", line 260, in _request
    extract_body, requests_kwargs, post_json)
  [Previous line repeated 7 more times]
  File "/usr/local/lib/python3.6/site-packages/googlemaps/client.py", line 203, in _request
    raise googlemaps.exceptions.Timeout()
googlemaps.exceptions.Timeout
2018-12-10 20:29:14 WARNING (MainThread) [homeassistant.helpers.entity] Update of sensor.google_travel_time__driving is taking over 10 seconds
2018-12-10 20:29:35 WARNING (MainThread) [homeassistant.components.sensor] Updating google_travel_time sensor took longer than the scheduled update interval 0:00:30
2018-12-10 20:30:06 WARNING (MainThread) [homeassistant.components.sensor] Updating google_travel_time sensor took longer than the scheduled update interval 0:00:30
2018-12-10 20:30:06 ERROR (MainThread) [homeassistant.helpers.entity] Update for sensor.google_travel_time__driving fails
Traceback (most recent call last):
  File "/usr/local/lib/python3.6/site-packages/googlemaps/client.py", line 253, in _request
    result = self._get_body(response)
  File "/usr/local/lib/python3.6/site-packages/googlemaps/client.py", line 276, in _get_body
    raise googlemaps.exceptions._RetriableRequest()
googlemaps.exceptions._RetriableRequest

During handling of the above exception, another exception occurred:

Traceback (most recent call last):
  File "/usr/local/lib/python3.6/site-packages/googlemaps/client.py", line 253, in _request
    result = self._get_body(response)
  File "/usr/local/lib/python3.6/site-packages/googlemaps/client.py", line 276, in _get_body
    raise googlemaps.exceptions._RetriableRequest()
googlemaps.exceptions._RetriableRequest

During handling of the above exception, another exception occurred:

Traceback (most recent call last):
  File "/usr/local/lib/python3.6/site-packages/googlemaps/client.py", line 253, in _request
    result = self._get_body(response)
  File "/usr/local/lib/python3.6/site-packages/googlemaps/client.py", line 276, in _get_body
    raise googlemaps.exceptions._RetriableRequest()
googlemaps.exceptions._RetriableRequest

During handling of the above exception, another exception occurred:

Traceback (most recent call last):
  File "/usr/local/lib/python3.6/site-packages/googlemaps/client.py", line 253, in _request
    result = self._get_body(response)
  File "/usr/local/lib/python3.6/site-packages/googlemaps/client.py", line 276, in _get_body
    raise googlemaps.exceptions._RetriableRequest()
googlemaps.exceptions._RetriableRequest

During handling of the above exception, another exception occurred:

Traceback (most recent call last):
  File "/usr/local/lib/python3.6/site-packages/googlemaps/client.py", line 253, in _request
    result = self._get_body(response)
  File "/usr/local/lib/python3.6/site-packages/googlemaps/client.py", line 276, in _get_body
    raise googlemaps.exceptions._RetriableRequest()
googlemaps.exceptions._RetriableRequest

During handling of the above exception, another exception occurred:

Traceback (most recent call last):
  File "/usr/local/lib/python3.6/site-packages/googlemaps/client.py", line 253, in _request
    result = self._get_body(response)
  File "/usr/local/lib/python3.6/site-packages/googlemaps/client.py", line 276, in _get_body
    raise googlemaps.exceptions._RetriableRequest()
googlemaps.exceptions._RetriableRequest

During handling of the above exception, another exception occurred:

Traceback (most recent call last):
  File "/usr/local/lib/python3.6/site-packages/googlemaps/client.py", line 253, in _request
    result = self._get_body(response)
  File "/usr/local/lib/python3.6/site-packages/googlemaps/client.py", line 276, in _get_body
    raise googlemaps.exceptions._RetriableRequest()
googlemaps.exceptions._RetriableRequest

During handling of the above exception, another exception occurred:

Traceback (most recent call last):
  File "/usr/local/lib/python3.6/site-packages/googlemaps/client.py", line 253, in _request
    result = self._get_body(response)
  File "/usr/local/lib/python3.6/site-packages/googlemaps/client.py", line 276, in _get_body
    raise googlemaps.exceptions._RetriableRequest()
googlemaps.exceptions._RetriableRequest

During handling of the above exception, another exception occurred:

Traceback (most recent call last):
  File "/usr/local/lib/python3.6/site-packages/googlemaps/client.py", line 253, in _request
    result = self._get_body(response)
  File "/usr/local/lib/python3.6/site-packages/googlemaps/client.py", line 276, in _get_body
    raise googlemaps.exceptions._RetriableRequest()
googlemaps.exceptions._RetriableRequest

During handling of the above exception, another exception occurred:

Traceback (most recent call last):
  File "/usr/local/lib/python3.6/site-packages/googlemaps/client.py", line 253, in _request
    result = self._get_body(response)
  File "/usr/local/lib/python3.6/site-packages/googlemaps/client.py", line 276, in _get_body
    raise googlemaps.exceptions._RetriableRequest()
googlemaps.exceptions._RetriableRequest

During handling of the above exception, another exception occurred:

Traceback (most recent call last):
  File "/usr/local/lib/python3.6/site-packages/googlemaps/client.py", line 253, in _request
    result = self._get_body(response)
  File "/usr/local/lib/python3.6/site-packages/googlemaps/client.py", line 276, in _get_body
    raise googlemaps.exceptions._RetriableRequest()
googlemaps.exceptions._RetriableRequest

During handling of the above exception, another exception occurred:

Traceback (most recent call last):
  File "/usr/local/lib/python3.6/site-packages/homeassistant/helpers/entity.py", line 221, in async_update_ha_state
    await self.async_device_update()
  File "/usr/local/lib/python3.6/site-packages/homeassistant/helpers/entity.py", line 349, in async_device_update
    await self.hass.async_add_executor_job(self.update)
  File "/usr/local/lib/python3.6/concurrent/futures/thread.py", line 56, in run
    result = self.fn(*self.args, **self.kwargs)
  File "/usr/local/lib/python3.6/site-packages/homeassistant/util/__init__.py", line 324, in wrapper
    result = method(*args, **kwargs)
  File "/usr/local/lib/python3.6/site-packages/homeassistant/components/sensor/google_travel_time.py", line 242, in update
    self._origin, self._destination, **options_copy)
  File "/usr/local/lib/python3.6/site-packages/googlemaps/client.py", line 356, in wrapper
    result = func(*args, **kwargs)
  File "/usr/local/lib/python3.6/site-packages/googlemaps/distance_matrix.py", line 130, in distance_matrix
    return client._request("/maps/api/distancematrix/json", params)
  File "/usr/local/lib/python3.6/site-packages/googlemaps/client.py", line 260, in _request
    extract_body, requests_kwargs, post_json)
  File "/usr/local/lib/python3.6/site-packages/googlemaps/client.py", line 260, in _request
    extract_body, requests_kwargs, post_json)
  File "/usr/local/lib/python3.6/site-packages/googlemaps/client.py", line 260, in _request
    extract_body, requests_kwargs, post_json)
  [Previous line repeated 7 more times]
  File "/usr/local/lib/python3.6/site-packages/googlemaps/client.py", line 203, in _request
    raise googlemaps.exceptions.Timeout()
googlemaps.exceptions.Timeout
2018-12-10 20:30:47 WARNING (MainThread) [homeassistant.helpers.entity] Update of sensor.google_travel_time__driving is taking over 10 seconds
2018-12-10 20:30:48 ERROR (SyncWorker_2) [homeassistant.components.sensor.waze_travel_time] Error on retrieving data: Internal Error
2018-12-10 20:31:07 WARNING (MainThread) [homeassistant.components.sensor] Updating google_travel_time sensor took longer than the scheduled update interval 0:00:30
2018-12-10 20:31:38 WARNING (MainThread) [homeassistant.components.sensor] Updating google_travel_time sensor took longer than the scheduled update interval 0:00:30
2018-12-10 20:32:03 ERROR (MainThread) [homeassistant.helpers.entity] Update for sensor.google_travel_time__driving fails
Traceback (most recent call last):
  File "/usr/local/lib/python3.6/site-packages/googlemaps/client.py", line 253, in _request
    result = self._get_body(response)
  File "/usr/local/lib/python3.6/site-packages/googlemaps/client.py", line 276, in _get_body
    raise googlemaps.exceptions._RetriableRequest()
googlemaps.exceptions._RetriableRequest

During handling of the above exception, another exception occurred:

Traceback (most recent call last):
  File "/usr/local/lib/python3.6/site-packages/googlemaps/client.py", line 253, in _request
    result = self._get_body(response)
  File "/usr/local/lib/python3.6/site-packages/googlemaps/client.py", line 276, in _get_body
    raise googlemaps.exceptions._RetriableRequest()
googlemaps.exceptions._RetriableRequest

During handling of the above exception, another exception occurred:

Traceback (most recent call last):
  File "/usr/local/lib/python3.6/site-packages/googlemaps/client.py", line 253, in _request
    result = self._get_body(response)
  File "/usr/local/lib/python3.6/site-packages/googlemaps/client.py", line 276, in _get_body
    raise googlemaps.exceptions._RetriableRequest()
googlemaps.exceptions._RetriableRequest

During handling of the above exception, another exception occurred:

Traceback (most recent call last):
  File "/usr/local/lib/python3.6/site-packages/googlemaps/client.py", line 253, in _request
    result = self._get_body(response)
  File "/usr/local/lib/python3.6/site-packages/googlemaps/client.py", line 276, in _get_body
    raise googlemaps.exceptions._RetriableRequest()
googlemaps.exceptions._RetriableRequest

During handling of the above exception, another exception occurred:

Traceback (most recent call last):
  File "/usr/local/lib/python3.6/site-packages/googlemaps/client.py", line 253, in _request
    result = self._get_body(response)
  File "/usr/local/lib/python3.6/site-packages/googlemaps/client.py", line 276, in _get_body
    raise googlemaps.exceptions._RetriableRequest()
googlemaps.exceptions._RetriableRequest

During handling of the above exception, another exception occurred:

Traceback (most recent call last):
  File "/usr/local/lib/python3.6/site-packages/googlemaps/client.py", line 253, in _request
    result = self._get_body(response)
  File "/usr/local/lib/python3.6/site-packages/googlemaps/client.py", line 276, in _get_body
    raise googlemaps.exceptions._RetriableRequest()
googlemaps.exceptions._RetriableRequest

During handling of the above exception, another exception occurred:

Traceback (most recent call last):
  File "/usr/local/lib/python3.6/site-packages/googlemaps/client.py", line 253, in _request
    result = self._get_body(response)
  File "/usr/local/lib/python3.6/site-packages/googlemaps/client.py", line 276, in _get_body
    raise googlemaps.exceptions._RetriableRequest()
googlemaps.exceptions._RetriableRequest

During handling of the above exception, another exception occurred:

Traceback (most recent call last):
  File "/usr/local/lib/python3.6/site-packages/googlemaps/client.py", line 253, in _request
    result = self._get_body(response)
  File "/usr/local/lib/python3.6/site-packages/googlemaps/client.py", line 276, in _get_body
    raise googlemaps.exceptions._RetriableRequest()
googlemaps.exceptions._RetriableRequest

During handling of the above exception, another exception occurred:

Traceback (most recent call last):
  File "/usr/local/lib/python3.6/site-packages/googlemaps/client.py", line 253, in _request
    result = self._get_body(response)
  File "/usr/local/lib/python3.6/site-packages/googlemaps/client.py", line 276, in _get_body
    raise googlemaps.exceptions._RetriableRequest()
googlemaps.exceptions._RetriableRequest

During handling of the above exception, another exception occurred:

Traceback (most recent call last):
  File "/usr/local/lib/python3.6/site-packages/googlemaps/client.py", line 253, in _request
    result = self._get_body(response)
  File "/usr/local/lib/python3.6/site-packages/googlemaps/client.py", line 276, in _get_body
    raise googlemaps.exceptions._RetriableRequest()
googlemaps.exceptions._RetriableRequest

During handling of the above exception, another exception occurred:

Traceback (most recent call last):
  File "/usr/local/lib/python3.6/site-packages/googlemaps/client.py", line 253, in _request
    result = self._get_body(response)
  File "/usr/local/lib/python3.6/site-packages/googlemaps/client.py", line 276, in _get_body
    raise googlemaps.exceptions._RetriableRequest()
googlemaps.exceptions._RetriableRequest

During handling of the above exception, another exception occurred:

Traceback (most recent call last):
  File "/usr/local/lib/python3.6/site-packages/googlemaps/client.py", line 253, in _request
    result = self._get_body(response)
  File "/usr/local/lib/python3.6/site-packages/googlemaps/client.py", line 276, in _get_body
    raise googlemaps.exceptions._RetriableRequest()
googlemaps.exceptions._RetriableRequest

During handling of the above exception, another exception occurred:

Traceback (most recent call last):
  File "/usr/local/lib/python3.6/site-packages/homeassistant/helpers/entity.py", line 221, in async_update_ha_state
    await self.async_device_update()
  File "/usr/local/lib/python3.6/site-packages/homeassistant/helpers/entity.py", line 349, in async_device_update
    await self.hass.async_add_executor_job(self.update)
  File "/usr/local/lib/python3.6/concurrent/futures/thread.py", line 56, in run
    result = self.fn(*self.args, **self.kwargs)
  File "/usr/local/lib/python3.6/site-packages/homeassistant/util/__init__.py", line 324, in wrapper
    result = method(*args, **kwargs)
  File "/usr/local/lib/python3.6/site-packages/homeassistant/components/sensor/google_travel_time.py", line 242, in update
    self._origin, self._destination, **options_copy)
  File "/usr/local/lib/python3.6/site-packages/googlemaps/client.py", line 356, in wrapper
    result = func(*args, **kwargs)
  File "/usr/local/lib/python3.6/site-packages/googlemaps/distance_matrix.py", line 130, in distance_matrix
    return client._request("/maps/api/distancematrix/json", params)
  File "/usr/local/lib/python3.6/site-packages/googlemaps/client.py", line 260, in _request
    extract_body, requests_kwargs, post_json)
  File "/usr/local/lib/python3.6/site-packages/googlemaps/client.py", line 260, in _request
    extract_body, requests_kwargs, post_json)
  File "/usr/local/lib/python3.6/site-packages/googlemaps/client.py", line 260, in _request
    extract_body, requests_kwargs, post_json)
  [Previous line repeated 8 more times]
  File "/usr/local/lib/python3.6/site-packages/googlemaps/client.py", line 203, in _request
    raise googlemaps.exceptions.Timeout()
googlemaps.exceptions.Timeout
2018-12-10 20:32:18 WARNING (MainThread) [homeassistant.helpers.entity] Update of sensor.google_travel_time__driving is taking over 10 seconds
2018-12-10 20:32:39 WARNING (MainThread) [homeassistant.components.sensor] Updating google_travel_time sensor took longer than the scheduled update interval 0:00:30
2018-12-10 20:33:10 WARNING (MainThread) [homeassistant.components.sensor] Updating google_travel_time sensor took longer than the scheduled update interval 0:00:30
2018-12-10 20:33:31 ERROR (MainThread) [homeassistant.helpers.entity] Update for sensor.google_travel_time__driving fails
Traceback (most recent call last):
  File "/usr/local/lib/python3.6/site-packages/googlemaps/client.py", line 253, in _request
    result = self._get_body(response)
  File "/usr/local/lib/python3.6/site-packages/googlemaps/client.py", line 276, in _get_body
    raise googlemaps.exceptions._RetriableRequest()
googlemaps.exceptions._RetriableRequest

During handling of the above exception, another exception occurred:

Traceback (most recent call last):
  File "/usr/local/lib/python3.6/site-packages/googlemaps/client.py", line 253, in _request
    result = self._get_body(response)
  File "/usr/local/lib/python3.6/site-packages/googlemaps/client.py", line 276, in _get_body
    raise googlemaps.exceptions._RetriableRequest()
googlemaps.exceptions._RetriableRequest

During handling of the above exception, another exception occurred:

Traceback (most recent call last):
  File "/usr/local/lib/python3.6/site-packages/googlemaps/client.py", line 253, in _request
    result = self._get_body(response)
  File "/usr/local/lib/python3.6/site-packages/googlemaps/client.py", line 276, in _get_body
    raise googlemaps.exceptions._RetriableRequest()
googlemaps.exceptions._RetriableRequest

During handling of the above exception, another exception occurred:

Traceback (most recent call last):
  File "/usr/local/lib/python3.6/site-packages/googlemaps/client.py", line 253, in _request
    result = self._get_body(response)
  File "/usr/local/lib/python3.6/site-packages/googlemaps/client.py", line 276, in _get_body
    raise googlemaps.exceptions._RetriableRequest()
googlemaps.exceptions._RetriableRequest

During handling of the above exception, another exception occurred:

Traceback (most recent call last):
  File "/usr/local/lib/python3.6/site-packages/googlemaps/client.py", line 253, in _request
    result = self._get_body(response)
  File "/usr/local/lib/python3.6/site-packages/googlemaps/client.py", line 276, in _get_body
    raise googlemaps.exceptions._RetriableRequest()
googlemaps.exceptions._RetriableRequest

During handling of the above exception, another exception occurred:

Traceback (most recent call last):
  File "/usr/local/lib/python3.6/site-packages/googlemaps/client.py", line 253, in _request
    result = self._get_body(response)
  File "/usr/local/lib/python3.6/site-packages/googlemaps/client.py", line 276, in _get_body
    raise googlemaps.exceptions._RetriableRequest()
googlemaps.exceptions._RetriableRequest

During handling of the above exception, another exception occurred:

Traceback (most recent call last):
  File "/usr/local/lib/python3.6/site-packages/googlemaps/client.py", line 253, in _request
    result = self._get_body(response)
  File "/usr/local/lib/python3.6/site-packages/googlemaps/client.py", line 276, in _get_body
    raise googlemaps.exceptions._RetriableRequest()
googlemaps.exceptions._RetriableRequest

During handling of the above exception, another exception occurred:

Traceback (most recent call last):
  File "/usr/local/lib/python3.6/site-packages/googlemaps/client.py", line 253, in _request
    result = self._get_body(response)
  File "/usr/local/lib/python3.6/site-packages/googlemaps/client.py", line 276, in _get_body
    raise googlemaps.exceptions._RetriableRequest()
googlemaps.exceptions._RetriableRequest

During handling of the above exception, another exception occurred:

Traceback (most recent call last):
  File "/usr/local/lib/python3.6/site-packages/googlemaps/client.py", line 253, in _request
    result = self._get_body(response)
  File "/usr/local/lib/python3.6/site-packages/googlemaps/client.py", line 276, in _get_body
    raise googlemaps.exceptions._RetriableRequest()
googlemaps.exceptions._RetriableRequest

During handling of the above exception, another exception occurred:

Traceback (most recent call last):
  File "/usr/local/lib/python3.6/site-packages/googlemaps/client.py", line 253, in _request
    result = self._get_body(response)
  File "/usr/local/lib/python3.6/site-packages/googlemaps/client.py", line 276, in _get_body
    raise googlemaps.exceptions._RetriableRequest()
googlemaps.exceptions._RetriableRequest

During handling of the above exception, another exception occurred:

Traceback (most recent call last):
  File "/usr/local/lib/python3.6/site-packages/googlemaps/client.py", line 253, in _request
    result = self._get_body(response)
  File "/usr/local/lib/python3.6/site-packages/googlemaps/client.py", line 276, in _get_body
    raise googlemaps.exceptions._RetriableRequest()
googlemaps.exceptions._RetriableRequest

During handling of the above exception, another exception occurred:

Traceback (most recent call last):
  File "/usr/local/lib/python3.6/site-packages/googlemaps/client.py", line 253, in _request
    result = self._get_body(response)
  File "/usr/local/lib/python3.6/site-packages/googlemaps/client.py", line 276, in _get_body
    raise googlemaps.exceptions._RetriableRequest()
googlemaps.exceptions._RetriableRequest

During handling of the above exception, another exception occurred:

Traceback (most recent call last):
  File "/usr/local/lib/python3.6/site-packages/homeassistant/helpers/entity.py", line 221, in async_update_ha_state
    await self.async_device_update()
  File "/usr/local/lib/python3.6/site-packages/homeassistant/helpers/entity.py", line 349, in async_device_update
    await self.hass.async_add_executor_job(self.update)
  File "/usr/local/lib/python3.6/concurrent/futures/thread.py", line 56, in run
    result = self.fn(*self.args, **self.kwargs)
  File "/usr/local/lib/python3.6/site-packages/homeassistant/util/__init__.py", line 324, in wrapper
    result = method(*args, **kwargs)
  File "/usr/local/lib/python3.6/site-packages/homeassistant/components/sensor/google_travel_time.py", line 242, in update
    self._origin, self._destination, **options_copy)
  File "/usr/local/lib/python3.6/site-packages/googlemaps/client.py", line 356, in wrapper
    result = func(*args, **kwargs)
  File "/usr/local/lib/python3.6/site-packages/googlemaps/distance_matrix.py", line 130, in distance_matrix
    return client._request("/maps/api/distancematrix/json", params)
  File "/usr/local/lib/python3.6/site-packages/googlemaps/client.py", line 260, in _request
    extract_body, requests_kwargs, post_json)
  File "/usr/local/lib/python3.6/site-packages/googlemaps/client.py", line 260, in _request
    extract_body, requests_kwargs, post_json)
  File "/usr/local/lib/python3.6/site-packages/googlemaps/client.py", line 260, in _request
    extract_body, requests_kwargs, post_json)
  [Previous line repeated 8 more times]
  File "/usr/local/lib/python3.6/site-packages/googlemaps/client.py", line 203, in _request
    raise googlemaps.exceptions.Timeout()
googlemaps.exceptions.Timeout
