2018-12-10 18:46:53 WARNING (MainThread) [homeassistant.components.http] legacy_api_password support has been enabled. If you don't require it, remove the 'api_password' from your http config.
2018-12-10 18:47:07 ERROR (MainThread) [homeassistant.components.sensor] Error while setting up platform uber
Traceback (most recent call last):
  File "/usr/local/lib/python3.6/site-packages/homeassistant/helpers/entity_platform.py", line 128, in _async_setup_platform
    SLOW_SETUP_MAX_WAIT, loop=hass.loop)
  File "/usr/local/lib/python3.6/asyncio/tasks.py", line 358, in wait_for
    return fut.result()
  File "/usr/local/lib/python3.6/concurrent/futures/thread.py", line 56, in run
    result = self.fn(*self.args, **self.kwargs)
  File "/usr/local/lib/python3.6/site-packages/homeassistant/components/sensor/uber.py", line 55, in setup_platform
    session, start_latitude, start_longitude, end_latitude, end_longitude)
  File "/usr/local/lib/python3.6/site-packages/homeassistant/components/sensor/uber.py", line 190, in __init__
    self.update()
  File "/usr/local/lib/python3.6/site-packages/homeassistant/util/__init__.py", line 324, in wrapper
    result = method(*args, **kwargs)
  File "/usr/local/lib/python3.6/site-packages/homeassistant/components/sensor/uber.py", line 232, in update
    self.start_latitude, self.start_longitude)
  File "/usr/local/lib/python3.6/site-packages/uber_rides/client.py", line 209, in get_pickup_time_estimates
    return self._api_call('GET', 'v1.2/estimates/time', args=args)
  File "/usr/local/lib/python3.6/site-packages/uber_rides/client.py", line 107, in _api_call
    return request.execute()
  File "/usr/local/lib/python3.6/site-packages/uber_rides/request.py", line 152, in execute
    return self._send(prepared_request)
  File "/usr/local/lib/python3.6/site-packages/uber_rides/request.py", line 136, in _send
    response = session.send(prepared_request)
  File "/usr/local/lib/python3.6/site-packages/requests/sessions.py", line 644, in send
    r = dispatch_hook('response', hooks, r, **kwargs)
  File "/usr/local/lib/python3.6/site-packages/requests/hooks.py", line 31, in dispatch_hook
    _hook_data = hook(hook_data, **kwargs)
  File "/usr/local/lib/python3.6/site-packages/uber_rides/utils/handlers.py", line 60, in error_handler
    raise ClientError(response, error_message)
  File "/usr/local/lib/python3.6/site-packages/uber_rides/errors.py", line 112, in __init__
    errors, meta = super(ClientError, self)._adapt_response(response)
  File "/usr/local/lib/python3.6/site-packages/uber_rides/errors.py", line 51, in _adapt_response
    raise UnknownHttpError(response)
uber_rides.errors.UnknownHttpError
2018-12-10 18:47:08 ERROR (MainThread) [homeassistant.components.sensor.yr] Retrying in 18 minutes: Cannot connect to host aa015h6buqvih86i1.api.met.no:443 ssl:None [Try again]
2018-12-10 18:52:14 ERROR (MainThread) [homeassistant.components.websocket_api.http.connection.547977158608] Error handling message: {'type': 'call_service', 'domain': 'wake_on_lan', 'service': 'send_magic_packet', 'service_data': 'broadcast_address: 192.168.1.255', 'id': 17}
Traceback (most recent call last):
  File "/usr/local/lib/python3.6/site-packages/homeassistant/components/websocket_api/connection.py", line 65, in async_handle
    handler(self.hass, self, schema(msg))
  File "/usr/local/lib/python3.6/site-packages/voluptuous/schema_builder.py", line 267, in __call__
    return self._compiled([], data)
  File "/usr/local/lib/python3.6/site-packages/voluptuous/schema_builder.py", line 589, in validate_dict
    return base_validate(path, iteritems(data), out)
  File "/usr/local/lib/python3.6/site-packages/voluptuous/schema_builder.py", line 427, in validate_mapping
    raise er.MultipleInvalid(errors)
voluptuous.error.MultipleInvalid: expected dict for dictionary value @ data['service_data']
2018-12-10 18:55:14 ERROR (MainThread) [homeassistant.components.websocket_api.http.connection.547977158608] Error handling message: {'type': 'call_service', 'domain': 'wake_on_lan', 'service': 'send_magic_packet', 'service_data': 'mac: 94:de:80:7f:85:79', 'id': 19}
Traceback (most recent call last):
  File "/usr/local/lib/python3.6/site-packages/homeassistant/components/websocket_api/connection.py", line 65, in async_handle
    handler(self.hass, self, schema(msg))
  File "/usr/local/lib/python3.6/site-packages/voluptuous/schema_builder.py", line 267, in __call__
    return self._compiled([], data)
  File "/usr/local/lib/python3.6/site-packages/voluptuous/schema_builder.py", line 589, in validate_dict
    return base_validate(path, iteritems(data), out)
  File "/usr/local/lib/python3.6/site-packages/voluptuous/schema_builder.py", line 427, in validate_mapping
    raise er.MultipleInvalid(errors)
voluptuous.error.MultipleInvalid: expected dict for dictionary value @ data['service_data']
2018-12-10 18:55:26 ERROR (MainThread) [homeassistant.components.websocket_api.http.connection.547977158608] Error handling message: {'type': 'call_service', 'domain': 'wake_on_lan', 'service': 'send_magic_packet', 'service_data': 'mac: 94:de:80:7f:85:79', 'id': 20}
Traceback (most recent call last):
  File "/usr/local/lib/python3.6/site-packages/homeassistant/components/websocket_api/connection.py", line 65, in async_handle
    handler(self.hass, self, schema(msg))
  File "/usr/local/lib/python3.6/site-packages/voluptuous/schema_builder.py", line 267, in __call__
    return self._compiled([], data)
  File "/usr/local/lib/python3.6/site-packages/voluptuous/schema_builder.py", line 589, in validate_dict
    return base_validate(path, iteritems(data), out)
  File "/usr/local/lib/python3.6/site-packages/voluptuous/schema_builder.py", line 427, in validate_mapping
    raise er.MultipleInvalid(errors)
voluptuous.error.MultipleInvalid: expected dict for dictionary value @ data['service_data']
2018-12-10 18:55:35 ERROR (MainThread) [homeassistant.components.websocket_api.http.connection.547977158608] Error handling message: {'type': 'call_service', 'domain': 'wake_on_lan', 'service': 'send_magic_packet', 'service_data': 'mac:94:de:80:7f:85:79', 'id': 21}
Traceback (most recent call last):
  File "/usr/local/lib/python3.6/site-packages/homeassistant/components/websocket_api/connection.py", line 65, in async_handle
    handler(self.hass, self, schema(msg))
  File "/usr/local/lib/python3.6/site-packages/voluptuous/schema_builder.py", line 267, in __call__
    return self._compiled([], data)
  File "/usr/local/lib/python3.6/site-packages/voluptuous/schema_builder.py", line 589, in validate_dict
    return base_validate(path, iteritems(data), out)
  File "/usr/local/lib/python3.6/site-packages/voluptuous/schema_builder.py", line 427, in validate_mapping
    raise er.MultipleInvalid(errors)
voluptuous.error.MultipleInvalid: expected dict for dictionary value @ data['service_data']
2018-12-10 18:56:40 WARNING (Thread-4) [pychromecast.socket_client] Heartbeat timeout, resetting connection
2018-12-10 18:57:04 WARNING (Thread-4) [pychromecast.socket_client] Heartbeat timeout, resetting connection
2018-12-10 19:01:25 WARNING (Thread-4) [pychromecast.socket_client] Heartbeat timeout, resetting connection
